Workbook
Name Data_Mapa: 'Parâmetros'!$B$6
Name Turno_Ini: 'Parâmetros'!$B$10
Name Turno_Fim: 'Parâmetros'!$B$11
Name Turno_Min: 'Parâmetros'!$B$12
Name Peso_Instrumentador: 'Parâmetros'!$B$22
Name Peso_Circulante: 'Parâmetros'!$B$23
Name Afinidade_Meta: 'Parâmetros'!$B$25
Name Afinidade_Min: 'Parâmetros'!$B$26
Name Nivel_Critico: 'Parâmetros'!$B$27
Name Part_Min_Critica: 'Parâmetros'!$B$28
Name Limpeza_Min: 'Parâmetros'!$B$31
Name Janela_Min: 'Parâmetros'!$B$32
Name Meta_Ocupacao: 'Parâmetros'!$B$33
Name Ocupacao_Max: 'Parâmetros'!$B$34
Name Aus_Tipos: 'Parâmetros'!$A$38:$A$42
Name Aus_Siglas: 'Parâmetros'!$B$38:$B$42
Name Lista_Funcoes: 'Parâmetros'!$F$5:$F$7
Name Lista_StatusCad: 'Parâmetros'!$G$5:$G$7
Name Lista_StatusCirurgia: 'Parâmetros'!$H$5:$H$8
Name Lista_Porte: 'Parâmetros'!$I$5:$I$7
Name Lista_TipoPosto: 'Parâmetros'!$J$5:$J$6
Name Lista_TiposAusencia: 'Parâmetros'!$A$38:$A$42
Name Hab_Nome: 'Habilidades'!$B$2:$B$15
Name Esp_Nome: 'Especialidades'!$A$2:$A$25
Name Esp_Hab: 'Especialidades'!$B$2:$B$25
Name Esp_Dur: 'Especialidades'!$C$2:$C$25
Name Postos_Cod: 'Postos'!$A$2:$A$17
Name Postos_Nome: 'Postos'!$B$2:$B$17
Name Postos_Tipo: 'Postos'!$C$2:$C$17
Name Postos_Nec: 'Postos'!$D$2:$D$17
Name Postos_Min: 'Postos'!$E$2:$E$17
Name Postos_Prior: 'Postos'!$F$2:$F$17
Name Postos_Hab: 'Postos'!$G$2:$G$17
Name Postos_Status: 'Postos'!$H$2:$H$17
Name Equipe_Mat: 'Equipe'!$A$2:$A$31
Name Equipe_Nome: 'Equipe'!$B$2:$B$31
Name Equipe_Funcao: 'Equipe'!$C$2:$C$31
Name Equipe_StatusCad: 'Equipe'!$D$2:$D$31
Name Equipe_Situacao: 'Equipe'!$E$2:$E$31
Name Matriz_Nome: 'Matriz_Habilidades'!$B$2:$B$31
Name Matriz_Niveis: 'Matriz_Habilidades'!$D$2:$Q$31
Name Matriz_Hab: 'Matriz_Habilidades'!$D$1:$Q$1
Name Aus_Tec: 'Ausencias'!$A$2:$A$151
Name Aus_Tipo: 'Ausencias'!$B$2:$B$151
Name Aus_Ini: 'Ausencias'!$C$2:$C$151
Name Aus_Fim: 'Ausencias'!$D$2:$D$151
Name Aus_Ativa: 'Ausencias'!$G$2:$G$151
Name Aus_Cod: 'Ausencias'!$H$2:$H$151
Name Mapa_Data: 'Mapa_Cirurgico'!$A$2:$A$201
Name Mapa_Sala: 'Mapa_Cirurgico'!$B$2:$B$201
Name Mapa_Ini: 'Mapa_Cirurgico'!$C$2:$C$201
Name Mapa_Fim: 'Mapa_Cirurgico'!$D$2:$D$201
Name Mapa_Esp: 'Mapa_Cirurgico'!$E$2:$E$201
Name Mapa_Hab: 'Mapa_Cirurgico'!$F$2:$F$201
Name Mapa_Status: 'Mapa_Cirurgico'!$J$2:$J$201
Name Mapa_Dur: 'Mapa_Cirurgico'!$K$2:$K$201
Name Mapa_MinOcup: 'Mapa_Cirurgico'!$L$2:$L$201
Name Mapa_Ordem: 'Mapa_Cirurgico'!$M$2:$M$201
Name Mapa_Livre: 'Mapa_Cirurgico'!$O$2:$O$201
Name Mapa_Alerta: 'Mapa_Cirurgico'!$P$2:$P$201

Sheet Instruções
A1: CENTRO CIRÚRGICO — ESCALA DIÁRIA DE TÉCNICOS POR POSTO
A2: 8 salas (2 técnicos cada) + admissão (2) + box de preparo oftalmológico (1) + sala de recém-nascido (1) = 20 vagas por dia, para um quadro de 22 técnicos com férias, folgas e atestados.
B4: 1. PREMISSAS ADOTADAS — confira antes de usar
B5: Um plantão por dia | C5: A escala do dia cobre UM plantão (07:00–19:00, alterável em Parâmetros). Foi a única leitura compatível com 22 técnicos para 20 vagas. Se o serviço tiver mais de um turno, avise: a estrutura muda.
B6: Papéis nas salas | C6: Nas salas cirúrgicas o Técnico 1 é o CIRCULANTE e o Técnico 2 é o INSTRUMENTADOR, com pesos diferentes na afinidade. Nos postos de apoio (admissão, box, RN) não há distinção de papel.
B7: Déficit é o normal | C7: Como quase nunca há 20 técnicos disponíveis, a planilha trabalha com PRIORIDADE DE COBERTURA: cada posto tem uma prioridade e um mínimo aceitável, e o Painel mostra o déficit, os postos descobertos e quantas cirurgias precisam ser remanejadas.
B8: Dados de exemplo | C8: Equipe, habilidades, ausências e agenda vêm preenchidos com um dia de demonstração (18 disponíveis para 20 vagas). Substitua pelos dados reais.
B9: 2. COMO A PLANILHA ESTÁ ORGANIZADA
B10: ENTRADAS (o que se digita) | C10: Parâmetros · Habilidades · Especialidades · Postos · Equipe · Matriz_Habilidades · Ausencias · Mapa_Cirurgico · colunas TÉCNICO 1 e TÉCNICO 2 da Escala_Dia
B11: PROCESSAMENTO (não digitar) | C11: Calc_Mix (minutos por habilidade em cada posto) e Calc_Afinidade (afinidade dos técnicos disponíveis e ainda não escalados). Ficam visíveis para auditoria.
B12: SAÍDAS | C12: Escala_Dia · Sugestao_Tecnicos · Jogo_de_Sala · Calendario_Ausencias · Painel · Base_Historico
B13: 3. A REGRA DE AFINIDADE
B14: Afinidade do técnico com o posto | C14: Média dos níveis do técnico nas habilidades exigidas pelo posto, PONDERADA PELOS MINUTOS de cada habilidade na agenda daquela sala. Habilidade que ocupa mais tempo pesa mais.
B15: Postos sem agenda | C15: Admissão, box e sala de RN — e qualquer sala sem cirurgia marcada, como a de urgência — usam a HABILIDADE DE REFERÊNCIA cadastrada na aba Postos.
B16: Afinidade do posto | C16: Sala: Peso_Circulante × técnico 1 + Peso_Instrumentador × técnico 2. Apoio: média simples. Com um só técnico, é a afinidade dele.
B17: Classificação | C17: ADEQUADO ≥ Afinidade_Meta (2,50) · ATENÇÃO entre a meta e a mínima · CRÍTICO abaixo de Afinidade_Min (2,00) · SEM EQUIPE quando o posto está descoberto.
B18: Alerta de inaptidão | C18: Se uma habilidade responder por ≥ Part_Min_Critica (20%) do tempo da sala e algum técnico da dupla tiver nível ≤ Nivel_Critico (1) nela, a linha é sinalizada mesmo com média boa.
B19: 4. ROTINA DO DIA
B20: Passo 1 — data | C20: Em Parâmetros, ajuste a Data da escala. Toda a planilha passa a olhar para esse dia.
B21: Passo 2 — ausências | C21: Lance férias, folgas, atestados, licenças e treinamentos em Ausencias (período de/até). A aba Equipe mostra na hora quem está disponível, e o Calendario_Ausencias dá a visão do mês inteiro.
B22: Passo 3 — agenda | C22: Lance as cirurgias em Mapa_Cirurgico. A coluna Alerta aponta sobreposição de horário, sala não cadastrada, duração inválida e horário fora da janela do plantão.
B23: Passo 4 — escala | C23: Em Escala_Dia, escolha os técnicos de cada posto nas listas suspensas (células azuis), na ordem de prioridade dos postos. A aba Sugestao_Tecnicos mostra, para cada posto, quem ainda está livre em ordem de afinidade — a lista se atualiza a cada nome escalado.
B24: Passo 5 — o que ficou descoberto | C24: O Painel (bloco 2) mostra o déficit, os postos descobertos e quantas cirurgias precisam ser remanejadas. Use o Jogo_de_Sala para achar em qual sala e em que horário elas cabem.
B25: Passo 6 — fechamento | C25: Copie as linhas de Escala_Dia e cole COMO VALORES em Base_Historico para guardar o histórico do dia.
B26: 5. JOGO DE SALA (encaixes)
B27: O que é cada janela | C27: Janela 0 é o tempo livre antes da primeira cirurgia. As demais são o intervalo entre a liberação de uma cirurgia (fim + limpeza) e o início da seguinte. A última vai até o fim do plantão.
B28: Cabe cirurgia de até | C28: É a duração da janela menos o tempo de limpeza — ou seja, o tamanho real do encaixe possível. A coluna Situação separa as janelas aproveitáveis (≥ Janela_Min, 30 min) das curtas.
B29: No Mapa_Cirurgico | C29: As colunas 'Sala liberada às' e 'Livre até a próxima (min)' mostram o mesmo em linha, cirurgia a cirurgia; a célula fica verde quando o intervalo comporta um encaixe.
B30: 6. CONVENÇÕES VISUAIS
B31: Azul | C31: Célula de entrada — pode digitar.
B32: Amarelo | C32: Premissa de negócio (Parâmetros). Alterar aqui recalcula toda a planilha.
B33: Preto | C33: Resultado de fórmula — não digitar por cima.
B34: Verde itálico | C34: Valor trazido de outra aba por fórmula.
B35: Vermelho / âmbar / verde | C35: Semáforo de cobertura, afinidade, ocupação e alertas.
B36: 7. COMO EXPANDIR
B37: Novo técnico | C37: Acrescente a linha em Equipe (até 30). Matriz_Habilidades, Calc_Afinidade, Calendario_Ausencias e as listas suspensas acompanham sozinhos — só preencha os níveis na Matriz.
B38: Nova habilidade | C38: Acrescente a linha em Habilidades (até 14 posições). As colunas da Matriz e do Calc_Mix pegam o nome automaticamente.
B39: Novo posto ou nova sala | C39: Acrescente a linha em Postos (até 16). As linhas correspondentes já existem em Calc_Mix, Escala_Dia, Sugestao_Tecnicos e Jogo_de_Sala e passam a funcionar sozinhas.
B40: Mais cirurgias / ausências | C40: O Mapa_Cirurgico comporta 200 cirurgias por dia e a aba Ausencias 150 registros; as fórmulas já cobrem esse intervalo.
B41: 8. OBSERVAÇÕES TÉCNICAS
...

Sheet Parâmetros
A1: PARÂMETROS E PREMISSAS
A2: Células amarelas são premissas de negócio. Alterá-las recalcula toda a planilha — nenhuma premissa está embutida em fórmula.
A3: 1. IDENTIFICAÇÃO | F3: LISTAS AUXILIARES
A4: Unidade / Hospital | B4: Hospital — preencher | F4: Função | G4: Status cadastral | H4: Status da cirurgia | I4: Porte | J4: Tipo de posto
A5: Setor | B5: Centro Cirúrgico | F5: Circulante | G5: Ativo | H5: Agendada | I5: P | J5: Sala cirúrgica
A6: Data da escala | B6: 46254 | D6: Data_Mapa | F6: Instrumentador | G6: Afastado | H6: Realizada | I6: M | J6: Apoio
A7: Coordenação responsável | B7: Coordenação de Enfermagem | F7: Ambos | G7: Desligado | H7: Cancelada | I7: G
H8: Suspensa
A9: 2. PLANTÃO (a escala do dia cobre um plantão)
A10: Início do plantão | B10: 0.29166667 | D10: Turno_Ini
A11: Fim do plantão | B11: 0.79166667 | D11: Turno_Fim
A12: Minutos do plantão | B12: =MOD(B11-B10,1)*1440 | D12: Turno_Min
A14: 3. ESCALA DE HABILIDADE (usada na Matriz_Habilidades)
A15: Nível | B15: Descrição | C15: Pontos | D15: Critério operacional
A16: 0 | B16: Não apto | C16: 0 | D16: Não pode assumir o posto
A17: 1 | B17: Em treinamento | C17: 1 | D17: Só atua acompanhado de técnico apto
A18: 2 | B18: Apto | C18: 2 | D18: Atua com autonomia
A19: 3 | B19: Referência | C19: 3 | D19: Atua em alta complexidade e treina a equipe
A21: 4. PARÂMETROS DE AFINIDADE
A22: Peso do INSTRUMENTADOR na afinidade da dupla | B22: 0.6 | D22: Peso_Instrumentador
A23: Peso do CIRCULANTE na afinidade da dupla | B23: 0.4 | D23: Peso_Circulante
A24: Soma dos pesos (precisa ser 1,00) | B24: =B22+B23
A25: Afinidade META — posto ADEQUADO quando ≥ | B25: 2.5 | D25: Afinidade_Meta
A26: Afinidade MÍNIMA aceitável — abaixo é CRÍTICO | B26: 2 | D26: Afinidade_Min
A27: Nível considerado INAPTO (≤) | B27: 1 | D27: Nivel_Critico
A28: Participação mínima da habilidade para alerta crítico | B28: 0.2 | D28: Part_Min_Critica
A30: 5. PARÂMETROS OPERACIONAIS
A31: Limpeza e preparação após cada cirurgia (min) | B31: 20 | D31: Limpeza_Min
A32: Janela mínima para considerar encaixe (min) | B32: 30 | D32: Janela_Min
A33: Meta de ocupação de sala | B33: 0.85 | D33: Meta_Ocupacao
A34: Ocupação máxima admitida | B34: 1 | D34: Ocupacao_Max
A36: 6. TIPOS DE AUSÊNCIA
A37: Tipo | B37: Sigla | C37: Cor no calendário
A38: Férias | B38: F
A39: Folga | B39: D
A40: Atestado | B40: A
A41: Licença | B41: L
A42: Treinamento | B42: T

Sheet Habilidades
A1: Código | B1: Habilidade | C1: Tipo | D1: Observação
A2: H01 | B2: Ortopedia e Traumatologia | C2: Cirúrgica
A3: H02 | B3: Cirurgia Geral e Videolaparoscopia | C3: Cirúrgica
A4: H03 | B4: Neurocirurgia | C4: Cirúrgica
A5: H04 | B5: Obstetrícia (cesariana) | C5: Cirúrgica
A6: H05 | B6: Ginecologia e Urologia | C6: Cirúrgica
A7: H06 | B7: Oftalmologia | C7: Cirúrgica
A8: H07 | B8: Otorrinolaringologia e Buco-maxilo | C8: Cirúrgica
A9: H08 | B9: Cirurgia Plástica e Vascular | C9: Cirúrgica
A10: H09 | B10: Admissão | C10: Apoio
A11: H10 | B11: Sala de recém-nascido | C11: Apoio
A17: A ORDEM desta lista define a ordem das colunas da Matriz_Habilidades e do Calc_Mix (ambas puxam o cabeçalho daqui). Há 14 posições; 10 em uso.

Sheet Especialidades
A1: Especialidade (como vem na agenda) | B1: Habilidade correspondente | C1: Duração média (min) | D1: Ativa | E1: Observação
A2: Ortopedia | B2: Ortopedia e Traumatologia | C2: 120 | D2: Sim
A3: Traumatologia | B3: Ortopedia e Traumatologia | C3: 90 | D3: Sim
A4: Cirurgia Geral | B4: Cirurgia Geral e Videolaparoscopia | C4: 90 | D4: Sim
A5: Cirurgia Bariátrica | B5: Cirurgia Geral e Videolaparoscopia | C5: 150 | D5: Sim
A6: Cirurgia Pediátrica | B6: Cirurgia Geral e Videolaparoscopia | C6: 75 | D6: Sim
A7: Neurocirurgia | B7: Neurocirurgia | C7: 210 | D7: Sim
A8: Cesariana | B8: Obstetrícia (cesariana) | C8: 60 | D8: Sim
A9: Ginecologia | B9: Ginecologia e Urologia | C9: 90 | D9: Sim
A10: Urologia | B10: Ginecologia e Urologia | C10: 90 | D10: Sim
A11: Oftalmologia | B11: Oftalmologia | C11: 45 | D11: Sim
A12: Otorrinolaringologia | B12: Otorrinolaringologia e Buco-maxilo | C12: 75 | D12: Sim
A13: Buco-Maxilo-Facial | B13: Otorrinolaringologia e Buco-maxilo | C13: 120 | D13: Sim
... A15: Cirurgia Vascular | B15: Cirurgia Plástica e Vascular | C15: 150 | D15: Sim
A27: Não se realizam cirurgias cardíacas nesta unidade. Cada especialidade da agenda aponta para uma das habilidades da equipe — é isso que liga o mapa cirúrgico à matriz de habilidades.

Sheet Postos
A1: Código | B1: Posto | C1: Tipo | D1: Técnicos necessários | E1: Mínimo aceitável | F1: Prioridade de cobertura | G1: Habilidade de referência | H1: Status | I1: Observação
A2: SO-01 | B2: Sala 1 | C2: Sala cirúrgica | D2: 2 | E2: 2 | F2: 5 | G2: Ortopedia e Traumatologia | H2: Ativo | I2: Eletivas de ortopedia
A3: SO-02 | B3: Sala 2 | C3: Sala cirúrgica | D3: 2 | E3: 2 | F3: 6 | G3: Cirurgia Geral e Videolaparoscopia | H3: Ativo | I3: Eletivas de cirurgia geral
A4: SO-03 | B4: Sala 3 | C4: Sala cirúrgica | D4: 2 | E4: 2 | F4: 9 | G4: Neurocirurgia | H4: Ativo | I4: Eletivas de neurocirurgia
A5: SO-04 | B5: Sala 4 | C5: Sala cirúrgica | D5: 2 | E5: 2 | F5: 10 | G5: Cirurgia Plástica e Vascular | H5: Ativo | I5: Plástica e vascular
A6: SO-05 | B6: Sala 5 | C6: Sala cirúrgica | D6: 2 | E6: 2 | F6: 7 | G6: Ginecologia e Urologia | H6: Ativo | I6: Gineco e urologia
A7: SO-06 | B7: Sala 6 | C7: Sala cirúrgica | D7: 2 | E7: 2 | F7: 2 | G7: Obstetrícia (cesariana) | H7: Ativo | I7: EXCLUSIVA do centro obstétrico — cesarianas
A8: SO-07 | B8: Sala 7 | C8: Sala cirúrgica | D8: 2 | E8: 2 | F8: 1 | G8: Cirurgia Geral e Videolaparoscopia | H8: Ativo | I8: RESERVADA a urgências — não pode ficar descoberta
A9: SO-08 | B9: Sala 8 | C9: Sala cirúrgica | D9: 2 | E9: 2 | F9: 8 | G9: Oftalmologia | H9: Ativo | I9: Oftalmologia — apoiada pelo box de preparo
A10: ADM | B10: Admissão | C10: Apoio | D10: 2 | E10: 1 | F10: 4 | G10: Admissão | H10: Ativo | I10: Recepção e preparo do paciente — opera com 1 no limite
A11: BOX | B11: Box de preparo oftalmológico | C11: Apoio | D11: 1 | E11: 1 | F11: 11 | G11: Oftalmologia | H11: Ativo | I11: Apoio da Sala 8
A12: RN | B12: Sala de recém-nascido | C12: Apoio | D12: 1 | E12: 1 | F12: 3 | G12: Sala de recém-nascido | H12: Ativo | I12: Bloco obstétrico
A19: Prioridade 1 é coberta primeiro quando falta pessoal. 'Mínimo aceitável' é o número de técnicos com que o posto ainda pode abrir; abaixo disso o posto fica descoberto.

Sheet Equipe
A1: Matrícula | B1: Nome do técnico | C1: Função | D1: Status cadastral | E1: SITUAÇÃO NA DATA | F1: Ausente até | G1: Observação
A2: TEC-001 | B2: Adriana Salvi | C2: Circulante | D2: Ativo | E2: =IF($B2="","",IF($D2<>"Ativo",$D2,IFERROR(INDEX(Aus_Tipo,MATCH($B2,Aus_Ativa,0)),"Disponível"))) | F2: =IF(OR($B2="",$E2="Disponível"),"",IFERROR(INDEX(Aus_Fim,MATCH($B2,Aus_Ativa,0)),""))
A3: TEC-002 | B3: Bruna Cordeiro | C3: Circulante | D3: Ativo | E3: =IF($B3="","",IF($D3<>"Ativo",$D3,IFERROR(INDEX(Aus_Tipo,MATCH($B3,Aus_Ativa,0)),"Disponível"))) | F3: =IF(OR($B3="",$E3="Disponível"),"",IFERROR(INDEX(Aus_Fim,MATCH($B3,Aus_Ativa,0)),""))
A4: TEC-003 | B4: Camila Bertoldi | C4: Circulante | D4: Ativo | E4: =IF($B4="","",IF($D4<>"Ativo",$D4,IFERROR(INDEX(Aus_Tipo,MATCH($B4,Aus_Ativa,0)),"Disponível"))) | F4: =IF(OR($B4="",$E4="Disponível"),"",IFERROR(INDEX(Aus_Fim,MATCH($B4,Aus_Ativa,0)),""))
A5: TEC-004 | B5: Daiane Prestes | C5: Circulante | D5: Ativo | E5: =IF($B5="","",IF($D5<>"Ativo",$D5,IFERROR(INDEX(Aus_Tipo,MATCH($B5,Aus_Ativa,0)),"Disponível"))) | F5: =IF(OR($B5="",$E5="Disponível"),"",IFERROR(INDEX(Aus_Fim,MATCH($B5,Aus_Ativa,0)),""))
A6: TEC-005 | B6: Elaine Mafra | C6: Circulante | D6: Ativo | E6: =IF($B6="","",IF($D6<>"Ativo",$D6,IFERROR(INDEX(Aus_Tipo,MATCH($B6,Aus_Ativa,0)),"Disponível"))) | F6: =IF(OR($B6="",$E6="Disponível"),"",IFERROR(INDEX(Aus_Fim,MATCH($B6,Aus_Ativa,0)),""))
A7: TEC-006 | B7: Fernanda Klein | C7: Circulante | D7: Ativo | E7: =IF($B7="","",IF($D7<>"Ativo",$D7,IFERROR(INDEX(Aus_Tipo,MATCH($B7,Aus_Ativa,0)),"Disponível"))) | F7: =IF(OR($B7="",$E7="Disponível"),"",IFERROR(INDEX(Aus_Fim,MATCH($B7,Aus_Ativa,0)),""))
A8: TEC-007 | B8: Gisele Antunes | C8: Circulante | D8: Ativo | E8: =IF($B8="","",IF($D8<>"Ativo",$D8,IFERROR(INDEX(Aus_Tipo,MATCH($B8,Aus_Ativa,0)),"Disponível"))) | F8: =IF(OR($B8="",$E8="Disponível"),"",IFERROR(INDEX(Aus_Fim,MATCH($B8,Aus_Ativa,0)),""))
A9: TEC-008 | B9: Heloísa Perin | C9: Circulante | D9: Ativo | E9: =IF($B9="","",IF($D9<>"Ativo",$D9,IFERROR(INDEX(Aus_Tipo,MATCH($B9,Aus_Ativa,0)),"Disponível"))) | F9: =IF(OR($B9="",$E9="Disponível"),"",IFERROR(INDEX(Aus_Fim,MATCH($B9,Aus_Ativa,0)),""))
A10: TEC-009 | B10: Ismael Kanitz | C10: Circulante | D10: Ativo | E10: =IF($B10="","",IF($D10<>"Ativo",$D10,IFERROR(INDEX(Aus_Tipo,MATCH($B10,Aus_Ativa,0)),"Disponível"))) | F10: =IF(OR($B10="",$E10="Disponível"),"",IFERROR(INDEX(Aus_Fim,MATCH($B10,Aus_Ativa,0)),""))
A11: TEC-010 | B11: Joana Belincanta | C11: Instrumentador | D11: Ativo | E11: =IF($B11="","",IF($D11<>"Ativo",$D11,IFERROR(INDEX(Aus_Tipo,MATCH($B11,Aus_Ativa,0)),"Disponível"))) | F11: =IF(OR($B11="",$E11="Disponível"),"",IFERROR(INDEX(Aus_Fim,MATCH($B11,Aus_Ativa,0)),""))
A12: TEC-011 | B12: Kelly Marchi | C12: Instrumentador | D12: Ativo | E12: =IF($B12="","",IF($D12<>"Ativo",$D12,IFERROR(INDEX(Aus_Tipo,MATCH($B12,Aus_Ativa,0)),"Disponível"))) | F12: =IF(OR($B12="",$E12="Disponível"),"",IFERROR(INDEX(Aus_Fim,MATCH($B12,Aus_Ativa,0)),""))
A13: TEC-012 | B13: Luciano Bordin | C13: Instrumentador | D13: Ativo | E13: =IF($B13="","",IF($D13<>"Ativo",$D13,IFERROR(INDEX(Aus_Tipo,MATCH($B13,Aus_Ativa,0)),"Disponível"))) | F13: =IF(OR($B13="",$E13="Disponível"),"",IFERROR(INDEX(Aus_Fim,MATCH($B13,Aus_Ativa,0)),""))
... A23: TEC-022 | B23: Zuleide Marcon | C23: Ambos | D23: Ativo | E23: =IF($B23="","",IF($D23<>"Ativo",$D23,IFERROR(INDEX(Aus_Tipo,MATCH($B23,Aus_Ativa,0)),"Disponível"))) | F23: =IF(OR($B23="",$E23="Disponível"),"",IFERROR(INDEX(Aus_Fim,MATCH($B23,Aus_Ativa,0)),""))
E24: =IF($B24="","",IF($D24<>"Ativo",$D24,IFERROR(INDEX(Aus_Tipo,MATCH($B24,Aus_Ativa,0)),"Disponível"))) | F24: =IF(OR($B24="",$E24="Disponível"),"",IFERROR(INDEX(Aus_Fim,MATCH($B24,Aus_Ativa,0)),""))
E25: =IF($B25="","",IF($D25<>"Ativo",$D25,IFERROR(INDEX(Aus_Tipo,MATCH($B25,Aus_Ativa,0)),"Disponível"))) | F25: =IF(OR($B25="",$E25="Disponível"),"",IFERROR(INDEX(Aus_Fim,MATCH($B25,Aus_Ativa,0)),""))
E26: =IF($B26="","",IF($D26<>"Ativo",$D26,IFERROR(INDEX(Aus_Tipo,MATCH($B26,Aus_Ativa,0)),"Disponível"))) | F26: =IF(OR($B26="",$E26="Disponível"),"",IFERROR(INDEX(Aus_Fim,MATCH($B26,Aus_Ativa,0)),""))
E27: =IF($B27="","",IF($D27<>"Ativo",$D27,IFERROR(INDEX(Aus_Tipo,MATCH($B27,Aus_Ativa,0)),"Disponível"))) | F27: =IF(OR($B27="",$E27="Disponível"),"",IFERROR(INDEX(Aus_Fim,MATCH($B27,Aus_Ativa,0)),""))
E28: =IF($B28="","",IF($D28<>"Ativo",$D28,IFERROR(INDEX(Aus_Tipo,MATCH($B28,Aus_Ativa,0)),"Disponível"))) | F28: =IF(OR($B28="",$E28="Disponível"),"",IFERROR(INDEX(Aus_Fim,MATCH($B28,Aus_Ativa,0)),""))
E29: =IF($B29="","",IF($D29<>"Ativo",$D29,IFERROR(INDEX(Aus_Tipo,MATCH($B29,Aus_Ativa,0)),"Disponível"))) | F29: =IF(OR($B29="",$E29="Disponível"),"",IFERROR(INDEX(Aus_Fim,MATCH($B29,Aus_Ativa,0)),""))
E30: =IF($B30="","",IF($D30<>"Ativo",$D30,IFERROR(INDEX(Aus_Tipo,MATCH($B30,Aus_Ativa,0)),"Disponível"))) | F30: =IF(OR($B30="",$E30="Disponível"),"",IFERROR(INDEX(Aus_Fim,MATCH($B30,Aus_Ativa,0)),""))
E31: =IF($B31="","",IF($D31<>"Ativo",$D31,IFERROR(INDEX(Aus_Tipo,MATCH($B31,Aus_Ativa,0)),"Disponível"))) | F31: =IF(OR($B31="",$E31="Disponível"),"",IFERROR(INDEX(Aus_Fim,MATCH($B31,Aus_Ativa,0)),""))

Sheet Matriz_Habilidades
A1: Matrícula | B1: Nome do técnico | C1: Função | D1: =IF('Habilidades'!$B$2="","",'Habilidades'!$B$2) | E1: =IF('Habilidades'!$B$3="","",'Habilidades'!$B$3) | F1: =IF('Habilidades'!$B$4="","",'Habilidades'!$B$4) | G1: =IF('Habilidades'!$B$5="","",'Habilidades'!$B$5) | H1: =IF('Habilidades'!$B$6="","",'Habilidades'!$B$6) | I1: =IF('Habilidades'!$B$7="","",'Habilidades'!$B$7) | J1: =IF('Habilidades'!$B$8="","",'Habilidades'!$B$8) | K1: =IF('Habilidades'!$B$9="","",'Habilidades'!$B$9) | L1: =IF('Habilidades'!$B$10="","",'Habilidades'!$B$10) | M1: =IF('Habilidades'!$B$11="","",'Habilidades'!$B$11) | N1: =IF('Habilidades'!$B$12="","",'Habilidades'!$B$12) | O1: =IF('Habilidades'!$B$13="","",'Habilidades'!$B$13) | P1: =IF('Habilidades'!$B$14="","",'Habilidades'!$B$14) | Q1: =IF('Habilidades'!$B$15="","",'Habilidades'!$B$15) | R1: Nível médio (geral) | S1: Nº habilidades aptas (≥2)
A2: =IF('Equipe'!A2="","",'Equipe'!A2) | B2: =IF('Equipe'!B2="","",'Equipe'!B2) | C2: =IF('Equipe'!C2="","",'Equipe'!C2) | D2: 3 | E2: 2 | F2: 1 | G2: 1 | H2: 0 | I2: 0 | J2: 0 | K2: 1 | L2: 1 | M2: 1 | R2: =IF($B2="","",IFERROR(SUMPRODUCT((Matriz_Hab<>"")*$D2:$Q2)/SUMPRODUCT(--(Matriz_Hab<>"")),"")) | S2: =IF($B2="","",SUMPRODUCT((Matriz_Hab<>"")*($D2:$Q2>=2)))
A3: =IF('Equipe'!A3="","",'Equipe'!A3) | B3: =IF('Equipe'!B3="","",'Equipe'!B3) | C3: =IF('Equipe'!C3="","",'Equipe'!C3) | D3: 3 | E3: 1 | F3: 1 | G3: 0 | H3: 1 | I3: 0 | J3: 0 | K3: 1 | L3: 2 | M3: 0 | R3: =IF($B3="","",IFERROR(SUMPRODUCT((Matriz_Hab<>"")*$D3:$Q3)/SUMPRODUCT(--(Matriz_Hab<>"")),"")) | S3: =IF($B3="","",SUMPRODUCT((Matriz_Hab<>"")*($D3:$Q3>=2)))
A4: =IF('Equipe'!A4="","",'Equipe'!A4) | B4: =IF('Equipe'!B4="","",'Equipe'!B4) | C4: =IF('Equipe'!C4="","",'Equipe'!C4) | D4: 1 | E4: 3 | F4: 2 | G4: 2 | H4: 0 | I4: 1 | J4: 0 | K4: 0 | L4: 1 | M4: 1 | R4: =IF($B4="","",IFERROR(SUMPRODUCT((Matriz_Hab<>"")*$D4:$Q4)/SUMPRODUCT(--(Matriz_Hab<>"")),"")) | S4: =IF($B4="","",SUMPRODUCT((Matriz_Hab<>"")*($D4:$Q4>=2)))
A5: =IF('Equipe'!A5="","",'Equipe'!A5) | B5: =IF('Equipe'!B5="","",'Equipe'!B5) | C5: =IF('Equipe'!C5="","",'Equipe'!C5) | D5: 0 | E5: 3 | F5: 2 | G5: 1 | H5: 0 | I5: 0 | J5: 0 | K5: 0 | L5: 2 | M5: 1 | R5: =IF($B5="","",IFERROR(SUMPRODUCT((Matriz_Hab<>"")*$D5:$Q5)/SUMPRODUCT(--(Matriz_Hab<>"")),"")) | S5: =IF($B5="","",SUMPRODUCT((Matriz_Hab<>"")*($D5:$Q5>=2)))
A6: =IF('Equipe'!A6="","",'Equipe'!A6) | B6: =IF('Equipe'!B6="","",'Equipe'!B6) | C6: =IF('Equipe'!C6="","",'Equipe'!C6) | D6: 0 | E6: 0 | F6: 3 | G6: 2 | H6: 2 | I6: 0 | J6: 0 | K6: 0 | L6: 1 | M6: 0 | R6: =IF($B6="","",IFERROR(SUMPRODUCT((Matriz_Hab<>"")*$D6:$Q6)/SUMPRODUCT(--(Matriz_Hab<>"")),"")) | S6: =IF($B6="","",SUMPRODUCT((Matriz_Hab<>"")*($D6:$Q6>=2)))
A7: =IF('Equipe'!A7="","",'Equipe'!A7) | B7: =IF('Equipe'!B7="","",'Equipe'!B7) | C7: =IF('Equipe'!C7="","",'Equipe'!C7) | D7: 1 | E7: 0 | F7: 3 | G7: 2 | H7: 2 | I7: 0 | J7: 0 | K7: 1 | L7: 1 | M7: 0 | R7: =IF($B7="","",IFERROR(SUMPRODUCT((Matriz_Hab<>"")*$D7:$Q7)/SUMPRODUCT(--(Matriz_Hab<>"")),"")) | S7: =IF($B7="","",SUMPRODUCT((Matriz_Hab<>"")*($D7:$Q7>=2)))
A8: =IF('Equipe'!A8="","",'Equipe'!A8) | B8: =IF('Equipe'!B8="","",'Equipe'!B8) | C8: =IF('Equipe'!C8="","",'Equipe'!C8) | D8: 0 | E8: 1 | F8: 1 | G8: 0 | H8: 0 | I8: 1 | J8: 1 | K8: 3 | L8: 2 | M8: 2 | R8: =IF($B8="","",IFERROR(SUMPRODUCT((Matriz_Hab<>"")*$D8:$Q8)/SUMPRODUCT(--(Matriz_Hab<>"")),"")) | S8: =IF($B8="","",SUMPRODUCT((Matriz_Hab<>"")*($D8:$Q8>=2)))
A9: =IF('Equipe'!A9="","",'Equipe'!A9) | B9: =IF('Equipe'!B9="","",'Equipe'!B9) | C9: =IF('Equipe'!C9="","",'Equipe'!C9) | D9: 1 | E9: 1 | F9: 1 | G9: 0 | H9: 0 | I9: 0 | J9: 1 | K9: 3 | L9: 2 | M9: 1 | R9: =IF($B9="","",IFERROR(SUMPRODUCT((Matriz_Hab<>"")*$D9:$Q9)/SUMPRODUCT(--(Matriz_Hab<>"")),"")) | S9: =IF($B9="","",SUMPRODUCT((Matriz_Hab<>"")*($D9:$Q9>=2)))
A10: =IF('Equipe'!A10="","",'Equipe'!A10) | B10: =IF('Equipe'!B10="","",'Equipe'!B10) | C10: =IF('Equipe'!C10="","",'Equipe'!C10) | D10: 1 | E10: 0 | F10: 1 | G10: 0 | H10: 3 | I10: 2 | J10: 2 | K10: 1 | L10: 2 | M10: 1 | R10: =IF($B10="","",IFERROR(SUMPRODUCT((Matriz_Hab<>"")*$D10:$Q10)/SUMPRODUCT(--(Matriz_Hab<>"")),"")) | S10: =IF($B10="","",SUMPRODUCT((Matriz_Hab<>"")*($D10:$Q10>=2)))
A11: =IF('Equipe'!A11="","",'Equipe'!A11) | B11: =IF('Equipe'!B11="","",'Equipe'!B11) | C11: =IF('Equipe'!C11="","",'Equipe'!C11) | D11: 1 | E11: 1 | F11: 0 | G11: 1 | H11: 3 | I11: 1 | J11: 2 | K11: 1 | L11: 1 | M11: 1 | R11: =IF($B11="","",IFERROR(SUMPRODUCT((Matriz_Hab<>"")*$D11:$Q11)/SUMPRODUCT(--(Matriz_Hab<>"")),"")) | S11: =IF($B11="","",SUMPRODUCT((Matriz_Hab<>"")*($D11:$Q11>=2)))
A12: =IF('Equipe'!A12="","",'Equipe'!A12) | B12: =IF('Equipe'!B12="","",'Equipe'!B12) | C12: =IF('Equipe'!C12="","",'Equipe'!C12) | D12: 0 | E12: 0 | F12: 0 | G12: 0 | H12: 0 | I12: 3 | J12: 1 | K12: 1 | L12: 1 | M12: 0 | R12: =IF($B12="","",IFERROR(SUMPRODUCT((Matriz_Hab<>"")*$D12:$Q12)/SUMPRODUCT(--(Matriz_Hab<>"")),"")) | S12: =IF($B12="","",SUMPRODUCT((Matriz_Hab<>"")*($D12:$Q12>=2)))
A13: =IF('Equipe'!A13="","",'Equipe'!A13) | B13: =IF('Equipe'!B13="","",'Equipe'!B13) | C13: =IF('Equipe'!C13="","",'Equipe'!C13) | D13: 0 | E13: 0 | F13: 0 | G13: 1 | H13: 1 | I13: 3 | J13: 2 | K13: 1 | L13: 2 | M13: 1 | R13: =IF($B13="","",IFERROR(SUMPRODUCT((Matriz_Hab<>"")*$D13:$Q13)/SUMPRODUCT(--(Matriz_Hab<>"")),"")) | S13: =IF($B13="","",SUMPRODUCT((Matriz_Hab<>"")*($D13:$Q13>=2)))
... A23: =IF('Equipe'!A23="","",'Equipe'!A23) | B23: =IF('Equipe'!B23="","",'Equipe'!B23) | C23: =IF('Equipe'!C23="","",'Equipe'!C23) | D23: 1 | E23: 1 | F23: 1 | G23: 0 | H23: 1 | I23: 1 | J23: 0 | K23: 0 | L23: 3 | M23: 1 | R23: =IF($B23="","",IFERROR(SUMPRODUCT((Matriz_Hab<>"")*$D23:$Q23)/SUMPRODUCT(--(Matriz_Hab<>"")),"")) | S23: =IF($B23="","",SUMPRODUCT((Matriz_Hab<>"")*($D23:$Q23>=2)))
A24: =IF('Equipe'!A24="","",'Equipe'!A24) | B24: =IF('Equipe'!B24="","",'Equipe'!B24) | C24: =IF('Equipe'!C24="","",'Equipe'!C24) | R24: =IF($B24="","",IFERROR(SUMPRODUCT((Matriz_Hab<>"")*$D24:$Q24)/SUMPRODUCT(--(Matriz_Hab<>"")),"")) | S24: =IF($B24="","",SUMPRODUCT((Matriz_Hab<>"")*($D24:$Q24>=2)))
A25: =IF('Equipe'!A25="","",'Equipe'!A25) | B25: =IF('Equipe'!B25="","",'Equipe'!B25) | C25: =IF('Equipe'!C25="","",'Equipe'!C25) | R25: =IF($B25="","",IFERROR(SUMPRODUCT((Matriz_Hab<>"")*$D25:$Q25)/SUMPRODUCT(--(Matriz_Hab<>"")),"")) | S25: =IF($B25="","",SUMPRODUCT((Matriz_Hab<>"")*($D25:$Q25>=2)))
A26: =IF('Equipe'!A26="","",'Equipe'!A26) | B26: =IF('Equipe'!B26="","",'Equipe'!B26) | C26: =IF('Equipe'!C26="","",'Equipe'!C26) | R26: =IF($B26="","",IFERROR(SUMPRODUCT((Matriz_Hab<>"")*$D26:$Q26)/SUMPRODUCT(--(Matriz_Hab<>"")),"")) | S26: =IF($B26="","",SUMPRODUCT((Matriz_Hab<>"")*($D26:$Q26>=2)))
A27: =IF('Equipe'!A27="","",'Equipe'!A27) | B27: =IF('Equipe'!B27="","",'Equipe'!B27) | C27: =IF('Equipe'!C27="","",'Equipe'!C27) | R27: =IF($B27="","",IFERROR(SUMPRODUCT((Matriz_Hab<>"")*$D27:$Q27)/SUMPRODUCT(--(Matriz_Hab<>"")),"")) | S27: =IF($B27="","",SUMPRODUCT((Matriz_Hab<>"")*($D27:$Q27>=2)))
A28: =IF('Equipe'!A28="","",'Equipe'!A28) | B28: =IF('Equipe'!B28="","",'Equipe'!B28) | C28: =IF('Equipe'!C28="","",'Equipe'!C28) | R28: =IF($B28="","",IFERROR(SUMPRODUCT((Matriz_Hab<>"")*$D28:$Q28)/SUMPRODUCT(--(Matriz_Hab<>"")),"")) | S28: =IF($B28="","",SUMPRODUCT((Matriz_Hab<>"")*($D28:$Q28>=2)))
A29: =IF('Equipe'!A29="","",'Equipe'!A29) | B29: =IF('Equipe'!B29="","",'Equipe'!B29) | C29: =IF('Equipe'!C29="","",'Equipe'!C29) | R29: =IF($B29="","",IFERROR(SUMPRODUCT((Matriz_Hab<>"")*$D29:$Q29)/SUMPRODUCT(--(Matriz_Hab<>"")),"")) | S29: =IF($B29="","",SUMPRODUCT((Matriz_Hab<>"")*($D29:$Q29>=2)))
A30: =IF('Equipe'!A30="","",'Equipe'!A30) | B30: =IF('Equipe'!B30="","",'Equipe'!B30) | C30: =IF('Equipe'!C30="","",'Equipe'!C30) | R30: =IF($B30="","",IFERROR(SUMPRODUCT((Matriz_Hab<>"")*$D30:$Q30)/SUMPRODUCT(--(Matriz_Hab<>"")),"")) | S30: =IF($B30="","",SUMPRODUCT((Matriz_Hab<>"")*($D30:$Q30>=2)))
A31: =IF('Equipe'!A31="","",'Equipe'!A31) | B31: =IF('Equipe'!B31="","",'Equipe'!B31) | C31: =IF('Equipe'!C31="","",'Equipe'!C31) | R31: =IF($B31="","",IFERROR(SUMPRODUCT((Matriz_Hab<>"")*$D31:$Q31)/SUMPRODUCT(--(Matriz_Hab<>"")),"")) | S31: =IF($B31="","",SUMPRODUCT((Matriz_Hab<>"")*($D31:$Q31>=2)))

Sheet Ausencias
A1: Técnico | B1: Tipo | C1: Data início | D1: Data fim | E1: Dias | F1: Observação | G1: aux_ativa | H1: aux_cod
A2: Zuleide Marcon | B2: Férias | C2: 46244 | D2: 46258 | E2: =IF(OR($A2="",NOT(ISNUMBER($C2)),NOT(ISNUMBER($D2))),"",$D2-$C2+1) | F2: Férias programadas | G2: =IF(AND($A2<>"",ISNUMBER($C2),ISNUMBER($D2),$C2<=Data_Mapa,$D2>=Data_Mapa),$A2,"") | H2: =IF($A2="",0,IFERROR(MATCH($B2,Aus_Tipos,0),0))
A3: Ismael Kanitz | B3: Férias | C3: 46240 | D3: 46254 | E3: =IF(OR($A3="",NOT(ISNUMBER($C3)),NOT(ISNUMBER($D3))),"",$D3-$C3+1) | F3: Férias programadas | G3: =IF(AND($A3<>"",ISNUMBER($C3),ISNUMBER($D3),$C3<=Data_Mapa,$D3>=Data_Mapa),$A3,"") | H3: =IF($A3="",0,IFERROR(MATCH($B3,Aus_Tipos,0),0))
A4: Wanessa Piccoli | B4: Atestado | C4: 46253 | D4: 46255 | E4: =IF(OR($A4="",NOT(ISNUMBER($C4)),NOT(ISNUMBER($D4))),"",$D4-$C4+1) | F4: Atestado médico — 3 dias | G4: =IF(AND($A4<>"",ISNUMBER($C4),ISNUMBER($D4),$C4<=Data_Mapa,$D4>=Data_Mapa),$A4,"") | H4: =IF($A4="",0,IFERROR(MATCH($B4,Aus_Tipos,0),0))
A5: Elaine Mafra | B5: Folga | C5: 46254 | D5: 46254 | E5: =IF(OR($A5="",NOT(ISNUMBER($C5)),NOT(ISNUMBER($D5))),"",$D5-$C5+1) | F5: Folga da escala | G5: =IF(AND($A5<>"",ISNUMBER($C5),ISNUMBER($D5),$C5<=Data_Mapa,$D5>=Data_Mapa),$A5,"") | H5: =IF($A5="",0,IFERROR(MATCH($B5,Aus_Tipos,0),0))
A6: Adriana Salvi | B6: Folga | C6: 46246 | D6: 46246 | E6: =IF(OR($A6="",NOT(ISNUMBER($C6)),NOT(ISNUMBER($D6))),"",$D6-$C6+1) | G6: =IF(AND($A6<>"",ISNUMBER($C6),ISNUMBER($D6),$C6<=Data_Mapa,$D6>=Data_Mapa),$A6,"") | H6: =IF($A6="",0,IFERROR(MATCH($B6,Aus_Tipos,0),0))
A7: Bruna Cordeiro | B7: Folga | C7: 46247 | D7: 46247 | E7: =IF(OR($A7="",NOT(ISNUMBER($C7)),NOT(ISNUMBER($D7))),"",$D7-$C7+1) | G7: =IF(AND($A7<>"",ISNUMBER($C7),ISNUMBER($D7),$C7<=Data_Mapa,$D7>=Data_Mapa),$A7,"") | H7: =IF($A7="",0,IFERROR(MATCH($B7,Aus_Tipos,0),0))
A8: Camila Bertoldi | B8: Folga | C8: 46251 | D8: 46251 | E8: =IF(OR($A8="",NOT(ISNUMBER($C8)),NOT(ISNUMBER($D8))),"",$D8-$C8+1) | G8: =IF(AND($A8<>"",ISNUMBER($C8),ISNUMBER($D8),$C8<=Data_Mapa,$D8>=Data_Mapa),$A8,"") | H8: =IF($A8="",0,IFERROR(MATCH($B8,Aus_Tipos,0),0))
A9: Daiane Prestes | B9: Folga | C9: 46252 | D9: 46252 | E9: =IF(OR($A9="",NOT(ISNUMBER($C9)),NOT(ISNUMBER($D9))),"",$D9-$C9+1) | G9: =IF(AND($A9<>"",ISNUMBER($C9),ISNUMBER($D9),$C9<=Data_Mapa,$D9>=Data_Mapa),$A9,"") | H9: =IF($A9="",0,IFERROR(MATCH($B9,Aus_Tipos,0),0))
A10: Fernanda Klein | B10: Folga | C10: 46258 | D10: 46258 | E10: =IF(OR($A10="",NOT(ISNUMBER($C10)),NOT(ISNUMBER($D10))),"",$D10-$C10+1) | G10: =IF(AND($A10<>"",ISNUMBER($C10),ISNUMBER($D10),$C10<=Data_Mapa,$D10>=Data_Mapa),$A10,"") | H10: =IF($A10="",0,IFERROR(MATCH($B10,Aus_Tipos,0),0))
A11: Gisele Antunes | B11: Treinamento | C11: 46260 | D11: 46261 | E11: =IF(OR($A11="",NOT(ISNUMBER($C11)),NOT(ISNUMBER($D11))),"",$D11-$C11+1) | F11: Curso de CME | G11: =IF(AND($A11<>"",ISNUMBER($C11),ISNUMBER($D11),$C11<=Data_Mapa,$D11>=Data_Mapa),$A11,"") | H11: =IF($A11="",0,IFERROR(MATCH($B11,Aus_Tipos,0),0))
A12: Marcia Tonet | B12: Folga | C12: 46259 | D12: 46259 | E12: =IF(OR($A12="",NOT(ISNUMBER($C12)),NOT(ISNUMBER($D12))),"",$D12-$C12+1) | G12: =IF(AND($A12<>"",ISNUMBER($C12),ISNUMBER($D12),$C12<=Data_Mapa,$D12>=Data_Mapa),$A12,"") | H12: =IF($A12="",0,IFERROR(MATCH($B12,Aus_Tipos,0),0))
A13: Odair Bianchi | B13: Licença | C13: 46262 | D13: 46265 | E13: =IF(OR($A13="",NOT(ISNUMBER($C13)),NOT(ISNUMBER($D13))),"",$D13-$C13+1) | F13: Licença nojo | G13: =IF(AND($A13<>"",ISNUMBER($C13),ISNUMBER($D13),$C13<=Data_Mapa,$D13>=Data_Mapa),$A13,"") | H13: =IF($A13="",0,IFERROR(MATCH($B13,Aus_Tipos,0),0))
A14: Patrícia Zortéa | B14: Atestado | C14: 46239 | D14: 46240 | E14: =IF(OR($A14="",NOT(ISNUMBER($C14)),NOT(ISNUMBER($D14))),"",$D14-$C14+1) | F14: Atestado médico | G14: =IF(AND($A14<>"",ISNUMBER($C14),ISNUMBER($D14),$C14<=Data_Mapa,$D14>=Data_Mapa),$A14,"") | H14: =IF($A14="",0,IFERROR(MATCH($B14,Aus_Tipos,0),0))
E15: =IF(OR($A15="",NOT(ISNUMBER($C15)),NOT(ISNUMBER($D15))),"",$D15-$C15+1) | G15: =IF(AND($A15<>"",ISNUMBER($C15),ISNUMBER($D15),$C15<=Data_Mapa,$D15>=Data_Mapa),$A15,"") | H15: =IF($A15="",0,IFERROR(MATCH($B15,Aus_Tipos,0),0))
E16: =IF(OR($A16="",NOT(ISNUMBER($C16)),NOT(ISNUMBER($D16))),"",$D16-$C16+1) | G16: =IF(AND($A16<>"",ISNUMBER($C16),ISNUMBER($D16),$C16<=Data_Mapa,$D16>=Data_Mapa),$A16,"") | H16: =IF($A16="",0,IFERROR(MATCH($B16,Aus_Tipos,0),0))
E17: =IF(OR($A17="",NOT(ISNUMBER($C17)),NOT(ISNUMBER($D17))),"",$D17-$C17+1) | G17: =IF(AND($A17<>"",ISNUMBER($C17),ISNUMBER($D17),$C17<=Data_Mapa,$D17>=Data_Mapa),$A17,"") | H17: =IF($A17="",0,IFERROR(MATCH($B17,Aus_Tipos,0),0))
E18: =IF(OR($A18="",NOT(ISNUMBER($C18)),NOT(ISNUMBER($D18))),"",$D18-$C18+1) | G18: =IF(AND($A18<>"",ISNUMBER($C18),ISNUMBER($D18),$C18<=Data_Mapa,$D18>=Data_Mapa),$A18,"") | H18: =IF($A18="",0,IFERROR(MATCH($B18,Aus_Tipos,0),0))
E19: =IF(OR($A19="",NOT(ISNUMBER($C19)),NOT(ISNUMBER($D19))),"",$D19-$C19+1) | G19: =IF(AND($A19<>"",ISNUMBER($C19),ISNUMBER($D19),$C19<=Data_Mapa,$D19>=Data_Mapa),$A19,"") | H19: =IF($A19="",0,IFERROR(MATCH($B19,Aus_Tipos,0),0))
E20: =IF(OR($A20="",NOT(ISNUMBER($C20)),NOT(ISNUMBER($D20))),"",$D20-$C20+1) | G20: =IF(AND($A20<>"",ISNUMBER($C20),ISNUMBER($D20),$C20<=Data_Mapa,$D20>=Data_Mapa),$A20,"") | H20: =IF($A20="",0,IFERROR(MATCH($B20,Aus_Tipos,0),0))
E21: =IF(OR($A21="",NOT(ISNUMBER($C21)),NOT(ISNUMBER($D21))),"",$D21-$C21+1) | G21: =IF(AND($A21<>"",ISNUMBER($C21),ISNUMBER($D21),$C21<=Data_Mapa,$D21>=Data_Mapa),$A21,"") | H21: =IF($A21="",0,IFERROR(MATCH($B21,Aus_Tipos,0),0))
E22: =IF(OR($A22="",NOT(ISNUMBER($C22)),NOT(ISNUMBER($D22))),"",$D22-$C22+1) | G22: =IF(AND($A22<>"",ISNUMBER($C22),ISNUMBER($D22),$C22<=Data_Mapa,$D22>=Data_Mapa),$A22,"") | H22: =IF($A22="",0,IFERROR(MATCH($B22,Aus_Tipos,0),0))
E23: =IF(OR($A23="",NOT(ISNUMBER($C23)),NOT(ISNUMBER($D23))),"",$D23-$C23+1) | G23: =IF(AND($A23<>"",ISNUMBER($C23),ISNUMBER($D23),$C23<=Data_Mapa,$D23>=Data_Mapa),$A23,"") | H23: =IF($A23="",0,IFERROR(MATCH($B23,Aus_Tipos,0),0))
E24: =IF(OR($A24="",NOT(ISNUMBER($C24)),NOT(ISNUMBER($D24))),"",$D24-$C24+1) | G24: =IF(AND($A24<>"",ISNUMBER($C24),ISNUMBER($D24),$C24<=Data_Mapa,$D24>=Data_Mapa),$A24,"") | H24: =IF($A24="",0,IFERROR(MATCH($B24,Aus_Tipos,0),0))
E25: =IF(OR($A25="",NOT(ISNUMBER($C25)),NOT(ISNUMBER($D25))),"",$D25-$C25+1) | G25: =IF(AND($A25<>"",ISNUMBER($C25),ISNUMBER($D25),$C25<=Data_Mapa,$D25>=Data_Mapa),$A25,"") | H25: =IF($A25="",0,IFERROR(MATCH($B25,Aus_Tipos,0),0))
E26: =IF(OR($A26="",NOT(ISNUMBER($C26)),NOT(ISNUMBER($D26))),"",$D26-$C26+1) | G26: =IF(AND($A26<>"",ISNUMBER($C26),ISNUMBER($D26),$C26<=Data_Mapa,$D26>=Data_Mapa),$A26,"") | H26: =IF($A26="",0,IFERROR(MATCH($B26,Aus_Tipos,0),0))
... E151: =IF(OR($A151="",NOT(ISNUMBER($C151)),NOT(ISNUMBER($D151))),"",$D151-$C151+1) | G151: =IF(AND($A151<>"",ISNUMBER($C151),ISNUMBER($D151),$C151<=Data_Mapa,$D151>=Data_Mapa),$A151,"") | H151: =IF($A151="",0,IFERROR(MATCH($B151,Aus_Tipos,0),0))

Sheet Calendario_Ausencias
A1: CALENDÁRIO DE AUSÊNCIAS | C1: =DATE(YEAR(Data_Mapa),MONTH(Data_Mapa),1) | L1: F = Férias · D = Folga · A = Atestado · L = Licença · T = Treinamento · ! = registros sobrepostos
A2: Matrícula | B2: Nome do técnico | C2: =$C$1 | D2: =IF(MONTH(C2+1)=MONTH($C$1),C2+1,"") | E2: =IF(MONTH(D2+1)=MONTH($C$1),D2+1,"") | F2: =IF(MONTH(E2+1)=MONTH($C$1),E2+1,"") | G2: =IF(MONTH(F2+1)=MONTH($C$1),F2+1,"") | H2: =IF(MONTH(G2+1)=MONTH($C$1),G2+1,"") | I2: =IF(MONTH(H2+1)=MONTH($C$1),H2+1,"") | J2: =IF(MONTH(I2+1)=MONTH($C$1),I2+1,"") | K2: =IF(MONTH(J2+1)=MONTH($C$1),J2+1,"") | ... AG2: =IF(MONTH(AF2+1)=MONTH($C$1),AF2+1,"") | AH2: Férias | AI2: Folgas | AJ2: Atestados | AK2: Dias ausente
C3: =IF(C2="","",CHOOSE(WEEKDAY(C2),"dom","seg","ter","qua","qui","sex","sáb")) | D3: =IF(D2="","",CHOOSE(WEEKDAY(D2),"dom","seg","ter","qua","qui","sex","sáb")) | E3: =IF(E2="","",CHOOSE(WEEKDAY(E2),"dom","seg","ter","qua","qui","sex","sáb")) | F3: =IF(F2="","",CHOOSE(WEEKDAY(F2),"dom","seg","ter","qua","qui","sex","sáb")) | G3: =IF(G2="","",CHOOSE(WEEKDAY(G2),"dom","seg","ter","qua","qui","sex","sáb")) | H3: =IF(H2="","",CHOOSE(WEEKDAY(H2),"dom","seg","ter","qua","qui","sex","sáb")) | I3: =IF(I2="","",CHOOSE(WEEKDAY(I2),"dom","seg","ter","qua","qui","sex","sáb")) | J3: =IF(J2="","",CHOOSE(WEEKDAY(J2),"dom","seg","ter","qua","qui","sex","sáb")) | ... AG3: =IF(AG2="","",CHOOSE(WEEKDAY(AG2),"dom","seg","ter","qua","qui","sex","sáb"))
A4: =IF('Equipe'!A2="","",'Equipe'!A2) | B4: =IF('Equipe'!B2="","",'Equipe'!B2) | C4: =IF(OR($B4="",C$2=""),"",IF(SUMPRODUCT((Aus_Tec=$B4)*(Aus_Ini<=C$2)*(Aus_Fim>=C$2)*(Aus_Cod>0))=0,"",IF(SUMPRODUCT((Aus_Tec=$B4)*(Aus_Ini<=C$2)*(Aus_Fim>=C$2)*(Aus_Cod>0))>1,"!",IFERROR(INDEX(Aus_Siglas,SUMPRODUCT((Aus_Tec=$B4)*(Aus_Ini<=C$2)*(Aus_Fim>=C$2)*Aus_Cod)),"!")))) | D4: =IF(OR($B4="",D$2=""),"",IF(SUMPRODUCT((Aus_Tec=$B4)*(Aus_Ini<=D$2)*(Aus_Fim>=D$2)*(Aus_Cod>0))=0,"",IF(SUMPRODUCT((Aus_Tec=$B4)*(Aus_Ini<=D$2)*(Aus_Fim>=D$2)*(Aus_Cod>0))>1,"!",IFERROR(INDEX(Aus_Siglas,SUMPRODUCT((Aus_Tec=$B4)*(Aus_Ini<=D$2)*(Aus_Fim>=D$2)*Aus_Cod)),"!")))) | E4: =IF(OR($B4="",E$2=""),"",IF(SUMPRODUCT((Aus_Tec=$B4)*(Aus_Ini<=E$2)*(Aus_Fim>=E$2)*(Aus_Cod>0))=0,"",IF(SUMPRODUCT((Aus_Tec=$B4)*(Aus_Ini<=E$2)*(Aus_Fim>=E$2)*(Aus_Cod>0))>1,"!",IFERROR(INDEX(Aus_Siglas,SUMPRODUCT((Aus_Tec=$B4)*(Aus_Ini<=E$2)*(Aus_Fim>=E$2)*Aus_Cod)),"!")))) | F4: =IF(OR($B4="",F$2=""),"",IF(SUMPRODUCT((Aus_Tec=$B4)*(Aus_Ini<=F$2)*(Aus_Fim>=F$2)*(Aus_Cod>0))=0,"",IF(SUMPRODUCT((Aus_Tec=$B4)*(Aus_Ini<=F$2)*(Aus_Fim>=F$2)*(Aus_Cod>0))>1,"!",IFERROR(INDEX(Aus_Siglas,SUMPRODUCT((Aus_Tec=$B4)*(Aus_Ini<=F$2)*(Aus_Fim>=F$2)*Aus_Cod)),"!")))) | G4: =IF(OR($B4="",G$2=""),"",IF(SUMPRODUCT((Aus_Tec=$B4)*(Aus_Ini<=G$2)*(Aus_Fim>=G$2)*(Aus_Cod>0))=0,"",IF(SUMPRODUCT((Aus_Tec=$B4)*(Aus_Ini<=G$2)*(Aus_Fim>=G$2)*(Aus_Cod>0))>1,"!",IFERROR(INDEX(Aus_Siglas,SUMPRODUCT((Aus_Tec=$B4)*(Aus_Ini<=G$2)*(Aus_Fim>=G$2)*Aus_Cod)),"!")))) | H4: =IF(OR($B4="",H$2=""),"",IF(SUMPRODUCT((Aus_Tec=$B4)*(Aus_Ini<=H$2)*(Aus_Fim>=H$2)*(Aus_Cod>0))=0,"",IF(SUMPRODUCT((Aus_Tec=$B4)*(Aus_Ini<=H$2)*(Aus_Fim>=H$2)*(Aus_Cod>0))>1,"!",IFERROR(INDEX(Aus_Siglas,SUMPRODUCT((Aus_Tec=$B4)*(Aus_Ini<=H$2)*(Aus_Fim>=H$2)*Aus_Cod)),"!")))) | I4: =IF(OR($B4="",I$2=""),"",IF(SUMPRODUCT((Aus_Tec=$B4)*(Aus_Ini<=I$2)*(Aus_Fim>=I$2)*(Aus_Cod>0))=0,"",IF(SUMPRODUCT((Aus_Tec=$B4)*(Aus_Ini<=I$2)*(Aus_Fim>=I$2)*(Aus_Cod>0))>1,"!",IFERROR(INDEX(Aus_Siglas,SUMPRODUCT((Aus_Tec=$B4)*(Aus_Ini<=I$2)*(Aus_Fim>=I$2)*Aus_Cod)),"!")))) | J4: =IF(OR($B4="",J$2=""),"",IF(SUMPRODUCT((Aus_Tec=$B4)*(Aus_Ini<=J$2)*(Aus_Fim>=J$2)*(Aus_Cod>0))=0,"",IF(SUMPRODUCT((Aus_Tec=$B4)*(Aus_Ini<=J$2)*(Aus_Fim>=J$2)*(Aus_Cod>0))>1,"!",IFERROR(INDEX(Aus_Siglas,SUMPRODUCT((Aus_Tec=$B4)*(Aus_Ini<=J$2)*(Aus_Fim>=J$2)*Aus_Cod)),"!")))) | ... AG4: =IF(OR($B4="",AG$2=""),"",IF(SUMPRODUCT((Aus_Tec=$B4)*(Aus_Ini<=AG$2)*(Aus_Fim>=AG$2)*(Aus_Cod>0))=0,"",IF(SUMPRODUCT((Aus_Tec=$B4)*(Aus_Ini<=AG$2)*(Aus_Fim>=AG$2)*(Aus_Cod>0))>1,"!",IFERROR(INDEX(Aus_Siglas,SUMPRODUCT((Aus_Tec=$B4)*(Aus_Ini<=AG$2)*(Aus_Fim>=AG$2)*Aus_Cod)),"!")))) | AH4: =IF($B4="","",COUNTIF($C4:$AG4,"F")) | AI4: =IF($B4="","",COUNTIF($C4:$AG4,"D")) | AJ4: =IF($B4="","",COUNTIF($C4:$AG4,"A")) | AK4: =IF($B4="","",SUMPRODUCT(($C4:$AG4<>"")*1))
A5: =IF('Equipe'!A3="","",'Equipe'!A3) | B5: =IF('Equipe'!B3="","",'Equipe'!B3) | C5: =IF(OR($B5="",C$2=""),"",IF(SUMPRODUCT((Aus_Tec=$B5)*(Aus_Ini<=C$2)*(Aus_Fim>=C$2)*(Aus_Cod>0))=0,"",IF(SUMPRODUCT((Aus_Tec=$B5)*(Aus_Ini<=C$2)*(Aus_Fim>=C$2)*(Aus_Cod>0))>1,"!",IFERROR(INDEX(Aus_Siglas,SUMPRODUCT((Aus_Tec=$B5)*(Aus_Ini<=C$2)*(Aus_Fim>=C$2)*Aus_Cod)),"!")))) | D5: =IF(OR($B5="",D$2=""),"",IF(SUMPRODUCT((Aus_Tec=$B5)*(Aus_Ini<=D$2)*(Aus_Fim>=D$2)*(Aus_Cod>0))=0,"",IF(SUMPRODUCT((Aus_Tec=$B5)*(Aus_Ini<=D$2)*(Aus_Fim>=D$2)*(Aus_Cod>0))>1,"!",IFERROR(INDEX(Aus_Siglas,SUMPRODUCT((Aus_Tec=$B5)*(Aus_Ini<=D$2)*(Aus_Fim>=D$2)*Aus_Cod)),"!")))) | E5: =IF(OR($B5="",E$2=""),"",IF(SUMPRODUCT((Aus_Tec=$B5)*(Aus_Ini<=E$2)*(Aus_Fim>=E$2)*(Aus_Cod>0))=0,"",IF(SUMPRODUCT((Aus_Tec=$B5)*(Aus_Ini<=E$2)*(Aus_Fim>=E$2)*(Aus_Cod>0))>1,"!",IFERROR(INDEX(Aus_Siglas,SUMPRODUCT((Aus_Tec=$B5)*(Aus_Ini<=E$2)*(Aus_Fim>=E$2)*Aus_Cod)),"!")))) | F5: =IF(OR($B5="",F$2=""),"",IF(SUMPRODUCT((Aus_Tec=$B5)*(Aus_Ini<=F$2)*(Aus_Fim>=F$2)*(Aus_Cod>0))=0,"",IF(SUMPRODUCT((Aus_Tec=$B5)*(Aus_Ini<=F$2)*(Aus_Fim>=F$2)*(Aus_Cod>0))>1,"!",IFERROR(INDEX(Aus_Siglas,SUMPRODUCT((Aus_Tec=$B5)*(Aus_Ini<=F$2)*(Aus_Fim>=F$2)*Aus_Cod)),"!")))) | G5: =IF(OR($B5="",G$2=""),"",IF(SUMPRODUCT((Aus_Tec=$B5)*(Aus_Ini<=G$2)*(Aus_Fim>=G$2)*(Aus_Cod>0))=0,"",IF(SUMPRODUCT((Aus_Tec=$B5)*(Aus_Ini<=G$2)*(Aus_Fim>=G$2)*(Aus_Cod>0))>1,"!",IFERROR(INDEX(Aus_Siglas,SUMPRODUCT((Aus_Tec=$B5)*(Aus_Ini<=G$2)*(Aus_Fim>=G$2)*Aus_Cod)),"!")))) | H5: =IF(OR($B5="",H$2=""),"",IF(SUMPRODUCT((Aus_Tec=$B5)*(Aus_Ini<=H$2)*(Aus_Fim>=H$2)*(Aus_Cod>0))=0,"",IF(SUMPRODUCT((Aus_Tec=$B5)*(Aus_Ini<=H$2)*(Aus_Fim>=H$2)*(Aus_Cod>0))>1,"!",IFERROR(INDEX(Aus_Siglas,SUMPRODUCT((Aus_Tec=$B5)*(Aus_Ini<=H$2)*(Aus_Fim>=H$2)*Aus_Cod)),"!")))) | I5: =IF(OR($B5="",I$2=""),"",IF(SUMPRODUCT((Aus_Tec=$B5)*(Aus_Ini<=I$2)*(Aus_Fim>=I$2)*(Aus_Cod>0))=0,"",IF(SUMPRODUCT((Aus_Tec=$B5)*(Aus_Ini<=I$2)*(Aus_Fim>=I$2)*(Aus_Cod>0))>1,"!",IFERROR(INDEX(Aus_Siglas,SUMPRODUCT((Aus_Tec=$B5)*(Aus_Ini<=I$2)*(Aus_Fim>=I$2)*Aus_Cod)),"!")))) | J5: =IF(OR($B5="",J$2=""),"",IF(SUMPRODUCT((Aus_Tec=$B5)*(Aus_Ini<=J$2)*(Aus_Fim>=J$2)*(Aus_Cod>0))=0,"",IF(SUMPRODUCT((Aus_Tec=$B5)*(Aus_Ini<=J$2)*(Aus_Fim>=J$2)*(Aus_Cod>0))>1,"!",IFERROR(INDEX(Aus_Siglas,SUMPRODUCT((Aus_Tec=$B5)*(Aus_Ini<=J$2)*(Aus_Fim>=J$2)*Aus_Cod)),"!")))) | ... AG5: =IF(OR($B5="",AG$2=""),"",IF(SUMPRODUCT((Aus_Tec=$B5)*(Aus_Ini<=AG$2)*(Aus_Fim>=AG$2)*(Aus_Cod>0))=0,"",IF(SUMPRODUCT((Aus_Tec=$B5)*(Aus_Ini<=AG$2)*(Aus_Fim>=AG$2)*(Aus_Cod>0))>1,"!",IFERROR(INDEX(Aus_Siglas,SUMPRODUCT((Aus_Tec=$B5)*(Aus_Ini<=AG$2)*(Aus_Fim>=AG$2)*Aus_Cod)),"!")))) | AH5: =IF($B5="","",COUNTIF($C5:$AG5,"F")) | AI5: =IF($B5="","",COUNTIF($C5:$AG5,"D")) | AJ5: =IF($B5="","",COUNTIF($C5:$AG5,"A")) | AK5: =IF($B5="","",SUMPRODUCT(($C5:$AG5<>"")*1))
A6: =IF('Equipe'!A4="","",'Equipe'!A4) | B6: =IF('Equipe'!B4="","",'Equipe'!B4) | C6: =IF(OR($B6="",C$2=""),"",IF(SUMPRODUCT((Aus_Tec=$B6)*(Aus_Ini<=C$2)*(Aus_Fim>=C$2)*(Aus_Cod>0))=0,"",IF(SUMPRODUCT((Aus_Tec=$B6)*(Aus_Ini<=C$2)*(Aus_Fim>=C$2)*(Aus_Cod>0))>1,"!",IFERROR(INDEX(Aus_Siglas,SUMPRODUCT((Aus_Tec=$B6)*(Aus_Ini<=C$2)*(Aus_Fim>=C$2)*Aus_Cod)),"!")))) | D6: =IF(OR($B6="",D$2=""),"",IF(SUMPRODUCT((Aus_Tec=$B6)*(Aus_Ini<=D$2)*(Aus_Fim>=D$2)*(Aus_Cod>0))=0,"",IF(SUMPRODUCT((Aus_Tec=$B6)*(Aus_Ini<=D$2)*(Aus_Fim>=D$2)*(Aus_Cod>0))>1,"!",IFERROR(INDEX(Aus_Siglas,SUMPRODUCT((Aus_Tec=$B6)*(Aus_Ini<=D$2)*(Aus_Fim>=D$2)*Aus_Cod)),"!")))) | E6: =IF(OR($B6="",E$2=""),"",IF(SUMPRODUCT((Aus_Tec=$B6)*(Aus_Ini<=E$2)*(Aus_Fim>=E$2)*(Aus_Cod>0))=0,"",IF(SUMPRODUCT((Aus_Tec=$B6)*(Aus_Ini<=E$2)*(Aus_Fim>=E$2)*(Aus_Cod>0))>1,"!",IFERROR(INDEX(Aus_Siglas,SUMPRODUCT((Aus_Tec=$B6)*(Aus_Ini<=E$2)*(Aus_Fim>=E$2)*Aus_Cod)),"!")))) | F6: =IF(OR($B6="",F$2=""),"",IF(SUMPRODUCT((Aus_Tec=$B6)*(Aus_Ini<=F$2)*(Aus_Fim>=F$2)*(Aus_Cod>0))=0,"",IF(SUMPRODUCT((Aus_Tec=$B6)*(Aus_Ini<=F$2)*(Aus_Fim>=F$2)*(Aus_Cod>0))>1,"!",IFERROR(INDEX(Aus_Siglas,SUMPRODUCT((Aus_Tec=$B6)*(Aus_Ini<=F$2)*(Aus_Fim>=F$2)*Aus_Cod)),"!")))) | G6: =IF(OR($B6="",G$2=""),"",IF(SUMPRODUCT((Aus_Tec=$B6)*(Aus_Ini<=G$2)*(Aus_Fim>=G$2)*(Aus_Cod>0))=0,"",IF(SUMPRODUCT((Aus_Tec=$B6)*(Aus_Ini<=G$2)*(Aus_Fim>=G$2)*(Aus_Cod>0))>1,"!",IFERROR(INDEX(Aus_Siglas,SUMPRODUCT((Aus_Tec=$B6)*(Aus_Ini<=G$2)*(Aus_Fim>=G$2)*Aus_Cod)),"!")))) | H6: =IF(OR($B6="",H$2=""),"",IF(SUMPRODUCT((Aus_Tec=$B6)*(Aus_Ini<=H$2)*(Aus_Fim>=H$2)*(Aus_Cod>0))=0,"",IF(SUMPRODUCT((Aus_Tec=$B6)*(Aus_Ini<=H$2)*(Aus_Fim>=H$2)*(Aus_Cod>0))>1,"!",IFERROR(INDEX(Aus_Siglas,SUMPRODUCT((Aus_Tec=$B6)*(Aus_Ini<=H$2)*(Aus_Fim>=H$2)*Aus_Cod)),"!")))) | I6: =IF(OR($B6="",I$2=""),"",IF(SUMPRODUCT((Aus_Tec=$B6)*(Aus_Ini<=I$2)*(Aus_Fim>=I$2)*(Aus_Cod>0))=0,"",IF(SUMPRODUCT((Aus_Tec=$B6)*(Aus_Ini<=I$2)*(Aus_Fim>=I$2)*(Aus_Cod>0))>1,"!",IFERROR(INDEX(Aus_Siglas,SUMPRODUCT((Aus_Tec=$B6)*(Aus_Ini<=I$2)*(Aus_Fim>=I$2)*Aus_Cod)),"!")))) | J6: =IF(OR($B6="",J$2=""),"",IF(SUMPRODUCT((Aus_Tec=$B6)*(Aus_Ini<=J$2)*(Aus_Fim>=J$2)*(Aus_Cod>0))=0,"",IF(SUMPRODUCT((Aus_Tec=$B6)*(Aus_Ini<=J$2)*(Aus_Fim>=J$2)*(Aus_Cod>0))>1,"!",IFERROR(INDEX(Aus_Siglas,SUMPRODUCT((Aus_Tec=$B6)*(Aus_Ini<=J$2)*(Aus_Fim>=J$2)*Aus_Cod)),"!")))) | ... AG6: =IF(OR($B6="",AG$2=""),"",IF(SUMPRODUCT((Aus_Tec=$B6)*(Aus_Ini<=AG$2)*(Aus_Fim>=AG$2)*(Aus_Cod>0))=0,"",IF(SUMPRODUCT((Aus_Tec=$B6)*(Aus_Ini<=AG$2)*(Aus_Fim>=AG$2)*(Aus_Cod>0))>1,"!",IFERROR(INDEX(Aus_Siglas,SUMPRODUCT((Aus_Tec=$B6)*(Aus_Ini<=AG$2)*(Aus_Fim>=AG$2)*Aus_Cod)),"!")))) | AH6: =IF($B6="","",COUNTIF($C6:$AG6,"F")) | AI6: =IF($B6="","",COUNTIF($C6:$AG6,"D")) | AJ6: =IF($B6="","",COUNTIF($C6:$AG6,"A")) | AK6: =IF($B6="","",SUMPRODUCT(($C6:$AG6<>"")*1))
A7: =IF('Equipe'!A5="","",'Equipe'!A5) | B7: =IF('Equipe'!B5="","",'Equipe'!B5) | C7: =IF(OR($B7="",C$2=""),"",IF(SUMPRODUCT((Aus_Tec=$B7)*(Aus_Ini<=C$2)*(Aus_Fim>=C$2)*(Aus_Cod>0))=0,"",IF(SUMPRODUCT((Aus_Tec=$B7)*(Aus_Ini<=C$2)*(Aus_Fim>=C$2)*(Aus_Cod>0))>1,"!",IFERROR(INDEX(Aus_Siglas,SUMPRODUCT((Aus_Tec=$B7)*(Aus_Ini<=C$2)*(Aus_Fim>=C$2)*Aus_Cod)),"!")))) | D7: =IF(OR($B7="",D$2=""),"",IF(SUMPRODUCT((Aus_Tec=$B7)*(Aus_Ini<=D$2)*(Aus_Fim>=D$2)*(Aus_Cod>0))=0,"",IF(SUMPRODUCT((Aus_Tec=$B7)*(Aus_Ini<=D$2)*(Aus_Fim>=D$2)*(Aus_Cod>0))>1,"!",IFERROR(INDEX(Aus_Siglas,SUMPRODUCT((Aus_Tec=$B7)*(Aus_Ini<=D$2)*(Aus_Fim>=D$2)*Aus_Cod)),"!")))) | E7: =IF(OR($B7="",E$2=""),"",IF(SUMPRODUCT((Aus_Tec=$B7)*(Aus_Ini<=E$2)*(Aus_Fim>=E$2)*(Aus_Cod>0))=0,"",IF(SUMPRODUCT((Aus_Tec=$B7)*(Aus_Ini<=E$2)*(Aus_Fim>=E$2)*(Aus_Cod>0))>1,"!",IFERROR(INDEX(Aus_Siglas,SUMPRODUCT((Aus_Tec=$B7)*(Aus_Ini<=E$2)*(Aus_Fim>=E$2)*Aus_Cod)),"!")))) | F7: =IF(OR($B7="",F$2=""),"",IF(SUMPRODUCT((Aus_Tec=$B7)*(Aus_Ini<=F$2)*(Aus_Fim>=F$2)*(Aus_Cod>0))=0,"",IF(SUMPRODUCT((Aus_Tec=$B7)*(Aus_Ini<=F$2)*(Aus_Fim>=F$2)*(Aus_Cod>0))>1,"!",IFERROR(INDEX(Aus_Siglas,SUMPRODUCT((Aus_Tec=$B7)*(Aus_Ini<=F$2)*(Aus_Fim>=F$2)*Aus_Cod)),"!")))) | G7: =IF(OR($B7="",G$2=""),"",IF(SUMPRODUCT((Aus_Tec=$B7)*(Aus_Ini<=G$2)*(Aus_Fim>=G$2)*(Aus_Cod>0))=0,"",IF(SUMPRODUCT((Aus_Tec=$B7)*(Aus_Ini<=G$2)*(Aus_Fim>=G$2)*(Aus_Cod>0))>1,"!",IFERROR(INDEX(Aus_Siglas,SUMPRODUCT((Aus_Tec=$B7)*(Aus_Ini<=G$2)*(Aus_Fim>=G$2)*Aus_Cod)),"!")))) | H7: =IF(OR($B7="",H$2=""),"",IF(SUMPRODUCT((Aus_Tec=$B7)*(Aus_Ini<=H$2)*(Aus_Fim>=H$2)*(Aus_Cod>0))=0,"",IF(SUMPRODUCT((Aus_Tec=$B7)*(Aus_Ini<=H$2)*(Aus_Fim>=H$2)*(Aus_Cod>0))>1,"!",IFERROR(INDEX(Aus_Siglas,SUMPRODUCT((Aus_Tec=$B7)*(Aus_Ini<=H$2)*(Aus_Fim>=H$2)*Aus_Cod)),"!")))) | I7: =IF(OR($B7="",I$2=""),"",IF(SUMPRODUCT((Aus_Tec=$B7)*(Aus_Ini<=I$2)*(Aus_Fim>=I$2)*(Aus_Cod>0))=0,"",IF(SUMPRODUCT((Aus_Tec=$B7)*(Aus_Ini<=I$2)*(Aus_Fim>=I$2)*(Aus_Cod>0))>1,"!",IFERROR(INDEX(Aus_Siglas,SUMPRODUCT((Aus_Tec=$B7)*(Aus_Ini<=I$2)*(Aus_Fim>=I$2)*Aus_Cod)),"!")))) | J7: =IF(OR($B7="",J$2=""),"",IF(SUMPRODUCT((Aus_Tec=$B7)*(Aus_Ini<=J$2)*(Aus_Fim>=J$2)*(Aus_Cod>0))=0,"",IF(SUMPRODUCT((Aus_Tec=$B7)*(Aus_Ini<=J$2)*(Aus_Fim>=J$2)*(Aus_Cod>0))>1,"!",IFERROR(INDEX(Aus_Siglas,SUMPRODUCT((Aus_Tec=$B7)*(Aus_Ini<=J$2)*(Aus_Fim>=J$2)*Aus_Cod)),"!")))) | ... AG7: =IF(OR($B7="",AG$2=""),"",IF(SUMPRODUCT((Aus_Tec=$B7)*(Aus_Ini<=AG$2)*(Aus_Fim>=AG$2)*(Aus_Cod>0))=0,"",IF(SUMPRODUCT((Aus_Tec=$B7)*(Aus_Ini<=AG$2)*(Aus_Fim>=AG$2)*(Aus_Cod>0))>1,"!",IFERROR(INDEX(Aus_Siglas,SUMPRODUCT((Aus_Tec=$B7)*(Aus_Ini<=AG$2)*(Aus_Fim>=AG$2)*Aus_Cod)),"!")))) | AH7: =IF($B7="","",COUNTIF($C7:$AG7,"F")) | AI7: =IF($B7="","",COUNTIF($C7:$AG7,"D")) | AJ7: =IF($B7="","",COUNTIF($C7:$AG7,"A")) | AK7: =IF($B7="","",SUMPRODUCT(($C7:$AG7<>"")*1))
A8: =IF('Equipe'!A6="","",'Equipe'!A6) | B8: =IF('Equipe'!B6="","",'Equipe'!B6) | C8: =IF(OR($B8="",C$2=""),"",IF(SUMPRODUCT((Aus_Tec=$B8)*(Aus_Ini<=C$2)*(Aus_Fim>=C$2)*(Aus_Cod>0))=0,"",IF(SUMPRODUCT((Aus_Tec=$B8)*(Aus_Ini<=C$2)*(Aus_Fim>=C$2)*(Aus_Cod>0))>1,"!",IFERROR(INDEX(Aus_Siglas,SUMPRODUCT((Aus_Tec=$B8)*(Aus_Ini<=C$2)*(Aus_Fim>=C$2)*Aus_Cod)),"!")))) | D8: =IF(OR($B8="",D$2=""),"",IF(SUMPRODUCT((Aus_Tec=$B8)*(Aus_Ini<=D$2)*(Aus_Fim>=D$2)*(Aus_Cod>0))=0,"",IF(SUMPRODUCT((Aus_Tec=$B8)*(Aus_Ini<=D$2)*(Aus_Fim>=D$2)*(Aus_Cod>0))>1,"!",IFERROR(INDEX(Aus_Siglas,SUMPRODUCT((Aus_Tec=$B8)*(Aus_Ini<=D$2)*(Aus_Fim>=D$2)*Aus_Cod)),"!")))) | E8: =IF(OR($B8="",E$2=""),"",IF(SUMPRODUCT((Aus_Tec=$B8)*(Aus_Ini<=E$2)*(Aus_Fim>=E$2)*(Aus_Cod>0))=0,"",IF(SUMPRODUCT((Aus_Tec=$B8)*(Aus_Ini<=E$2)*(Aus_Fim>=E$2)*(Aus_Cod>0))>1,"!",IFERROR(INDEX(Aus_Siglas,SUMPRODUCT((Aus_Tec=$B8)*(Aus_Ini<=E$2)*(Aus_Fim>=E$2)*Aus_Cod)),"!")))) | F8: =IF(OR($B8="",F$2=""),"",IF(SUMPRODUCT((Aus_Tec=$B8)*(Aus_Ini<=F$2)*(Aus_Fim>=F$2)*(Aus_Cod>0))=0,"",IF(SUMPRODUCT((Aus_Tec=$B8)*(Aus_Ini<=F$2)*(Aus_Fim>=F$2)*(Aus_Cod>0))>1,"!",IFERROR(INDEX(Aus_Siglas,SUMPRODUCT((Aus_Tec=$B8)*(Aus_Ini<=F$2)*(Aus_Fim>=F$2)*Aus_Cod)),"!")))) | G8: =IF(OR($B8="",G$2=""),"",IF(SUMPRODUCT((Aus_Tec=$B8)*(Aus_Ini<=G$2)*(Aus_Fim>=G$2)*(Aus_Cod>0))=0,"",IF(SUMPRODUCT((Aus_Tec=$B8)*(Aus_Ini<=G$2)*(Aus_Fim>=G$2)*(Aus_Cod>0))>1,"!",IFERROR(INDEX(Aus_Siglas,SUMPRODUCT((Aus_Tec=$B8)*(Aus_Ini<=G$2)*(Aus_Fim>=G$2)*Aus_Cod)),"!")))) | H8: =IF(OR($B8="",H$2=""),"",IF(SUMPRODUCT((Aus_Tec=$B8)*(Aus_Ini<=H$2)*(Aus_Fim>=H$2)*(Aus_Cod>0))=0,"",IF(SUMPRODUCT((Aus_Tec=$B8)*(Aus_Ini<=H$2)*(Aus_Fim>=H$2)*(Aus_Cod>0))>1,"!",IFERROR(INDEX(Aus_Siglas,SUMPRODUCT((Aus_Tec=$B8)*(Aus_Ini<=H$2)*(Aus_Fim>=H$2)*Aus_Cod)),"!")))) | I8: =IF(OR($B8="",I$2=""),"",IF(SUMPRODUCT((Aus_Tec=$B8)*(Aus_Ini<=I$2)*(Aus_Fim>=I$2)*(Aus_Cod>0))=0,"",IF(SUMPRODUCT((Aus_Tec=$B8)*(Aus_Ini<=I$2)*(Aus_Fim>=I$2)*(Aus_Cod>0))>1,"!",IFERROR(INDEX(Aus_Siglas,SUMPRODUCT((Aus_Tec=$B8)*(Aus_Ini<=I$2)*(Aus_Fim>=I$2)*Aus_Cod)),"!")))) | J8: =IF(OR($B8="",J$2=""),"",IF(SUMPRODUCT((Aus_Tec=$B8)*(Aus_Ini<=J$2)*(Aus_Fim>=J$2)*(Aus_Cod>0))=0,"",IF(SUMPRODUCT((Aus_Tec=$B8)*(Aus_Ini<=J$2)*(Aus_Fim>=J$2)*(Aus_Cod>0))>1,"!",IFERROR(INDEX(Aus_Siglas,SUMPRODUCT((Aus_Tec=$B8)*(Aus_Ini<=J$2)*(Aus_Fim>=J$2)*Aus_Cod)),"!")))) | ... AG8: =IF(OR($B8="",AG$2=""),"",IF(SUMPRODUCT((Aus_Tec=$B8)*(Aus_Ini<=AG$2)*(Aus_Fim>=AG$2)*(Aus_Cod>0))=0,"",IF(SUMPRODUCT((Aus_Tec=$B8)*(Aus_Ini<=AG$2)*(Aus_Fim>=AG$2)*(Aus_Cod>0))>1,"!",IFERROR(INDEX(Aus_Siglas,SUMPRODUCT((Aus_Tec=$B8)*(Aus_Ini<=AG$2)*(Aus_Fim>=AG$2)*Aus_Cod)),"!")))) | AH8: =IF($B8="","",COUNTIF($C8:$AG8,"F")) | AI8: =IF($B8="","",COUNTIF($C8:$AG8,"D")) | AJ8: =IF($B8="","",COUNTIF($C8:$AG8,"A")) | AK8: =IF($B8="","",SUMPRODUCT(($C8:$AG8<>"")*1))
A9: =IF('Equipe'!A7="","",'Equipe'!A7) | B9: =IF('Equipe'!B7="","",'Equipe'!B7) | C9: =IF(OR($B9="",C$2=""),"",IF(SUMPRODUCT((Aus_Tec=$B9)*(Aus_Ini<=C$2)*(Aus_Fim>=C$2)*(Aus_Cod>0))=0,"",IF(SUMPRODUCT((Aus_Tec=$B9)*(Aus_Ini<=C$2)*(Aus_Fim>=C$2)*(Aus_Cod>0))>1,"!",IFERROR(INDEX(Aus_Siglas,SUMPRODUCT((Aus_Tec=$B9)*(Aus_Ini<=C$2)*(Aus_Fim>=C$2)*Aus_Cod)),"!")))) | D9: =IF(OR($B9="",D$2=""),"",IF(SUMPRODUCT((Aus_Tec=$B9)*(Aus_Ini<=D$2)*(Aus_Fim>=D$2)*(Aus_Cod>0))=0,"",IF(SUMPRODUCT((Aus_Tec=$B9)*(Aus_Ini<=D$2)*(Aus_Fim>=D$2)*(Aus_Cod>0))>1,"!",IFERROR(INDEX(Aus_Siglas,SUMPRODUCT((Aus_Tec=$B9)*(Aus_Ini<=D$2)*(Aus_Fim>=D$2)*Aus_Cod)),"!")))) | E9: =IF(OR($B9="",E$2=""),"",IF(SUMPRODUCT((Aus_Tec=$B9)*(Aus_Ini<=E$2)*(Aus_Fim>=E$2)*(Aus_Cod>0))=0,"",IF(SUMPRODUCT((Aus_Tec=$B9)*(Aus_Ini<=E$2)*(Aus_Fim>=E$2)*(Aus_Cod>0))>1,"!",IFERROR(INDEX(Aus_Siglas,SUMPRODUCT((Aus_Tec=$B9)*(Aus_Ini<=E$2)*(Aus_Fim>=E$2)*Aus_Cod)),"!")))) | F9: =IF(OR($B9="",F$2=""),"",IF(SUMPRODUCT((Aus_Tec=$B9)*(Aus_Ini<=F$2)*(Aus_Fim>=F$2)*(Aus_Cod>0))=0,"",IF(SUMPRODUCT((Aus_Tec=$B9)*(Aus_Ini<=F$2)*(Aus_Fim>=F$2)*(Aus_Cod>0))>1,"!",IFERROR(INDEX(Aus_Siglas,SUMPRODUCT((Aus_Tec=$B9)*(Aus_Ini<=F$2)*(Aus_Fim>=F$2)*Aus_Cod)),"!")))) | G9: =IF(OR($B9="",G$2=""),"",IF(SUMPRODUCT((Aus_Tec=$B9)*(Aus_Ini<=G$2)*(Aus_Fim>=G$2)*(Aus_Cod>0))=0,"",IF(SUMPRODUCT((Aus_Tec=$B9)*(Aus_Ini<=G$2)*(Aus_Fim>=G$2)*(Aus_Cod>0))>1,"!",IFERROR(INDEX(Aus_Siglas,SUMPRODUCT((Aus_Tec=$B9)*(Aus_Ini<=G$2)*(Aus_Fim>=G$2)*Aus_Cod)),"!")))) | H9: =IF(OR($B9="",H$2=""),"",IF(SUMPRODUCT((Aus_Tec=$B9)*(Aus_Ini<=H$2)*(Aus_Fim>=H$2)*(Aus_Cod>0))=0,"",IF(SUMPRODUCT((Aus_Tec=$B9)*(Aus_Ini<=H$2)*(Aus_Fim>=H$2)*(Aus_Cod>0))>1,"!",IFERROR(INDEX(Aus_Siglas,SUMPRODUCT((Aus_Tec=$B9)*(Aus_Ini<=H$2)*(Aus_Fim>=H$2)*Aus_Cod)),"!")))) | I9: =IF(OR($B9="",I$2=""),"",IF(SUMPRODUCT((Aus_Tec=$B9)*(Aus_Ini<=I$2)*(Aus_Fim>=I$2)*(Aus_Cod>0))=0,"",IF(SUMPRODUCT((Aus_Tec=$B9)*(Aus_Ini<=I$2)*(Aus_Fim>=I$2)*(Aus_Cod>0))>1,"!",IFERROR(INDEX(Aus_Siglas,SUMPRODUCT((Aus_Tec=$B9)*(Aus_Ini<=I$2)*(Aus_Fim>=I$2)*Aus_Cod)),"!")))) | J9: =IF(OR($B9="",J$2=""),"",IF(SUMPRODUCT((Aus_Tec=$B9)*(Aus_Ini<=J$2)*(Aus_Fim>=J$2)*(Aus_Cod>0))=0,"",IF(SUMPRODUCT((Aus_Tec=$B9)*(Aus_Ini<=J$2)*(Aus_Fim>=J$2)*(Aus_Cod>0))>1,"!",IFERROR(INDEX(Aus_Siglas,SUMPRODUCT((Aus_Tec=$B9)*(Aus_Ini<=J$2)*(Aus_Fim>=J$2)*Aus_Cod)),"!")))) | ... AG9: =IF(OR($B9="",AG$2=""),"",IF(SUMPRODUCT((Aus_Tec=$B9)*(Aus_Ini<=AG$2)*(Aus_Fim>=AG$2)*(Aus_Cod>0))=0,"",IF(SUMPRODUCT((Aus_Tec=$B9)*(Aus_Ini<=AG$2)*(Aus_Fim>=AG$2)*(Aus_Cod>0))>1,"!",IFERROR(INDEX(Aus_Siglas,SUMPRODUCT((Aus_Tec=$B9)*(Aus_Ini<=AG$2)*(Aus_Fim>=AG$2)*Aus_Cod)),"!")))) | AH9: =IF($B9="","",COUNTIF($C9:$AG9,"F")) | AI9: =IF($B9="","",COUNTIF($C9:$AG9,"D")) | AJ9: =IF($B9="","",COUNTIF($C9:$AG9,"A")) | AK9: =IF($B9="","",SUMPRODUCT(($C9:$AG9<>"")*1))
A10: =IF('Equipe'!A8="","",'Equipe'!A8) | B10: =IF('Equipe'!B8="","",'Equipe'!B8) | C10: =IF(OR($B10="",C$2=""),"",IF(SUMPRODUCT((Aus_Tec=$B10)*(Aus_Ini<=C$2)*(Aus_Fim>=C$2)*(Aus_Cod>0))=0,"",IF(SUMPRODUCT((Aus_Tec=$B10)*(Aus_Ini<=C$2)*(Aus_Fim>=C$2)*(Aus_Cod>0))>1,"!",IFERROR(INDEX(Aus_Siglas,SUMPRODUCT((Aus_Tec=$B10)*(Aus_Ini<=C$2)*(Aus_Fim>=C$2)*Aus_Cod)),"!")))) | D10: =IF(OR($B10="",D$2=""),"",IF(SUMPRODUCT((Aus_Tec=$B10)*(Aus_Ini<=D$2)*(Aus_Fim>=D$2)*(Aus_Cod>0))=0,"",IF(SUMPRODUCT((Aus_Tec=$B10)*(Aus_Ini<=D$2)*(Aus_Fim>=D$2)*(Aus_Cod>0))>1,"!",IFERROR(INDEX(Aus_Siglas,SUMPRODUCT((Aus_Tec=$B10)*(Aus_Ini<=D$2)*(Aus_Fim>=D$2)*Aus_Cod)),"!")))) | E10: =IF(OR($B10="",E$2=""),"",IF(SUMPRODUCT((Aus_Tec=$B10)*(Aus_Ini<=E$2)*(Aus_Fim>=E$2)*(Aus_Cod>0))=0,"",IF(SUMPRODUCT((Aus_Tec=$B10)*(Aus_Ini<=E$2)*(Aus_Fim>=E$2)*(Aus_Cod>0))>1,"!",IFERROR(INDEX(Aus_Siglas,SUMPRODUCT((Aus_Tec=$B10)*(Aus_Ini<=E$2)*(Aus_Fim>=E$2)*Aus_Cod)),"!")))) | F10: =IF(OR($B10="",F$2=""),"",IF(SUMPRODUCT((Aus_Tec=$B10)*(Aus_Ini<=F$2)*(Aus_Fim>=F$2)*(Aus_Cod>0))=0,"",IF(SUMPRODUCT((Aus_Tec=$B10)*(Aus_Ini<=F$2)*(Aus_Fim>=F$2)*(Aus_Cod>0))>1,"!",IFERROR(INDEX(Aus_Siglas,SUMPRODUCT((Aus_Tec=$B10)*(Aus_Ini<=F$2)*(Aus_Fim>=F$2)*Aus_Cod)),"!")))) | G10: =IF(OR($B10="",G$2=""),"",IF(SUMPRODUCT((Aus_Tec=$B10)*(Aus_Ini<=G$2)*(Aus_Fim>=G$2)*(Aus_Cod>0))=0,"",IF(SUMPRODUCT((Aus_Tec=$B10)*(Aus_Ini<=G$2)*(Aus_Fim>=G$2)*(Aus_Cod>0))>1,"!",IFERROR(INDEX(Aus_Siglas,SUMPRODUCT((Aus_Tec=$B10)*(Aus_Ini<=G$2)*(Aus_Fim>=G$2)*Aus_Cod)),"!")))) | H10: =IF(OR($B10="",H$2=""),"",IF(SUMPRODUCT((Aus_Tec=$B10)*(Aus_Ini<=H$2)*(Aus_Fim>=H$2)*(Aus_Cod>0))=0,"",IF(SUMPRODUCT((Aus_Tec=$B10)*(Aus_Ini<=H$2)*(Aus_Fim>=H$2)*(Aus_Cod>0))>1,"!",IFERROR(INDEX(Aus_Siglas,SUMPRODUCT((Aus_Tec=$B10)*(Aus_Ini<=H$2)*(Aus_Fim>=H$2)*Aus_Cod)),"!")))) | I10: =IF(OR($B10="",I$2=""),"",IF(SUMPRODUCT((Aus_Tec=$B10)*(Aus_Ini<=I$2)*(Aus_Fim>=I$2)*(Aus_Cod>0))=0,"",IF(SUMPRODUCT((Aus_Tec=$B10)*(Aus_Ini<=I$2)*(Aus_Fim>=I$2)*(Aus_Cod>0))>1,"!",IFERROR(INDEX(Aus_Siglas,SUMPRODUCT((Aus_Tec=$B10)*(Aus_Ini<=I$2)*(Aus_Fim>=I$2)*Aus_Cod)),"!")))) | J10: =IF(OR($B10="",J$2=""),"",IF(SUMPRODUCT((Aus_Tec=$B10)*(Aus_Ini<=J$2)*(Aus_Fim>=J$2)*(Aus_Cod>0))=0,"",IF(SUMPRODUCT((Aus_Tec=$B10)*(Aus_Ini<=J$2)*(Aus_Fim>=J$2)*(Aus_Cod>0))>1,"!",IFERROR(INDEX(Aus_Siglas,SUMPRODUCT((Aus_Tec=$B10)*(Aus_Ini<=J$2)*(Aus_Fim>=J$2)*Aus_Cod)),"!")))) | ... AG10: =IF(OR($B10="",AG$2=""),"",IF(SUMPRODUCT((Aus_Tec=$B10)*(Aus_Ini<=AG$2)*(Aus_Fim>=AG$2)*(Aus_Cod>0))=0,"",IF(SUMPRODUCT((Aus_Tec=$B10)*(Aus_Ini<=AG$2)*(Aus_Fim>=AG$2)*(Aus_Cod>0))>1,"!",IFERROR(INDEX(Aus_Siglas,SUMPRODUCT((Aus_Tec=$B10)*(Aus_Ini<=AG$2)*(Aus_Fim>=AG$2)*Aus_Cod)),"!")))) | AH10: =IF($B10="","",COUNTIF($C10:$AG10,"F")) | AI10: =IF($B10="","",COUNTIF($C10:$AG10,"D")) | AJ10: =IF($B10="","",COUNTIF($C10:$AG10,"A")) | AK10: =IF($B10="","",SUMPRODUCT(($C10:$AG10<>"")*1))
A11: =IF('Equipe'!A9="","",'Equipe'!A9) | B11: =IF('Equipe'!B9="","",'Equipe'!B9) | C11: =IF(OR($B11="",C$2=""),"",IF(SUMPRODUCT((Aus_Tec=$B11)*(Aus_Ini<=C$2)*(Aus_Fim>=C$2)*(Aus_Cod>0))=0,"",IF(SUMPRODUCT((Aus_Tec=$B11)*(Aus_Ini<=C$2)*(Aus_Fim>=C$2)*(Aus_Cod>0))>1,"!",IFERROR(INDEX(Aus_Siglas,SUMPRODUCT((Aus_Tec=$B11)*(Aus_Ini<=C$2)*(Aus_Fim>=C$2)*Aus_Cod)),"!")))) | D11: =IF(OR($B11="",D$2=""),"",IF(SUMPRODUCT((Aus_Tec=$B11)*(Aus_Ini<=D$2)*(Aus_Fim>=D$2)*(Aus_Cod>0))=0,"",IF(SUMPRODUCT((Aus_Tec=$B11)*(Aus_Ini<=D$2)*(Aus_Fim>=D$2)*(Aus_Cod>0))>1,"!",IFERROR(INDEX(Aus_Siglas,SUMPRODUCT((Aus_Tec=$B11)*(Aus_Ini<=D$2)*(Aus_Fim>=D$2)*Aus_Cod)),"!")))) | E11: =IF(OR($B11="",E$2=""),"",IF(SUMPRODUCT((Aus_Tec=$B11)*(Aus_Ini<=E$2)*(Aus_Fim>=E$2)*(Aus_Cod>0))=0,"",IF(SUMPRODUCT((Aus_Tec=$B11)*(Aus_Ini<=E$2)*(Aus_Fim>=E$2)*(Aus_Cod>0))>1,"!",IFERROR(INDEX(Aus_Siglas,SUMPRODUCT((Aus_Tec=$B11)*(Aus_Ini<=E$2)*(Aus_Fim>=E$2)*Aus_Cod)),"!")))) | F11: =IF(OR($B11="",F$2=""),"",IF(SUMPRODUCT((Aus_Tec=$B11)*(Aus_Ini<=F$2)*(Aus_Fim>=F$2)*(Aus_Cod>0))=0,"",IF(SUMPRODUCT((Aus_Tec=$B11)*(Aus_Ini<=F$2)*(Aus_Fim>=F$2)*(Aus_Cod>0))>1,"!",IFERROR(INDEX(Aus_Siglas,SUMPRODUCT((Aus_Tec=$B11)*(Aus_Ini<=F$2)*(Aus_Fim>=F$2)*Aus_Cod)),"!")))) | G11: =IF(OR($B11="",G$2=""),"",IF(SUMPRODUCT((Aus_Tec=$B11)*(Aus_Ini<=G$2)*(Aus_Fim>=G$2)*(Aus_Cod>0))=0,"",IF(SUMPRODUCT((Aus_Tec=$B11)*(Aus_Ini<=G$2)*(Aus_Fim>=G$2)*(Aus_Cod>0))>1,"!",IFERROR(INDEX(Aus_Siglas,SUMPRODUCT((Aus_Tec=$B11)*(Aus_Ini<=G$2)*(Aus_Fim>=G$2)*Aus_Cod)),"!")))) | H11: =IF(OR($B11="",H$2=""),"",IF(SUMPRODUCT((Aus_Tec=$B11)*(Aus_Ini<=H$2)*(Aus_Fim>=H$2)*(Aus_Cod>0))=0,"",IF(SUMPRODUCT((Aus_Tec=$B11)*(Aus_Ini<=H$2)*(Aus_Fim>=H$2)*(Aus_Cod>0))>1,"!",IFERROR(INDEX(Aus_Siglas,SUMPRODUCT((Aus_Tec=$B11)*(Aus_Ini<=H$2)*(Aus_Fim>=H$2)*Aus_Cod)),"!")))) | I11: =IF(OR($B11="",I$2=""),"",IF(SUMPRODUCT((Aus_Tec=$B11)*(Aus_Ini<=I$2)*(Aus_Fim>=I$2)*(Aus_Cod>0))=0,"",IF(SUMPRODUCT((Aus_Tec=$B11)*(Aus_Ini<=I$2)*(Aus_Fim>=I$2)*(Aus_Cod>0))>1,"!",IFERROR(INDEX(Aus_Siglas,SUMPRODUCT((Aus_Tec=$B11)*(Aus_Ini<=I$2)*(Aus_Fim>=I$2)*Aus_Cod)),"!")))) | J11: =IF(OR($B11="",J$2=""),"",IF(SUMPRODUCT((Aus_Tec=$B11)*(Aus_Ini<=J$2)*(Aus_Fim>=J$2)*(Aus_Cod>0))=0,"",IF(SUMPRODUCT((Aus_Tec=$B11)*(Aus_Ini<=J$2)*(Aus_Fim>=J$2)*(Aus_Cod>0))>1,"!",IFERROR(INDEX(Aus_Siglas,SUMPRODUCT((Aus_Tec=$B11)*(Aus_Ini<=J$2)*(Aus_Fim>=J$2)*Aus_Cod)),"!")))) | ... AG11: =IF(OR($B11="",AG$2=""),"",IF(SUMPRODUCT((Aus_Tec=$B11)*(Aus_Ini<=AG$2)*(Aus_Fim>=AG$2)*(Aus_Cod>0))=0,"",IF(SUMPRODUCT((Aus_Tec=$B11)*(Aus_Ini<=AG$2)*(Aus_Fim>=AG$2)*(Aus_Cod>0))>1,"!",IFERROR(INDEX(Aus_Siglas,SUMPRODUCT((Aus_Tec=$B11)*(Aus_Ini<=AG$2)*(Aus_Fim>=AG$2)*Aus_Cod)),"!")))) | AH11: =IF($B11="","",COUNTIF($C11:$AG11,"F")) | AI11: =IF($B11="","",COUNTIF($C11:$AG11,"D")) | AJ11: =IF($B11="","",COUNTIF($C11:$AG11,"A")) | AK11: =IF($B11="","",SUMPRODUCT(($C11:$AG11<>"")*1))
