Workbook
Name Periodo_Ini: 'Configuração'!$B$8
Name Turno_Ini: 'Configuração'!$B$11
Name Turno_Fim: 'Configuração'!$B$12
Name Turno_Min: 'Configuração'!$B$13
Name Limpeza_Min: 'Configuração'!$B$16
Name Janela_Min: 'Configuração'!$B$17
Name Data_Mapa: 'Mapa do Dia'!$A$6
Name Esp_Cod: 'Configuração'!$A$22:$A$41
Name Esp_Nome: 'Configuração'!$B$22:$B$41
Name Esp_Tipo: 'Configuração'!$C$22:$C$41
Name Esp_Dur: 'Configuração'!$D$22:$D$41
Name Postos_Cod: 'Configuração'!$A$45:$A$60
Name Postos_Nome: 'Configuração'!$B$45:$B$60
Name Postos_Tipo: 'Configuração'!$C$45:$C$60
Name Postos_Nec: 'Configuração'!$D$45:$D$60
Name Postos_Min: 'Configuração'!$E$45:$E$60
Name Postos_Prior: 'Configuração'!$F$45:$F$60
Name Postos_Esp: 'Configuração'!$G$45:$G$60
Name Postos_Func: 'Configuração'!$H$45:$H$60
Name Postos_Status: 'Configuração'!$I$45:$I$60
Name Postos_Encaixe: 'Configuração'!$K$45:$K$60
Name Feriados: 'Configuração'!$A$64:$A$83
Name Aus_Tipos: 'Configuração'!$A$87:$A$93
Name Aus_Siglas: 'Configuração'!$B$87:$B$93
Name Cir_Nome: 'Configuração'!$A$97:$A$156
Name Cir_Esp: 'Configuração'!$B$97:$B$156
Name Lista_StatusCad: 'Configuração'!$G$6:$G$8
Name Lista_StatusCir: 'Configuração'!$H$6:$H$9
Name Lista_TipoPosto: 'Configuração'!$I$6:$I$7
Name Lista_Especialidades: OFFSET('Configuração'!$B$22,0,0,MAX(1,COUNTA('Configuração'!$B$22:$B$41)),1)
Name Lista_Postos: OFFSET('Configuração'!$A$45,0,0,MAX(1,COUNTA('Configuração'!$A$45:$A$60)),1)
Name Equipe_Afin: 'Equipe'!$AE$2:$BH$31
Name Equipe_AfinN: 'Equipe'!$AD$2:$AD$31
Name Equipe_Mat: 'Equipe'!$A$2:$A$31
Name Equipe_Nome: 'Equipe'!$B$2:$B$31
Name Equipe_Status: 'Equipe'!$D$2:$D$31
Name Equipe_Situacao: 'Equipe'!$E$2:$E$31
Name Equipe_X: 'Equipe'!$H$2:$AA$31
Name Equipe_NEsp: 'Equipe'!$AB$2:$AB$31
Name Equipe_Curto: 'Equipe'!$AC$2:$AC$31
Name Lista_Tecnicos: OFFSET('Equipe'!$B$2,0,0,MAX(1,COUNTA('Equipe'!$B$2:$B$31)),1)
Name Aus_Tec: 'Folgas e Férias'!$A$2:$A$151
Name Aus_Tipo: 'Folgas e Férias'!$B$2:$B$151
Name Aus_Ini: 'Folgas e Férias'!$C$2:$C$151
Name Aus_Fim: 'Folgas e Férias'!$D$2:$D$151
Name Aus_Ativa: 'Folgas e Férias'!$G$2:$G$151
Name Aus_Cod: 'Folgas e Férias'!$H$2:$H$151
Name Mapa_Data: 'Agenda do Dia'!$A$2:$A$201
Name Mapa_Sala: 'Agenda do Dia'!$B$2:$B$201
Name Mapa_Esp: 'Agenda do Dia'!$E$2:$E$201
Name Mapa_Status: 'Agenda do Dia'!$H$2:$H$201
Name Mapa_Dur: 'Agenda do Dia'!$I$2:$I$201
Name Mapa_MinOcup: 'Agenda do Dia'!$J$2:$J$201
Name Mapa_Alerta: 'Agenda do Dia'!$N$2:$N$201
Name Mapa_RelIni: 'Agenda do Dia'!$P$2:$P$201
Name Mapa_RelFim: 'Agenda do Dia'!$Q$2:$Q$201
Name Mapa_Chave: 'Agenda do Dia'!$R$2:$R$201
Name Mapa_Row: 'Agenda do Dia'!$S$2:$S$201
Name Mapa_MinPlantao: 'Agenda do Dia'!$T$2:$T$201
Name Mix_Esp: 'Calc'!$E$1:$X$1

Sheet Painel
A1: CENTRO CIRÚRGICO — PAINEL DO DIA
A2: O dia inteiro numa tela. Esta aba só mostra — quem escala e quem troca é a aba Mapa do Dia.
A4: DATA DO MAPA | G4: =Data_Mapa | M4: =IF(Data_Mapa="","",CHOOSE(WEEKDAY(Data_Mapa),"domingo","segunda","terça","quarta","quinta","sexta","sábado")&IF(COUNTIF(Feriados,Data_Mapa)>0," · feriado",""))
A6: =IF(MAX(Aco_Nota)>=900,"AÇÃO NECESSÁRIA",IF(MAX(Aco_Nota)>=600,"ATENÇÃO",IF(MAX(Aco_Nota)>=1,"QUASE PRONTO","DIA FECHADO — nada pendente")))
A8: Cirurgias hoje | J8: Ambientes abertos | Q8: Prontos | X8: Com pendência | AG8: Disponíveis | AN8: Déficit | AU8: Maior atraso (min)
A9: =COUNTIFS(Mapa_Data,Data_Mapa,Mapa_MinOcup,">0") | J9: =COUNTIF('Mapa do Dia'!$B$10:$B$25,">0") | Q9: =COUNTIF('Mapa do Dia'!$F$10:$F$25,"OK") | X9: =SUMPRODUCT(('Mapa do Dia'!$F$10:$F$25<>"")*('Mapa do Dia'!$F$10:$F$25<>"OK")*('Mapa do Dia'!$F$10:$F$25<>"NÃO OPERA")) | AG9: =SUMPRODUCT((Equipe_Nome<>"")*(Equipe_Situacao="Disponível")) | AN9: =MAX(0,SUM('Calc'!$AD$2:$AD$17)-$AG$9) | AU9: =MAX(0,'Mapa do Dia'!$L$10:$L$25)
A10: O DIA INTEIRO — a cor do ambiente é a situação · a barra é a sala ocupada
A11: Ambiente | L11: Dupla do plantão | V11: =TEXT(MOD(Turno_Ini+0/1440,1),"HH:MM") | AB11: =TEXT(MOD(Turno_Ini+60/1440,1),"HH:MM") | AH11: =TEXT(MOD(Turno_Ini+120/1440,1),"HH:MM") | AN11: =TEXT(MOD(Turno_Ini+180/1440,1),"HH:MM") | AT11: =TEXT(MOD(Turno_Ini+240/1440,1),"HH:MM") | AZ11: =TEXT(MOD(Turno_Ini+300/1440,1),"HH:MM")
A12: =IF('Mapa do Dia'!$A10="","",'Mapa do Dia'!$A10) | L12: =IF('Mapa do Dia'!$A10="","",IF('Mapa do Dia'!$D10="","(falta escalar)",IFERROR(INDEX(Equipe_Curto,MATCH('Mapa do Dia'!$D10,Equipe_Nome,0)),'Mapa do Dia'!$D10))&IF('Mapa do Dia'!$B10<2,"",IF('Mapa do Dia'!$E10="", " · (falta escalar)"," · "&IFERROR(INDEX(Equipe_Curto,MATCH('Mapa do Dia'!$E10,Equipe_Nome,0)),'Mapa do Dia'!$E10)))) | V12: =IF(OR('Mapa do Dia'!$A10="",'Calc'!$B2<>"Sala cirúrgica"),"",IF(SUMPRODUCT((Mapa_Sala='Mapa do Dia'!$N10)*(Mapa_Data=Data_Mapa)*(Mapa_MinOcup>0)*(Mapa_RelIni<10)*(Mapa_RelFim>0))>0,2,IF(SUMPRODUCT((Mapa_Sala='Mapa do Dia'!$N10)*(Mapa_Data=Data_Mapa)*(Mapa_MinOcup>0)*(Mapa_RelFim<10)*(Mapa_RelFim+Limpeza_Min>0))>0,1,0))) | W12: =IF(OR('Mapa do Dia'!$A10="",'Calc'!$B2<>"Sala cirúrgica"),"",IF(SUMPRODUCT((Mapa_Sala='Mapa do Dia'!$N10)*(Mapa_Data=Data_Mapa)*(Mapa_MinOcup>0)*(Mapa_RelIni<20)*(Mapa_RelFim>10))>0,2,IF(SUMPRODUCT((Mapa_Sala='Mapa do Dia'!$N10)*(Mapa_Data=Data_Mapa)*(Mapa_MinOcup>0)*(Mapa_RelFim<20)*(Mapa_RelFim+Limpeza_Min>10))>0,1,0))) | X12: =IF(OR('Mapa do Dia'!$A10="",'Calc'!$B2<>"Sala cirúrgica"),"",IF(SUMPRODUCT((Mapa_Sala='Mapa do Dia'!$N10)*(Mapa_Data=Data_Mapa)*(Mapa_MinOcup>0)*(Mapa_RelIni<30)*(Mapa_RelFim>20))>0,2,IF(SUMPRODUCT((Mapa_Sala='Mapa do Dia'!$N10)*(Mapa_Data=Data_Mapa)*(Mapa_MinOcup>0)*(Mapa_RelFim<30)*(Mapa_RelFim+Limpeza_Min>20))>0,1,0))) | Y12: =IF(OR('Mapa do Dia'!$A10="",'Calc'!$B2<>"Sala cirúrgica"),"",IF(SUMPRODUCT((Mapa_Sala='Mapa do Dia'!$N10)*(Mapa_Data=Data_Mapa)*(Mapa_MinOcup>0)*(Mapa_RelIni<40)*(Mapa_RelFim>30))>0,2,IF(SUMPRODUCT((Mapa_Sala='Mapa do Dia'!$N10)*(Mapa_Data=Data_Mapa)*(Mapa_MinOcup>0)*(Mapa_RelFim<40)*(Mapa_RelFim+Limpeza_Min>30))>0,1,0))) | Z12: =IF(OR('Mapa do Dia'!$A10="",'Calc'!$B2<>"Sala cirúrgica"),"",IF(SUMPRODUCT((Mapa_Sala='Mapa do Dia'!$N10)*(Mapa_Data=Data_Mapa)*(Mapa_MinOcup>0)*(Mapa_RelIni<50)*(Mapa_RelFim>40))>0,2,IF(SUMPRODUCT((Mapa_Sala='Mapa do Dia'!$N10)*(Mapa_Data=Data_Mapa)*(Mapa_MinOcup>0)*(Mapa_RelFim<50)*(Mapa_RelFim+Limpeza_Min>40))>0,1,0))) | AA12: =IF(OR('Mapa do Dia'!$A10="",'Calc'!$B2<>"Sala cirúrgica"),"",IF(SUMPRODUCT((Mapa_Sala='Mapa do Dia'!$N10)*(Mapa_Data=Data_Mapa)*(Mapa_MinOcup>0)*(Mapa_RelIni<60)*(Mapa_RelFim>50))>0,2,IF(SUMPRODUCT((Mapa_Sala='Mapa do Dia'!$N10)*(Mapa_Data=Data_Mapa)*(Mapa_MinOcup>0)*(Mapa_RelFim<60)*(Mapa_RelFim+Limpeza_Min>50))>0,1,0))) | AB12: =IF(OR('Mapa do Dia'!$A10="",'Calc'!$B2<>"Sala cirúrgica"),"",IF(SUMPRODUCT((Mapa_Sala='Mapa do Dia'!$N10)*(Mapa_Data=Data_Mapa)*(Mapa_MinOcup>0)*(Mapa_RelIni<70)*(Mapa_RelFim>60))>0,2,IF(SUMPRODUCT((Mapa_Sala='Mapa do Dia'!$N10)*(Mapa_Data=Data_Mapa)*(Mapa_MinOcup>0)*(Mapa_RelFim<70)*(Mapa_RelFim+Limpeza_Min>60))>0,1,0))) | AC12: =IF(OR('Mapa do Dia'!$A10="",'Calc'!$B2<>"Sala cirúrgica"),"",IF(SUMPRODUCT((Mapa_Sala='Mapa do Dia'!$N10)*(Mapa_Data=Data_Mapa)*(Mapa_MinOcup>0)*(Mapa_RelIni<80)*(Mapa_RelFim>70))>0,2,IF(SUMPRODUCT((Mapa_Sala='Mapa do Dia'!$N10)*(Mapa_Data=Data_Mapa)*(Mapa_MinOcup>0)*(Mapa_RelFim<80)*(Mapa_RelFim+Limpeza_Min>70))>0,1,0))) | AD12: =IF(OR('Mapa do Dia'!$A10="",'Calc'!$B2<>"Sala cirúrgica"),"",IF(SUMPRODUCT((Mapa_Sala='Mapa do Dia'!$N10)*(Mapa_Data=Data_Mapa)*(Mapa_MinOcup>0)*(Mapa_RelIni<90)*(Mapa_RelFim>80))>0,2,IF(SUMPRODUCT((Mapa_Sala='Mapa do Dia'!$N10)*(Mapa_Data=Data_Mapa)*(Mapa_MinOcup>0)*(Mapa_RelFim<90)*(Mapa_RelFim+Limpeza_Min>80))>0,1,0))) | AE12: =IF(OR('Mapa do Dia'!$A10="",'Calc'!$B2<>"Sala cirúrgica"),"",IF(SUMPRODUCT((Mapa_Sala='Mapa do Dia'!$N10)*(Mapa_Data=Data_Mapa)*(Mapa_MinOcup>0)*(Mapa_RelIni<100)*(Mapa_RelFim>90))>0,2,IF(SUMPRODUCT((Mapa_Sala='Mapa do Dia'!$N10)*(Mapa_Data=Data_Mapa)*(Mapa_MinOcup>0)*(Mapa_RelFim<100)*(Mapa_RelFim+Limpeza_Min>90))>0,1,0))) | AF12: =IF(OR('Mapa do Dia'!$A10="",'Calc'!$B2<>"Sala cirúrgica"),"",IF(SUMPRODUCT((Mapa_Sala='Mapa do Dia'!$N10)*(Mapa_Data=Data_Mapa)*(Mapa_MinOcup>0)*(Mapa_RelIni<110)*(Mapa_RelFim>100))>0,2,IF(SUMPRODUCT((Mapa_Sala='Mapa do Dia'!$N10)*(Mapa_Data=Data_Mapa)*(Mapa_MinOcup>0)*(Mapa_RelFim<110)*(Mapa_RelFim+Limpeza_Min>100))>0,1,0))) | AG12: =IF(OR('Mapa do Dia'!$A10="",'Calc'!$B2<>"Sala cirúrgica"),"",IF(SUMPRODUCT((Mapa_Sala='Mapa do Dia'!$N10)*(Mapa_Data=Data_Mapa)*(Mapa_MinOcup>0)*(Mapa_RelIni<120)*(Mapa_RelFim>110))>0,2,IF(SUMPRODUCT((Mapa_Sala='Mapa do Dia'!$N10)*(Mapa_Data=Data_Mapa)*(Mapa_MinOcup>0)*(Mapa_RelFim<120)*(Mapa_RelFim+Limpeza_Min>110))>0,1,0))) | AH12: =IF(OR('Mapa do Dia'!$A10="",'Calc'!$B2<>"Sala cirúrgica"),"",IF(SUMPRODUCT((Mapa_Sala='Mapa do Dia'!$N10)*(Mapa_Data=Data_Mapa)*(Mapa_MinOcup>0)*(Mapa_RelIni<130)*(Mapa_RelFim>120))>0,2,IF(SUMPRODUCT((Mapa_Sala='Mapa do Dia'!$N10)*(Mapa_Data=Data_Mapa)*(Mapa_MinOcup>0)*(Mapa_RelFim<130)*(Mapa_RelFim+Limpeza_Min>120))>0,1,0))) | AI12: =IF(OR('Mapa do Dia'!$A10="",'Calc'!$B2<>"Sala cirúrgica"),"",IF(SUMPRODUCT((Mapa_Sala='Mapa do Dia'!$N10)*(Mapa_Data=Data_Mapa)*(Mapa_MinOcup>0)*(Mapa_RelIni<140)*(Mapa_RelFim>130))>0,2,IF(SUMPRODUCT((Mapa_Sala='Mapa do Dia'!$N10)*(Mapa_Data=Data_Mapa)*(Mapa_MinOcup>0)*(Mapa_RelFim<140)*(Mapa_RelFim+Limpeza_Min>130))>0,1,0))) | AJ12: =IF(OR('Mapa do Dia'!$A10="",'Calc'!$B2<>"Sala cirúrgica"),"",IF(SUMPRODUCT((Mapa_Sala='Mapa do Dia'!$N10)*(Mapa_Data=Data_Mapa)*(Mapa_MinOcup>0)*(Mapa_RelIni<150)*(Mapa_RelFim>140))>0,2,IF(SUMPRODUCT((Mapa_Sala='Mapa do Dia'!$N10)*(Mapa_Data=Data_Mapa)*(Mapa_MinOcup>0)*(Mapa_RelFim<150)*(Mapa_RelFim+Limpeza_Min>140))>0,1,0))) | AK12: =IF(OR('Mapa do Dia'!$A10="",'Calc'!$B2<>"Sala cirúrgica"),"",IF(SUMPRODUCT((Mapa_Sala='Mapa do Dia'!$N10)*(Mapa_Data=Data_Mapa)*(Mapa_MinOcup>0)*(Mapa_RelIni<160)*(Mapa_RelFim>150))>0,2,IF(SUMPRODUCT((Mapa_Sala='Mapa do Dia'!$N10)*(Mapa_Data=Data_Mapa)*(Mapa_MinOcup>0)*(Mapa_RelFim<160)*(Mapa_RelFim+Limpeza_Min>150))>0,1,0))) | AL12: =IF(OR('Mapa do Dia'!$A10="",'Calc'!$B2<>"Sala cirúrgica"),"",IF(SUMPRODUCT((Mapa_Sala='Mapa do Dia'!$N10)*(Mapa_Data=Data_Mapa)*(Mapa_MinOcup>0)*(Mapa_RelIni<170)*(Mapa_RelFim>160))>0,2,IF(SUMPRODUCT((Mapa_Sala='Mapa do Dia'!$N10)*(Mapa_Data=Data_Mapa)*(Mapa_MinOcup>0)*(Mapa_RelFim<170)*(Mapa_RelFim+Limpeza_Min>160))>0,1,0))) | AM12: =IF(OR('Mapa do Dia'!$A10="",'Calc'!$B2<>"Sala cirúrgica"),"",IF(SUMPRODUCT((Mapa_Sala='Mapa do Dia'!$N10)*(Mapa_Data=Data_Mapa)*(Mapa_MinOcup>0)*(Mapa_RelIni<180)*(Mapa_RelFim>170))>0,2,IF(SUMPRODUCT((Mapa_Sala='Mapa do Dia'!$N10)*(Mapa_Data=Data_Mapa)*(Mapa_MinOcup>0)*(Mapa_RelFim<180)*(Mapa_RelFim+Limpeza_Min>170))>0,1,0))) | AN12: =IF(OR('Mapa do Dia'!$A10="",'Calc'!$B2<>"Sala cirúrgica"),"",IF(SUMPRODUCT((Mapa_Sala='Mapa do Dia'!$N10)*(Mapa_Data=Data_Mapa)*(Mapa_MinOcup>0)*(Mapa_RelIni<190)*(Mapa_RelFim>180))>0,2,IF(SUMPRODUCT((Mapa_Sala='Mapa do Dia'!$N10)*(Mapa_Data=Data_Mapa)*(Mapa_MinOcup>0)*(Mapa_RelFim<190)*(Mapa_RelFim+Limpeza_Min>180))>0,1,0))) | AO12: =IF(OR('Mapa do Dia'!$A10="",'Calc'!$B2<>"Sala cirúrgica"),"",IF(SUMPRODUCT((Mapa_Sala='Mapa do Dia'!$N10)*(Mapa_Data=Data_Mapa)*(Mapa_MinOcup>0)*(Mapa_RelIni<200)*(Mapa_RelFim>190))>0,2,IF(SUMPRODUCT((Mapa_Sala='Mapa do Dia'!$N10)*(Mapa_Data=Data_Mapa)*(Mapa_MinOcup>0)*(Mapa_RelFim<200)*(Mapa_RelFim+Limpeza_Min>190))>0,1,0))) | AP12: =IF(OR('Mapa do Dia'!$A10="",'Calc'!$B2<>"Sala cirúrgica"),"",IF(SUMPRODUCT((Mapa_Sala='Mapa do Dia'!$N10)*(Mapa_Data=Data_Mapa)*(Mapa_MinOcup>0)*(Mapa_RelIni<210)*(Mapa_RelFim>200))>0,2,IF(SUMPRODUCT((Mapa_Sala='Mapa do Dia'!$N10)*(Mapa_Data=Data_Mapa)*(Mapa_MinOcup>0)*(Mapa_RelFim<210)*(Mapa_RelFim+Limpeza_Min>200))>0,1,0))) | AQ12: =IF(OR('Mapa do Dia'!$A10="",'Calc'!$B2<>"Sala cirúrgica"),"",IF(SUMPRODUCT((Mapa_Sala='Mapa do Dia'!$N10)*(Mapa_Data=Data_Mapa)*(Mapa_MinOcup>0)*(Mapa_RelIni<220)*(Mapa_RelFim>210))>0,2,IF(SUMPRODUCT((Mapa_Sala='Mapa do Dia'!$N10)*(Mapa_Data=Data_Mapa)*(Mapa_MinOcup>0)*(Mapa_RelFim<220)*(Mapa_RelFim+Limpeza_Min>210))>0,1,0))) | AR12: =IF(OR('Mapa do Dia'!$A10="",'Calc'!$B2<>"Sala cirúrgica"),"",IF(SUMPRODUCT((Mapa_Sala='Mapa do Dia'!$N10)*(Mapa_Data=Data_Mapa)*(Mapa_MinOcup>0)*(Mapa_RelIni<230)*(Mapa_RelFim>220))>0,2,IF(SUMPRODUCT((Mapa_Sala='Mapa do Dia'!$N10)*(Mapa_Data=Data_Mapa)*(Mapa_MinOcup>0)*(Mapa_RelFim<230)*(Mapa_RelFim+Limpeza_Min>220))>0,1,0))) | AS12: =IF(OR('Mapa do Dia'!$A10="",'Calc'!$B2<>"Sala cirúrgica"),"",IF(SUMPRODUCT((Mapa_Sala='Mapa do Dia'!$N10)*(Mapa_Data=Data_Mapa)*(Mapa_MinOcup>0)*(Mapa_RelIni<240)*(Mapa_RelFim>230))>0,2,IF(SUMPRODUCT((Mapa_Sala='Mapa do Dia'!$N10)*(Mapa_Data=Data_Mapa)*(Mapa_MinOcup>0)*(Mapa_RelFim<240)*(Mapa_RelFim+Limpeza_Min>230))>0,1,0))) | AT12: =IF(OR('Mapa do Dia'!$A10="",'Calc'!$B2<>"Sala cirúrgica"),"",IF(SUMPRODUCT((Mapa_Sala='Mapa do Dia'!$N10)*(Mapa_Data=Data_Mapa)*(Mapa_MinOcup>0)*(Mapa_RelIni<250)*(Mapa_RelFim>240))>0,2,IF(SUMPRODUCT((Mapa_Sala='Mapa do Dia'!$N10)*(Mapa_Data=Data_Mapa)*(Mapa_MinOcup>0)*(Mapa_RelFim<250)*(Mapa_RelFim+Limpeza_Min>240))>0,1,0))) | AU12: =IF(OR('Mapa do Dia'!$A10="",'Calc'!$B2<>"Sala cirúrgica"),"",IF(SUMPRODUCT((Mapa_Sala='Mapa do Dia'!$N10)*(Mapa_Data=Data_Mapa)*(Mapa_MinOcup>0)*(Mapa_RelIni<260)*(Mapa_RelFim>250))>0,2,IF(SUMPRODUCT((Mapa_Sala='Mapa do Dia'!$N10)*(Mapa_Data=Data_Mapa)*(Mapa_MinOcup>0)*(Mapa_RelFim<260)*(Mapa_RelFim+Limpeza_Min>250))>0,1,0))) | AV12: =IF(OR('Mapa do Dia'!$A10="",'Calc'!$B2<>"Sala cirúrgica"),"",IF(SUMPRODUCT((Mapa_Sala='Mapa do Dia'!$N10)*(Mapa_Data=Data_Mapa)*(Mapa_MinOcup>0)*(Mapa_RelIni<270)*(Mapa_RelFim>260))>0,2,IF(SUMPRODUCT((Mapa_Sala='Mapa do Dia'!$N10)*(Mapa_Data=Data_Mapa)*(Mapa_MinOcup>0)*(Mapa_RelFim<270)*(Mapa_RelFim+Limpeza_Min>260))>0,1,0))) | AW12: =IF(OR('Mapa do Dia'!$A10="",'Calc'!$B2<>"Sala cirúrgica"),"",IF(SUMPRODUCT((Mapa_Sala='Mapa do Dia'!$N10)*(Mapa_Data=Data_Mapa)*(Mapa_MinOcup>0)*(Mapa_RelIni<280)*(Mapa_RelFim>270))>0,2,IF(SUMPRODUCT((Mapa_Sala='Mapa do Dia'!$N10)*(Mapa_Data=Data_Mapa)*(Mapa_MinOcup>0)*(Mapa_RelFim<280)*(Mapa_RelFim+Limpeza_Min>270))>0,1,0))) | AX12: =IF(OR('Mapa do Dia'!$A10="",'Calc'!$B2<>"Sala cirúrgica"),"",IF(SUMPRODUCT((Mapa_Sala='Mapa do Dia'!$N10)*(Mapa_Data=Data_Mapa)*(Mapa_MinOcup>0)*(Mapa_RelIni<290)*(Mapa_RelFim>280))>0,2,IF(SUMPRODUCT((Mapa_Sala='Mapa do Dia'!$N10)*(Mapa_Data=Data_Mapa)*(Mapa_MinOcup>0)*(Mapa_RelFim<290)*(Mapa_RelFim+Limpeza_Min>280))>0,1,0))) | AY12: =IF(OR('Mapa do Dia'!$A10="",'Calc'!$B2<>"Sala cirúrgica"),"",IF(SUMPRODUCT((Mapa_Sala='Mapa do Dia'!$N10)*(Mapa_Data=Data_Mapa)*(Mapa_MinOcup>0)*(Mapa_RelIni<300)*(Mapa_RelFim>290))>0,2,IF(SUMPRODUCT((Mapa_Sala='Mapa do Dia'!$N10)*(Mapa_Data=Data_Mapa)*(Mapa_MinOcup>0)*(Mapa_RelFim<300)*(Mapa_RelFim+Limpeza_Min>290))>0,1,0))) | AZ12: =IF(OR('Mapa do Dia'!$A10="",'Calc'!$B2<>"Sala cirúrgica"),"",IF(SUMPRODUCT((Mapa_Sala='Mapa do Dia'!$N10)*(Mapa_Data=Data_Mapa)*(Mapa_MinOcup>0)*(Mapa_RelIni<310)*(Mapa_RelFim>300))>0,2,IF(SUMPRODUCT((Mapa_Sala='Mapa do Dia'!$N10)*(Mapa_Data=Data_Mapa)*(Mapa_MinOcup>0)*(Mapa_RelFim<310)*(Mapa_RelFim+Limpeza_Min>300))>0,1,0))) | BA12: =IF(OR('Mapa do Dia'!$A10="",'Calc'!$B2<>"Sala cirúrgica"),"",IF(SUMPRODUCT((Mapa_Sala='Mapa do Dia'!$N10)*(Mapa_Data=Data_Mapa)*(Mapa_MinOcup>0)*(Mapa_RelIni<320)*(Mapa_RelFim>310))>0,2,IF(SUMPRODUCT((Mapa_Sala='Mapa do Dia'!$N10)*(Mapa_Data=Data_Mapa)*(Mapa_MinOcup>0)*(Mapa_RelFim<320)*(Mapa_RelFim+Limpeza_Min>310))>0,1,0))) | BB12: =IF(OR('Mapa do Dia'!$A10="",'Calc'!$B2<>"Sala cirúrgica"),"",IF(SUMPRODUCT((Mapa_Sala='Mapa do Dia'!$N10)*(Mapa_Data=Data_Mapa)*(Mapa_MinOcup>0)*(Mapa_RelIni<330)*(Mapa_RelFim>320))>0,2,IF(SUMPRODUCT((Mapa_Sala='Mapa do Dia'!$N10)*(Mapa_Data=Data_Mapa)*(Mapa_MinOcup>0)*(Mapa_RelFim<330)*(Mapa_RelFim+Limpeza_Min>320))>0,1,0))) | BC12: =IF(OR('Mapa do Dia'!$A10="",'Calc'!$B2<>"Sala cirúrgica"),"",IF(SUMPRODUCT((Mapa_Sala='Mapa do Dia'!$N10)*(Mapa_Data=Data_Mapa)*(Mapa_MinOcup>0)*(Mapa_RelIni<340)*(Mapa_RelFim>330))>0,2,IF(SUMPRODUCT((Mapa_Sala='Mapa do Dia'!$N10)*(Mapa_Data=Data_Mapa)*(Mapa_MinOcup>0)*(Mapa_RelFim<340)*(Mapa_RelFim+Limpeza_Min>330))>0,1,0))) | BD12: =IF(OR('Mapa do Dia'!$A10="",'Calc'!$B2<>"Sala cirúrgica"),"",IF(SUMPRODUCT((Mapa_Sala='Mapa do Dia'!$N10)*(Mapa_Data=Data_Mapa)*(Mapa_MinOcup>0)*(Mapa_RelIni<350)*(Mapa_RelFim>340))>0,2,IF(SUMPRODUCT((Mapa_Sala='Mapa do Dia'!$N10)*(Mapa_Data=Data_Mapa)*(Mapa_MinOcup>0)*(Mapa_RelFim<350)*(Mapa_RelFim+Limpeza_Min>340))>0,1,0))) | BE12: =IF(OR('Mapa do Dia'!$A10="",'Calc'!$B2<>"Sala cirúrgica"),"",IF(SUMPRODUCT((Mapa_Sala='Mapa do Dia'!$N10)*(Mapa_Data=Data_Mapa)*(Mapa_MinOcup>0)*(Mapa_RelIni<360)*(Mapa_RelFim>350))>0,2,IF(SUMPRODUCT((Mapa_Sala='Mapa do Dia'!$N10)*(Mapa_Data=Data_Mapa)*(Mapa_MinOcup>0)*(Mapa_RelFim<360)*(Mapa_RelFim+Limpeza_Min>350))>0,1,0))) | BF12: =IF('Mapa do Dia'!$A10="","",'Mapa do Dia'!$F10)
A13: =IF('Mapa do Dia'!$A11="","",'Mapa do Dia'!$A11) | L13: =IF('Mapa do Dia'!$A11="","",IF('Mapa do Dia'!$D11="","(falta escalar)",IFERROR(INDEX(Equipe_Curto,MATCH('Mapa do Dia'!$D11,Equipe_Nome,0)),'Mapa do Dia'!$D11))&IF('Mapa do Dia'!$B11<2,"",IF('Mapa do Dia'!$E11="", " · (falta escalar)"," · "&IFERROR(INDEX(Equipe_Curto,MATCH('Mapa do Dia'!$E11,Equipe_Nome,0)),'Mapa do Dia'!$E11)))) | V13: =IF(OR('Mapa do Dia'!$A11="",'Calc'!$B3<>"Sala cirúrgica"),"",IF(SUMPRODUCT((Mapa_Sala='Mapa do Dia'!$N11)*(Mapa_Data=Data_Mapa)*(Mapa_MinOcup>0)*(Mapa_RelIni<10)*(Mapa_RelFim>0))>0,2,IF(SUMPRODUCT((Mapa_Sala='Mapa do Dia'!$N11)*(Mapa_Data=Data_Mapa)*(Mapa_MinOcup>0)*(Mapa_RelFim<10)*(Mapa_RelFim+Limpeza_Min>0))>0,1,0))) | W13: =IF(OR('Mapa do Dia'!$A11="",'Calc'!$B3<>"Sala cirúrgica"),"",IF(SUMPRODUCT((Mapa_Sala='Mapa do Dia'!$N11)*(Mapa_Data=Data_Mapa)*(Mapa_MinOcup>0)*(Mapa_RelIni<20)*(Mapa_RelFim>10))>0,2,IF(SUMPRODUCT((Mapa_Sala='Mapa do Dia'!$N11)*(Mapa_Data=Data_Mapa)*(Mapa_MinOcup>0)*(Mapa_RelFim<20)*(Mapa_RelFim+Limpeza_Min>10))>0,1,0))) | X13: =IF(OR('Mapa do Dia'!$A11="",'Calc'!$B3<>"Sala cirúrgica"),"",IF(SUMPRODUCT((Mapa_Sala='Mapa do Dia'!$N11)*(Mapa_Data=Data_Mapa)*(Mapa_MinOcup>0)*(Mapa_RelIni<30)*(Mapa_RelFim>20))>0,2,IF(SUMPRODUCT((Mapa_Sala='Mapa do Dia'!$N11)*(Mapa_Data=Data_Mapa)*(Mapa_MinOcup>0)*(Mapa_RelFim<30)*(Mapa_RelFim+Limpeza_Min>20))>0,1,0))) | Y13: =IF(OR('Mapa do Dia'!$A11="",'Calc'!$B3<>"Sala cirúrgica"),"",IF(SUMPRODUCT((Mapa_Sala='Mapa do Dia'!$N11)*(Mapa_Data=Data_Mapa)*(Mapa_MinOcup>0)*(Mapa_RelIni<40)*(Mapa_RelFim>30))>0,2,IF(SUMPRODUCT((Mapa_Sala='Mapa do Dia'!$N11)*(Mapa_Data=Data_Mapa)*(Mapa_MinOcup>0)*(Mapa_RelFim<40)*(Mapa_RelFim+Limpeza_Min>30))>0,1,0))) | Z13: =IF(OR('Mapa do Dia'!$A11="",'Calc'!$B3<>"Sala cirúrgica"),"",IF(SUMPRODUCT((Mapa_Sala='Mapa do Dia'!$N11)*(Mapa_Data=Data_Mapa)*(Mapa_MinOcup>0)*(Mapa_RelIni<50)*(Mapa_RelFim>40))>0,2,IF(SUMPRODUCT((Mapa_Sala='Mapa do Dia'!$N11)*(Mapa_Data=Data_Mapa)*(Mapa_MinOcup>0)*(Mapa_RelFim<50)*(Mapa_RelFim+Limpeza_Min>40))>0,1,0))) | AA13: =IF(OR('Mapa do Dia'!$A11="",'Calc'!$B3<>"Sala cirúrgica"),"",IF(SUMPRODUCT((Mapa_Sala='Mapa do Dia'!$N11)*(Mapa_Data=Data_Mapa)*(Mapa_MinOcup>0)*(Mapa_RelIni<60)*(Mapa_RelFim>50))>0,2,IF(SUMPRODUCT((Mapa_Sala='Mapa do Dia'!$N11)*(Mapa_Data=Data_Mapa)*(Mapa_MinOcup>0)*(Mapa_RelFim<60)*(Mapa_RelFim+Limpeza_Min>50))>0,1,0))) | AB13: =IF(OR('Mapa do Dia'!$A11="",'Calc'!$B3<>"Sala cirúrgica"),"",IF(SUMPRODUCT((Mapa_Sala='Mapa do Dia'!$N11)*(Mapa_Data=Data_Mapa)*(Mapa_MinOcup>0)*(Mapa_RelIni<70)*(Mapa_RelFim>60))>0,2,IF(SUMPRODUCT((Mapa_Sala='Mapa do Dia'!$N11)*(Mapa_Data=Data_Mapa)*(Mapa_MinOcup>0)*(Mapa_RelFim<70)*(Mapa_RelFim+Limpeza_Min>60))>0,1,0))) | AC13: =IF(OR('Mapa do Dia'!$A11="",'Calc'!$B3<>"Sala cirúrgica"),"",IF(SUMPRODUCT((Mapa_Sala='Mapa do Dia'!$N11)*(Mapa_Data=Data_Mapa)*(Mapa_MinOcup>0)*(Mapa_RelIni<80)*(Mapa_RelFim>70))>0,2,IF(SUMPRODUCT((Mapa_Sala='Mapa do Dia'!$N11)*(Mapa_Data=Data_Mapa)*(Mapa_MinOcup>0)*(Mapa_RelFim<80)*(Mapa_RelFim+Limpeza_Min>70))>0,1,0))) | AD13: =IF(OR('Mapa do Dia'!$A11="",'Calc'!$B3<>"Sala cirúrgica"),"",IF(SUMPRODUCT((Mapa_Sala='Mapa do Dia'!$N11)*(Mapa_Data=Data_Mapa)*(Mapa_MinOcup>0)*(Mapa_RelIni<90)*(Mapa_RelFim>80))>0,2,IF(SUMPRODUCT((Mapa_Sala='Mapa do Dia'!$N11)*(Mapa_Data=Data_Mapa)*(Mapa_MinOcup>0)*(Mapa_RelFim<90)*(Mapa_RelFim+Limpeza_Min>80))>0,1,0))) | AE13: =IF(OR('Mapa do Dia'!$A11="",'Calc'!$B3<>"Sala cirúrgica"),"",IF(SUMPRODUCT((Mapa_Sala='Mapa do Dia'!$N11)*(Mapa_Data=Data_Mapa)*(Mapa_MinOcup>0)*(Mapa_RelIni<100)*(Mapa_RelFim>90))>0,2,IF(SUMPRODUCT((Mapa_Sala='Mapa do Dia'!$N11)*(Mapa_Data=Data_Mapa)*(Mapa_MinOcup>0)*(Mapa_RelFim<100)*(Mapa_RelFim+Limpeza_Min>90))>0,1,0))) | AF13: =IF(OR('Mapa do Dia'!$A11="",'Calc'!$B3<>"Sala cirúrgica"),"",IF(SUMPRODUCT((Mapa_Sala='Mapa do Dia'!$N11)*(Mapa_Data=Data_Mapa)*(Mapa_MinOcup>0)*(Mapa_RelIni<110)*(Mapa_RelFim>100))>0,2,IF(SUMPRODUCT((Mapa_Sala='Mapa do Dia'!$N11)*(Mapa_Data=Data_Mapa)*(Mapa_MinOcup>0)*(Mapa_RelFim<110)*(Mapa_RelFim+Limpeza_Min>100))>0,1,0))) | AG13: =IF(OR('Mapa do Dia'!$A11="",'Calc'!$B3<>"Sala cirúrgica"),"",IF(SUMPRODUCT((Mapa_Sala='Mapa do Dia'!$N11)*(Mapa_Data=Data_Mapa)*(Mapa_MinOcup>0)*(Mapa_RelIni<120)*(Mapa_RelFim>110))>0,2,IF(SUMPRODUCT((Mapa_Sala='Mapa do Dia'!$N11)*(Mapa_Data=Data_Mapa)*(Mapa_MinOcup>0)*(Mapa_RelFim<120)*(Mapa_RelFim+Limpeza_Min>110))>0,1,0))) | AH13: =IF(OR('Mapa do Dia'!$A11="",'Calc'!$B3<>"Sala cirúrgica"),"",IF(SUMPRODUCT((Mapa_Sala='Mapa do Dia'!$N11)*(Mapa_Data=Data_Mapa)*(Mapa_MinOcup>0)*(Mapa_RelIni<130)*(Mapa_RelFim>120))>0,2,IF(SUMPRODUCT((Mapa_Sala='Mapa do Dia'!$N11)*(Mapa_Data=Data_Mapa)*(Mapa_MinOcup>0)*(Mapa_RelFim<130)*(Mapa_RelFim+Limpeza_Min>120))>0,1,0))) | AI13: =IF(OR('Mapa do Dia'!$A11="",'Calc'!$B3<>"Sala cirúrgica"),"",IF(SUMPRODUCT((Mapa_Sala='Mapa do Dia'!$N11)*(Mapa_Data=Data_Mapa)*(Mapa_MinOcup>0)*(Mapa_RelIni<140)*(Mapa_RelFim>130))>0,2,IF(SUMPRODUCT((Mapa_Sala='Mapa do Dia'!$N11)*(Mapa_Data=Data_Mapa)*(Mapa_MinOcup>0)*(Mapa_RelFim<140)*(Mapa_RelFim+Limpeza_Min>130))>0,1,0))) | AJ13: =IF(OR('Mapa do Dia'!$A11="",'Calc'!$B3<>"Sala cirúrgica"),"",IF(SUMPRODUCT((Mapa_Sala='Mapa do Dia'!$N11)*(Mapa_Data=Data_Mapa)*(Mapa_MinOcup>0)*(Mapa_RelIni<150)*(Mapa_RelFim>140))>0,2,IF(SUMPRODUCT((Mapa_Sala='Mapa do Dia'!$N11)*(Mapa_Data=Data_Mapa)*(Mapa_MinOcup>0)*(Mapa_RelFim<150)*(Mapa_RelFim+Limpeza_Min>140))>0,1,0))) | AK13: =IF(OR('Mapa do Dia'!$A11="",'Calc'!$B3<>"Sala cirúrgica"),"",IF(SUMPRODUCT((Mapa_Sala='Mapa do Dia'!$N11)*(Mapa_Data=Data_Mapa)*(Mapa_MinOcup>0)*(Mapa_RelIni<160)*(Mapa_RelFim>150))>0,2,IF(SUMPRODUCT((Mapa_Sala='Mapa do Dia'!$N11)*(Mapa_Data=Data_Mapa)*(Mapa_MinOcup>0)*(Mapa_RelFim<160)*(Mapa_RelFim+Limpeza_Min>150))>0,1,0))) | AL13: =IF(OR('Mapa do Dia'!$A11="",'Calc'!$B3<>"Sala cirúrgica"),"",IF(SUMPRODUCT((Mapa_Sala='Mapa do Dia'!$N11)*(Mapa_Data=Data_Mapa)*(Mapa_MinOcup>0)*(Mapa_RelIni<170)*(Mapa_RelFim>160))>0,2,IF(SUMPRODUCT((Mapa_Sala='Mapa do Dia'!$N11)*(Mapa_Data=Data_Mapa)*(Mapa_MinOcup>0)*(Mapa_RelFim<170)*(Mapa_RelFim+Limpeza_Min>160))>0,1,0))) | AM13: =IF(OR('Mapa do Dia'!$A11="",'Calc'!$B3<>"Sala cirúrgica"),"",IF(SUMPRODUCT((Mapa_Sala='Mapa do Dia'!$N11)*(Mapa_Data=Data_Mapa)*(Mapa_MinOcup>0)*(Mapa_RelIni<180)*(Mapa_RelFim>170))>0,2,IF(SUMPRODUCT((Mapa_Sala='Mapa do Dia'!$N11)*(Mapa_Data=Data_Mapa)*(Mapa_MinOcup>0)*(Mapa_RelFim<180)*(Mapa_RelFim+Limpeza_Min>170))>0,1,0))) | AN13: =IF(OR('Mapa do Dia'!$A11="",'Calc'!$B3<>"Sala cirúrgica"),"",IF(SUMPRODUCT((Mapa_Sala='Mapa do Dia'!$N11)*(Mapa_Data=Data_Mapa)*(Mapa_MinOcup>0)*(Mapa_RelIni<190)*(Mapa_RelFim>180))>0,2,IF(SUMPRODUCT((Mapa_Sala='Mapa do Dia'!$N11)*(Mapa_Data=Data_Mapa)*(Mapa_MinOcup>0)*(Mapa_RelFim<190)*(Mapa_RelFim+Limpeza_Min>180))>0,1,0))) | AO13: =IF(OR('Mapa do Dia'!$A11="",'Calc'!$B3<>"Sala cirúrgica"),"",IF(SUMPRODUCT((Mapa_Sala='Mapa do Dia'!$N11)*(Mapa_Data=Data_Mapa)*(Mapa_MinOcup>0)*(Mapa_RelIni<200)*(Mapa_RelFim>190))>0,2,IF(SUMPRODUCT((Mapa_Sala='Mapa do Dia'!$N11)*(Mapa_Data=Data_Mapa)*(Mapa_MinOcup>0)*(Mapa_RelFim<200)*(Mapa_RelFim+Limpeza_Min>190))>0,1,0))) | AP13: =IF(OR('Mapa do Dia'!$A11="",'Calc'!$B3<>"Sala cirúrgica"),"",IF(SUMPRODUCT((Mapa_Sala='Mapa do Dia'!$N11)*(Mapa_Data=Data_Mapa)*(Mapa_MinOcup>0)*(Mapa_RelIni<210)*(Mapa_RelFim>200))>0,2,IF(SUMPRODUCT((Mapa_Sala='Mapa do Dia'!$N11)*(Mapa_Data=Data_Mapa)*(Mapa_MinOcup>0)*(Mapa_RelFim<210)*(Mapa_RelFim+Limpeza_Min>200))>0,1,0))) | AQ13: =IF(OR('Mapa do Dia'!$A11="",'Calc'!$B3<>"Sala cirúrgica"),"",IF(SUMPRODUCT((Mapa_Sala='Mapa do Dia'!$N11)*(Mapa_Data=Data_Mapa)*(Mapa_MinOcup>0)*(Mapa_RelIni<220)*(Mapa_RelFim>210))>0,2,IF(SUMPRODUCT((Mapa_Sala='Mapa do Dia'!$N11)*(Mapa_Data=Data_Mapa)*(Mapa_MinOcup>0)*(Mapa_RelFim<220)*(Mapa_RelFim+Limpeza_Min>210))>0,1,0))) | AR13: =IF(OR('Mapa do Dia'!$A11="",'Calc'!$B3<>"Sala cirúrgica"),"",IF(SUMPRODUCT((Mapa_Sala='Mapa do Dia'!$N11)*(Mapa_Data=Data_Mapa)*(Mapa_MinOcup>0)*(Mapa_RelIni<230)*(Mapa_RelFim>220))>0,2,IF(SUMPRODUCT((Mapa_Sala='Mapa do Dia'!$N11)*(Mapa_Data=Data_Mapa)*(Mapa_MinOcup>0)*(Mapa_RelFim<230)*(Mapa_RelFim+Limpeza_Min>220))>0,1,0))) | AS13: =IF(OR('Mapa do Dia'!$A11="",'Calc'!$B3<>"Sala cirúrgica"),"",IF(SUMPRODUCT((Mapa_Sala='Mapa do Dia'!$N11)*(Mapa_Data=Data_Mapa)*(Mapa_MinOcup>0)*(Mapa_RelIni<240)*(Mapa_RelFim>230))>0,2,IF(SUMPRODUCT((Mapa_Sala='Mapa do Dia'!$N11)*(Mapa_Data=Data_Mapa)*(Mapa_MinOcup>0)*(Mapa_RelFim<240)*(Mapa_RelFim+Limpeza_Min>230))>0,1,0))) | AT13: =IF(OR('Mapa do Dia'!$A11="",'Calc'!$B3<>"Sala cirúrgica"),"",IF(SUMPRODUCT((Mapa_Sala='Mapa do Dia'!$N11)*(Mapa_Data=Data_Mapa)*(Mapa_MinOcup>0)*(Mapa_RelIni<250)*(Mapa_RelFim>240))>0,2,IF(SUMPRODUCT((Mapa_Sala='Mapa do Dia'!$N11)*(Mapa_Data=Data_Mapa)*(Mapa_MinOcup>0)*(Mapa_RelFim<250)*(Mapa_RelFim+Limpeza_Min>240))>0,1,0))) | AU13: =IF(OR('Mapa do Dia'!$A11="",'Calc'!$B3<>"Sala cirúrgica"),"",IF(SUMPRODUCT((Mapa_Sala='Mapa do Dia'!$N11)*(Mapa_Data=Data_Mapa)*(Mapa_MinOcup>0)*(Mapa_RelIni<260)*(Mapa_RelFim>250))>0,2,IF(SUMPRODUCT((Mapa_Sala='Mapa do Dia'!$N11)*(Mapa_Data=Data_Mapa)*(Mapa_MinOcup>0)*(Mapa_RelFim<260)*(Mapa_RelFim+Limpeza_Min>250))>0,1,0))) | AV13: =IF(OR('Mapa do Dia'!$A11="",'Calc'!$B3<>"Sala cirúrgica"),"",IF(SUMPRODUCT((Mapa_Sala='Mapa do Dia'!$N11)*(Mapa_Data=Data_Mapa)*(Mapa_MinOcup>0)*(Mapa_RelIni<270)*(Mapa_RelFim>260))>0,2,IF(SUMPRODUCT((Mapa_Sala='Mapa do Dia'!$N11)*(Mapa_Data=Data_Mapa)*(Mapa_MinOcup>0)*(Mapa_RelFim<270)*(Mapa_RelFim+Limpeza_Min>260))>0,1,0))) | AW13: =IF(OR('Mapa do Dia'!$A11="",'Calc'!$B3<>"Sala cirúrgica"),"",IF(SUMPRODUCT((Mapa_Sala='Mapa do Dia'!$N11)*(Mapa_Data=Data_Mapa)*(Mapa_MinOcup>0)*(Mapa_RelIni<280)*(Mapa_RelFim>270))>0,2,IF(SUMPRODUCT((Mapa_Sala='Mapa do Dia'!$N11)*(Mapa_Data=Data_Mapa)*(Mapa_MinOcup>0)*(Mapa_RelFim<280)*(Mapa_RelFim+Limpeza_Min>270))>0,1,0))) | AX13: =IF(OR('Mapa do Dia'!$A11="",'Calc'!$B3<>"Sala cirúrgica"),"",IF(SUMPRODUCT((Mapa_Sala='Mapa do Dia'!$N11)*(Mapa_Data=Data_Mapa)*(Mapa_MinOcup>0)*(Mapa_RelIni<290)*(Mapa_RelFim>280))>0,2,IF(SUMPRODUCT((Mapa_Sala='Mapa do Dia'!$N11)*(Mapa_Data=Data_Mapa)*(Mapa_MinOcup>0)*(Mapa_RelFim<290)*(Mapa_RelFim+Limpeza_Min>280))>0,1,0))) | AY13: =IF(OR('Mapa do Dia'!$A11="",'Calc'!$B3<>"Sala cirúrgica"),"",IF(SUMPRODUCT((Mapa_Sala='Mapa do Dia'!$N11)*(Mapa_Data=Data_Mapa)*(Mapa_MinOcup>0)*(Mapa_RelIni<300)*(Mapa_RelFim>290))>0,2,IF(SUMPRODUCT((Mapa_Sala='Mapa do Dia'!$N11)*(Mapa_Data=Data_Mapa)*(Mapa_MinOcup>0)*(Mapa_RelFim<300)*(Mapa_RelFim+Limpeza_Min>290))>0,1,0))) | AZ13: =IF(OR('Mapa do Dia'!$A11="",'Calc'!$B3<>"Sala cirúrgica"),"",IF(SUMPRODUCT((Mapa_Sala='Mapa do Dia'!$N11)*(Mapa_Data=Data_Mapa)*(Mapa_MinOcup>0)*(Mapa_RelIni<310)*(Mapa_RelFim>300))>0,2,IF(SUMPRODUCT((Mapa_Sala='Mapa do Dia'!$N11)*(Mapa_Data=Data_Mapa)*(Mapa_MinOcup>0)*(Mapa_RelFim<310)*(Mapa_RelFim+Limpeza_Min>300))>0,1,0))) | BA13: =IF(OR('Mapa do Dia'!$A11="",'Calc'!$B3<>"Sala cirúrgica"),"",IF(SUMPRODUCT((Mapa_Sala='Mapa do Dia'!$N11)*(Mapa_Data=Data_Mapa)*(Mapa_MinOcup>0)*(Mapa_RelIni<320)*(Mapa_RelFim>310))>0,2,IF(SUMPRODUCT((Mapa_Sala='Mapa do Dia'!$N11)*(Mapa_Data=Data_Mapa)*(Mapa_MinOcup>0)*(Mapa_RelFim<320)*(Mapa_RelFim+Limpeza_Min>310))>0,1,0))) | BB13: =IF(OR('Mapa do Dia'!$A11="",'Calc'!$B3<>"Sala cirúrgica"),"",IF(SUMPRODUCT((Mapa_Sala='Mapa do Dia'!$N11)*(Mapa_Data=Data_Mapa)*(Mapa_MinOcup>0)*(Mapa_RelIni<330)*(Mapa_RelFim>320))>0,2,IF(SUMPRODUCT((Mapa_Sala='Mapa do Dia'!$N11)*(Mapa_Data=Data_Mapa)*(Mapa_MinOcup>0)*(Mapa_RelFim<330)*(Mapa_RelFim+Limpeza_Min>320))>0,1,0))) | BC13: =IF(OR('Mapa do Dia'!$A11="",'Calc'!$B3<>"Sala cirúrgica"),"",IF(SUMPRODUCT((Mapa_Sala='Mapa do Dia'!$N11)*(Mapa_Data=Data_Mapa)*(Mapa_MinOcup>0)*(Mapa_RelIni<340)*(Mapa_RelFim>330))>0,2,IF(SUMPRODUCT((Mapa_Sala='Mapa do Dia'!$N11)*(Mapa_Data=Data_Mapa)*(Mapa_MinOcup>0)*(Mapa_RelFim<340)*(Mapa_RelFim+Limpeza_Min>330))>0,1,0))) | BD13: =IF(OR('Mapa do Dia'!$A11="",'Calc'!$B3<>"Sala cirúrgica"),"",IF(SUMPRODUCT((Mapa_Sala='Mapa do Dia'!$N11)*(Mapa_Data=Data_Mapa)*(Mapa_MinOcup>0)*(Mapa_RelIni<350)*(Mapa_RelFim>340))>0,2,IF(SUMPRODUCT((Mapa_Sala='Mapa do Dia'!$N11)*(Mapa_Data=Data_Mapa)*(Mapa_MinOcup>0)*(Mapa_RelFim<350)*(Mapa_RelFim+Limpeza_Min>340))>0,1,0))) | BE13: =IF(OR('Mapa do Dia'!$A11="",'Calc'!$B3<>"Sala cirúrgica"),"",IF(SUMPRODUCT((Mapa_Sala='Mapa do Dia'!$N11)*(Mapa_Data=Data_Mapa)*(Mapa_MinOcup>0)*(Mapa_RelIni<360)*(Mapa_RelFim>350))>0,2,IF(SUMPRODUCT((Mapa_Sala='Mapa do Dia'!$N11)*(Mapa_Data=Data_Mapa)*(Mapa_MinOcup>0)*(Mapa_RelFim<360)*(Mapa_RelFim+Limpeza_Min>350))>0,1,0))) | BF13: =IF('Mapa do Dia'!$A11="","",'Mapa do Dia'!$F11)
A14: =IF('Mapa do Dia'!$A12="","",'Mapa do Dia'!$A12) | L14: =IF('Mapa do Dia'!$A12="","",IF('Mapa do Dia'!$D12="","(falta escalar)",IFERROR(INDEX(Equipe_Curto,MATCH('Mapa do Dia'!$D12,Equipe_Nome,0)),'Mapa do Dia'!$D12))&IF('Mapa do Dia'!$B12<2,"",IF('Mapa do Dia'!$E12="", " · (falta escalar)"," · "&IFERROR(INDEX(Equipe_Curto,MATCH('Mapa do Dia'!$E12,Equipe_Nome,0)),'Mapa do Dia'!$E12)))) | V14: =IF(OR('Mapa do Dia'!$A12="",'Calc'!$B4<>"Sala cirúrgica"),"",IF(SUMPRODUCT((Mapa_Sala='Mapa do Dia'!$N12)*(Mapa_Data=Data_Mapa)*(Mapa_MinOcup>0)*(Mapa_RelIni<10)*(Mapa_RelFim>0))>0,2,IF(SUMPRODUCT((Mapa_Sala='Mapa do Dia'!$N12)*(Mapa_Data=Data_Mapa)*(Mapa_MinOcup>0)*(Mapa_RelFim<10)*(Mapa_RelFim+Limpeza_Min>0))>0,1,0))) | W14: =IF(OR('Mapa do Dia'!$A12="",'Calc'!$B4<>"Sala cirúrgica"),"",IF(SUMPRODUCT((Mapa_Sala='Mapa do Dia'!$N12)*(Mapa_Data=Data_Mapa)*(Mapa_MinOcup>0)*(Mapa_RelIni<20)*(Mapa_RelFim>10))>0,2,IF(SUMPRODUCT((Mapa_Sala='Mapa do Dia'!$N12)*(Mapa_Data=Data_Mapa)*(Mapa_MinOcup>0)*(Mapa_RelFim<20)*(Mapa_RelFim+Limpeza_Min>10))>0,1,0))) | X14: =IF(OR('Mapa do Dia'!$A12="",'Calc'!$B4<>"Sala cirúrgica"),"",IF(SUMPRODUCT((Mapa_Sala='Mapa do Dia'!$N12)*(Mapa_Data=Data_Mapa)*(Mapa_MinOcup>0)*(Mapa_RelIni<30)*(Mapa_RelFim>20))>0,2,IF(SUMPRODUCT((Mapa_Sala='Mapa do Dia'!$N12)*(Mapa_Data=Data_Mapa)*(Mapa_MinOcup>0)*(Mapa_RelFim<30)*(Mapa_RelFim+Limpeza_Min>20))>0,1,0))) | Y14: =IF(OR('Mapa do Dia'!$A12="",'Calc'!$B4<>"Sala cirúrgica"),"",IF(SUMPRODUCT((Mapa_Sala='Mapa do Dia'!$N12)*(Mapa_Data=Data_Mapa)*(Mapa_MinOcup>0)*(Mapa_RelIni<40)*(Mapa_RelFim>30))>0,2,IF(SUMPRODUCT((Mapa_Sala='Mapa do Dia'!$N12)*(Mapa_Data=Data_Mapa)*(Mapa_MinOcup>0)*(Mapa_RelFim<40)*(Mapa_RelFim+Limpeza_Min>30))>0,1,0))) | Z14: =IF(OR('Mapa do Dia'!$A12="",'Calc'!$B4<>"Sala cirúrgica"),"",IF(SUMPRODUCT((Mapa_Sala='Mapa do Dia'!$N12)*(Mapa_Data=Data_Mapa)*(Mapa_MinOcup>0)*(Mapa_RelIni<50)*(Mapa_RelFim>40))>0,2,IF(SUMPRODUCT((Mapa_Sala='Mapa do Dia'!$N12)*(Mapa_Data=Data_Mapa)*(Mapa_MinOcup>0)*(Mapa_RelFim<50)*(Mapa_RelFim+Limpeza_Min>40))>0,1,0))) | AA14: =IF(OR('Mapa do Dia'!$A12="",'Calc'!$B4<>"Sala cirúrgica"),"",IF(SUMPRODUCT((Mapa_Sala='Mapa do Dia'!$N12)*(Mapa_Data=Data_Mapa)*(Mapa_MinOcup>0)*(Mapa_RelIni<60)*(Mapa_RelFim>50))>0,2,IF(SUMPRODUCT((Mapa_Sala='Mapa do Dia'!$N12)*(Mapa_Data=Data_Mapa)*(Mapa_MinOcup>0)*(Mapa_RelFim<60)*(Mapa_RelFim+Limpeza_Min>50))>0,1,0))) | AB14: =IF(OR('Mapa do Dia'!$A12="",'Calc'!$B4<>"Sala cirúrgica"),"",IF(SUMPRODUCT((Mapa_Sala='Mapa do Dia'!$N12)*(Mapa_Data=Data_Mapa)*(Mapa_MinOcup>0)*(Mapa_RelIni<70)*(Mapa_RelFim>60))>0,2,IF(SUMPRODUCT((Mapa_Sala='Mapa do Dia'!$N12)*(Mapa_Data=Data_Mapa)*(Mapa_MinOcup>0)*(Mapa_RelFim<70)*(Mapa_RelFim+Limpeza_Min>60))>0,1,0))) | AC14: =IF(OR('Mapa do Dia'!$A12="",'Calc'!$B4<>"Sala cirúrgica"),"",IF(SUMPRODUCT((Mapa_Sala='Mapa do Dia'!$N12)*(Mapa_Data=Data_Mapa)*(Mapa_MinOcup>0)*(Mapa_RelIni<80)*(Mapa_RelFim>70))>0,2,IF(SUMPRODUCT((Mapa_Sala='Mapa do Dia'!$N12)*(Mapa_Data=Data_Mapa)*(Mapa_MinOcup>0)*(Mapa_RelFim<80)*(Mapa_RelFim+Limpeza_Min>70))>0,1,0))) | AD14: =IF(OR('Mapa do Dia'!$A12="",'Calc'!$B4<>"Sala cirúrgica"),"",IF(SUMPRODUCT((Mapa_Sala='Mapa do Dia'!$N12)*(Mapa_Data=Data_Mapa)*(Mapa_MinOcup>0)*(Mapa_RelIni<90)*(Mapa_RelFim>80))>0,2,IF(SUMPRODUCT((Mapa_Sala='Mapa do Dia'!$N12)*(Mapa_Data=Data_Mapa)*(Mapa_MinOcup>0)*(Mapa_RelFim<90)*(Mapa_RelFim+Limpeza_Min>80))>0,1,0))) | AE14: =IF(OR('Mapa do Dia'!$A12="",'Calc'!$B4<>"Sala cirúrgica"),"",IF(SUMPRODUCT((Mapa_Sala='Mapa do Dia'!$N12)*(Mapa_Data=Data_Mapa)*(Mapa_MinOcup>0)*(Mapa_RelIni<100)*(Mapa_RelFim>90))>0,2,IF(SUMPRODUCT((Mapa_Sala='Mapa do Dia'!$N12)*(Mapa_Data=Data_Mapa)*(Mapa_MinOcup>0)*(Mapa_RelFim<100)*(Mapa_RelFim+Limpeza_Min>90))>0,1,0))) | AF14: =IF(OR('Mapa do Dia'!$A12="",'Calc'!$B4<>"Sala cirúrgica"),"",IF(SUMPRODUCT((Mapa_Sala='Mapa do Dia'!$N12)*(Mapa_Data=Data_Mapa)*(Mapa_MinOcup>0)*(Mapa_RelIni<110)*(Mapa_RelFim>100))>0,2,IF(SUMPRODUCT((Mapa_Sala='Mapa do Dia'!$N12)*(Mapa_Data=Data_Mapa)*(Mapa_MinOcup>0)*(Mapa_RelFim<110)*(Mapa_RelFim+Limpeza_Min>100))>0,1,0))) | AG14: =IF(OR('Mapa do Dia'!$A12="",'Calc'!$B4<>"Sala cirúrgica"),"",IF(SUMPRODUCT((Mapa_Sala='Mapa do Dia'!$N12)*(Mapa_Data=Data_Mapa)*(Mapa_MinOcup>0)*(Mapa_RelIni<120)*(Mapa_RelFim>110))>0,2,IF(SUMPRODUCT((Mapa_Sala='Mapa do Dia'!$N12)*(Mapa_Data=Data_Mapa)*(Mapa_MinOcup>0)*(Mapa_RelFim<120)*(Mapa_RelFim+Limpeza_Min>110))>0,1,0))) | AH14: =IF(OR('Mapa do Dia'!$A12="",'Calc'!$B4<>"Sala cirúrgica"),"",IF(SUMPRODUCT((Mapa_Sala='Mapa do Dia'!$N12)*(Mapa_Data=Data_Mapa)*(Mapa_MinOcup>0)*(Mapa_RelIni<130)*(Mapa_RelFim>120))>0,2,IF(SUMPRODUCT((Mapa_Sala='Mapa do Dia'!$N12)*(Mapa_Data=Data_Mapa)*(Mapa_MinOcup>0)*(Mapa_RelFim<130)*(Mapa_RelFim+Limpeza_Min>120))>0,1,0))) | AI14: =IF(OR('Mapa do Dia'!$A12="",'Calc'!$B4<>"Sala cirúrgica"),"",IF(SUMPRODUCT((Mapa_Sala='Mapa do Dia'!$N12)*(Mapa_Data=Data_Mapa)*(Mapa_MinOcup>0)*(Mapa_RelIni<140)*(Mapa_RelFim>130))>0,2,IF(SUMPRODUCT((Mapa_Sala='Mapa do Dia'!$N12)*(Mapa_Data=Data_Mapa)*(Mapa_MinOcup>0)*(Mapa_RelFim<140)*(Mapa_RelFim+Limpeza_Min>130))>0,1,0))) | AJ14: =IF(OR('Mapa do Dia'!$A12="",'Calc'!$B4<>"Sala cirúrgica"),"",IF(SUMPRODUCT((Mapa_Sala='Mapa do Dia'!$N12)*(Mapa_Data=Data_Mapa)*(Mapa_MinOcup>0)*(Mapa_RelIni<150)*(Mapa_RelFim>140))>0,2,IF(SUMPRODUCT((Mapa_Sala='Mapa do Dia'!$N12)*(Mapa_Data=Data_Mapa)*(Mapa_MinOcup>0)*(Mapa_RelFim<150)*(Mapa_RelFim+Limpeza_Min>140))>0,1,0))) | AK14: =IF(OR('Mapa do Dia'!$A12="",'Calc'!$B4<>"Sala cirúrgica"),"",IF(SUMPRODUCT((Mapa_Sala='Mapa do Dia'!$N12)*(Mapa_Data=Data_Mapa)*(Mapa_MinOcup>0)*(Mapa_RelIni<160)*(Mapa_RelFim>150))>0,2,IF(SUMPRODUCT((Mapa_Sala='Mapa do Dia'!$N12)*(Mapa_Data=Data_Mapa)*(Mapa_MinOcup>0)*(Mapa_RelFim<160)*(Mapa_RelFim+Limpeza_Min>150))>0,1,0))) | AL14: =IF(OR('Mapa do Dia'!$A12="",'Calc'!$B4<>"Sala cirúrgica"),"",IF(SUMPRODUCT((Mapa_Sala='Mapa do Dia'!$N12)*(Mapa_Data=Data_Mapa)*(Mapa_MinOcup>0)*(Mapa_RelIni<170)*(Mapa_RelFim>160))>0,2,IF(SUMPRODUCT((Mapa_Sala='Mapa do Dia'!$N12)*(Mapa_Data=Data_Mapa)*(Mapa_MinOcup>0)*(Mapa_RelFim<170)*(Mapa_RelFim+Limpeza_Min>160))>0,1,0))) | AM14: =IF(OR('Mapa do Dia'!$A12="",'Calc'!$B4<>"Sala cirúrgica"),"",IF(SUMPRODUCT((Mapa_Sala='Mapa do Dia'!$N12)*(Mapa_Data=Data_Mapa)*(Mapa_MinOcup>0)*(Mapa_RelIni<180)*(Mapa_RelFim>170))>0,2,IF(SUMPRODUCT((Mapa_Sala='Mapa do Dia'!$N12)*(Mapa_Data=Data_Mapa)*(Mapa_MinOcup>0)*(Mapa_RelFim<180)*(Mapa_RelFim+Limpeza_Min>170))>0,1,0))) | AN14: =IF(OR('Mapa do Dia'!$A12="",'Calc'!$B4<>"Sala cirúrgica"),"",IF(SUMPRODUCT((Mapa_Sala='Mapa do Dia'!$N12)*(Mapa_Data=Data_Mapa)*(Mapa_MinOcup>0)*(Mapa_RelIni<190)*(Mapa_RelFim>180))>0,2,IF(SUMPRODUCT((Mapa_Sala='Mapa do Dia'!$N12)*(Mapa_Data=Data_Mapa)*(Mapa_MinOcup>0)*(Mapa_RelFim<190)*(Mapa_RelFim+Limpeza_Min>180))>0,1,0))) | AO14: =IF(OR('Mapa do Dia'!$A12="",'Calc'!$B4<>"Sala cirúrgica"),"",IF(SUMPRODUCT((Mapa_Sala='Mapa do Dia'!$N12)*(Mapa_Data=Data_Mapa)*(Mapa_MinOcup>0)*(Mapa_RelIni<200)*(Mapa_RelFim>190))>0,2,IF(SUMPRODUCT((Mapa_Sala='Mapa do Dia'!$N12)*(Mapa_Data=Data_Mapa)*(Mapa_MinOcup>0)*(Mapa_RelFim<200)*(Mapa_RelFim+Limpeza_Min>190))>0,1,0))) | AP14: =IF(OR('Mapa do Dia'!$A12="",'Calc'!$B4<>"Sala cirúrgica"),"",IF(SUMPRODUCT((Mapa_Sala='Mapa do Dia'!$N12)*(Mapa_Data=Data_Mapa)*(Mapa_MinOcup>0)*(Mapa_RelIni<210)*(Mapa_RelFim>200))>0,2,IF(SUMPRODUCT((Mapa_Sala='Mapa do Dia'!$N12)*(Mapa_Data=Data_Mapa)*(Mapa_MinOcup>0)*(Mapa_RelFim<210)*(Mapa_RelFim+Limpeza_Min>200))>0,1,0))) | AQ14: =IF(OR('Mapa do Dia'!$A12="",'Calc'!$B4<>"Sala cirúrgica"),"",IF(SUMPRODUCT((Mapa_Sala='Mapa do Dia'!$N12)*(Mapa_Data=Data_Mapa)*(Mapa_MinOcup>0)*(Mapa_RelIni<220)*(Mapa_RelFim>210))>0,2,IF(SUMPRODUCT((Mapa_Sala='Mapa do Dia'!$N12)*(Mapa_Data=Data_Mapa)*(Mapa_MinOcup>0)*(Mapa_RelFim<220)*(Mapa_RelFim+Limpeza_Min>210))>0,1,0))) | AR14: =IF(OR('Mapa do Dia'!$A12="",'Calc'!$B4<>"Sala cirúrgica"),"",IF(SUMPRODUCT((Mapa_Sala='Mapa do Dia'!$N12)*(Mapa_Data=Data_Mapa)*(Mapa_MinOcup>0)*(Mapa_RelIni<230)*(Mapa_RelFim>220))>0,2,IF(SUMPRODUCT((Mapa_Sala='Mapa do Dia'!$N12)*(Mapa_Data=Data_Mapa)*(Mapa_MinOcup>0)*(Mapa_RelFim<230)*(Mapa_RelFim+Limpeza_Min>220))>0,1,0))) | AS14: =IF(OR('Mapa do Dia'!$A12="",'Calc'!$B4<>"Sala cirúrgica"),"",IF(SUMPRODUCT((Mapa_Sala='Mapa do Dia'!$N12)*(Mapa_Data=Data_Mapa)*(Mapa_MinOcup>0)*(Mapa_RelIni<240)*(Mapa_RelFim>230))>0,2,IF(SUMPRODUCT((Mapa_Sala='Mapa do Dia'!$N12)*(Mapa_Data=Data_Mapa)*(Mapa_MinOcup>0)*(Mapa_RelFim<240)*(Mapa_RelFim+Limpeza_Min>230))>0,1,0))) | AT14: =IF(OR('Mapa do Dia'!$A12="",'Calc'!$B4<>"Sala cirúrgica"),"",IF(SUMPRODUCT((Mapa_Sala='Mapa do Dia'!$N12)*(Mapa_Data=Data_Mapa)*(Mapa_MinOcup>0)*(Mapa_RelIni<250)*(Mapa_RelFim>240))>0,2,IF(SUMPRODUCT((Mapa_Sala='Mapa do Dia'!$N12)*(Mapa_Data=Data_Mapa)*(Mapa_MinOcup>0)*(Mapa_RelFim<250)*(Mapa_RelFim+Limpeza_Min>240))>0,1,0))) | AU14: =IF(OR('Mapa do Dia'!$A12="",'Calc'!$B4<>"Sala cirúrgica"),"",IF(SUMPRODUCT((Mapa_Sala='Mapa do Dia'!$N12)*(Mapa_Data=Data_Mapa)*(Mapa_MinOcup>0)*(Mapa_RelIni<260)*(Mapa_RelFim>250))>0,2,IF(SUMPRODUCT((Mapa_Sala='Mapa do Dia'!$N12)*(Mapa_Data=Data_Mapa)*(Mapa_MinOcup>0)*(Mapa_RelFim<260)*(Mapa_RelFim+Limpeza_Min>250))>0,1,0))) | AV14: =IF(OR('Mapa do Dia'!$A12="",'Calc'!$B4<>"Sala cirúrgica"),"",IF(SUMPRODUCT((Mapa_Sala='Mapa do Dia'!$N12)*(Mapa_Data=Data_Mapa)*(Mapa_MinOcup>0)*(Mapa_RelIni<270)*(Mapa_RelFim>260))>0,2,IF(SUMPRODUCT((Mapa_Sala='Mapa do Dia'!$N12)*(Mapa_Data=Data_Mapa)*(Mapa_MinOcup>0)*(Mapa_RelFim<270)*(Mapa_RelFim+Limpeza_Min>260))>0,1,0))) | AW14: =IF(OR('Mapa do Dia'!$A12="",'Calc'!$B4<>"Sala cirúrgica"),"",IF(SUMPRODUCT((Mapa_Sala='Mapa do Dia'!$N12)*(Mapa_Data=Data_Mapa)*(Mapa_MinOcup>0)*(Mapa_RelIni<280)*(Mapa_RelFim>270))>0,2,IF(SUMPRODUCT((Mapa_Sala='Mapa do Dia'!$N12)*(Mapa_Data=Data_Mapa)*(Mapa_MinOcup>0)*(Mapa_RelFim<280)*(Mapa_RelFim+Limpeza_Min>270))>0,1,0))) | AX14: =IF(OR('Mapa do Dia'!$A12="",'Calc'!$B4<>"Sala cirúrgica"),"",IF(SUMPRODUCT((Mapa_Sala='Mapa do Dia'!$N12)*(Mapa_Data=Data_Mapa)*(Mapa_MinOcup>0)*(Mapa_RelIni<290)*(Mapa_RelFim>280))>0,2,IF(SUMPRODUCT((Mapa_Sala='Mapa do Dia'!$N12)*(Mapa_Data=Data_Mapa)*(Mapa_MinOcup>0)*(Mapa_RelFim<290)*(Mapa_RelFim+Limpeza_Min>280))>0,1,0))) | AY14: =IF(OR('Mapa do Dia'!$A12="",'Calc'!$B4<>"Sala cirúrgica"),"",IF(SUMPRODUCT((Mapa_Sala='Mapa do Dia'!$N12)*(Mapa_Data=Data_Mapa)*(Mapa_MinOcup>0)*(Mapa_RelIni<300)*(Mapa_RelFim>290))>0,2,IF(SUMPRODUCT((Mapa_Sala='Mapa do Dia'!$N12)*(Mapa_Data=Data_Mapa)*(Mapa_MinOcup>0)*(Mapa_RelFim<300)*(Mapa_RelFim+Limpeza_Min>290))>0,1,0))) | AZ14: =IF(OR('Mapa do Dia'!$A12="",'Calc'!$B4<>"Sala cirúrgica"),"",IF(SUMPRODUCT((Mapa_Sala='Mapa do Dia'!$N12)*(Mapa_Data=Data_Mapa)*(Mapa_MinOcup>0)*(Mapa_RelIni<310)*(Mapa_RelFim>300))>0,2,IF(SUMPRODUCT((Mapa_Sala='Mapa do Dia'!$N12)*(Mapa_Data=Data_Mapa)*(Mapa_MinOcup>0)*(Mapa_RelFim<310)*(Mapa_RelFim+Limpeza_Min>300))>0,1,0))) | BA14: =IF(OR('Mapa do Dia'!$A12="",'Calc'!$B4<>"Sala cirúrgica"),"",IF(SUMPRODUCT((Mapa_Sala='Mapa do Dia'!$N12)*(Mapa_Data=Data_Mapa)*(Mapa_MinOcup>0)*(Mapa_RelIni<320)*(Mapa_RelFim>310))>0,2,IF(SUMPRODUCT((Mapa_Sala='Mapa do Dia'!$N12)*(Mapa_Data=Data_Mapa)*(Mapa_MinOcup>0)*(Mapa_RelFim<320)*(Mapa_RelFim+Limpeza_Min>310))>0,1,0))) | BB14: =IF(OR('Mapa do Dia'!$A12="",'Calc'!$B4<>"Sala cirúrgica"),"",IF(SUMPRODUCT((Mapa_Sala='Mapa do Dia'!$N12)*(Mapa_Data=Data_Mapa)*(Mapa_MinOcup>0)*(Mapa_RelIni<330)*(Mapa_RelFim>320))>0,2,IF(SUMPRODUCT((Mapa_Sala='Mapa do Dia'!$N12)*(Mapa_Data=Data_Mapa)*(Mapa_MinOcup>0)*(Mapa_RelFim<330)*(Mapa_RelFim+Limpeza_Min>320))>0,1,0))) | BC14: =IF(OR('Mapa do Dia'!$A12="",'Calc'!$B4<>"Sala cirúrgica"),"",IF(SUMPRODUCT((Mapa_Sala='Mapa do Dia'!$N12)*(Mapa_Data=Data_Mapa)*(Mapa_MinOcup>0)*(Mapa_RelIni<340)*(Mapa_RelFim>330))>0,2,IF(SUMPRODUCT((Mapa_Sala='Mapa do Dia'!$N12)*(Mapa_Data=Data_Mapa)*(Mapa_MinOcup>0)*(Mapa_RelFim<340)*(Mapa_RelFim+Limpeza_Min>330))>0,1,0))) | BD14: =IF(OR('Mapa do Dia'!$A12="",'Calc'!$B4<>"Sala cirúrgica"),"",IF(SUMPRODUCT((Mapa_Sala='Mapa do Dia'!$N12)*(Mapa_Data=Data_Mapa)*(Mapa_MinOcup>0)*(Mapa_RelIni<350)*(Mapa_RelFim>340))>0,2,IF(SUMPRODUCT((Mapa_Sala='Mapa do Dia'!$N12)*(Mapa_Data=Data_Mapa)*(Mapa_MinOcup>0)*(Mapa_RelFim<350)*(Mapa_RelFim+Limpeza_Min>340))>0,1,0))) | BE14: =IF(OR('Mapa do Dia'!$A12="",'Calc'!$B4<>"Sala cirúrgica"),"",IF(SUMPRODUCT((Mapa_Sala='Mapa do Dia'!$N12)*(Mapa_Data=Data_Mapa)*(Mapa_MinOcup>0)*(Mapa_RelIni<360)*(Mapa_RelFim>350))>0,2,IF(SUMPRODUCT((Mapa_Sala='Mapa do Dia'!$N12)*(Mapa_Data=Data_Mapa)*(Mapa_MinOcup>0)*(Mapa_RelFim<360)*(Mapa_RelFim+Limpeza_Min>350))>0,1,0))) | BF14: =IF('Mapa do Dia'!$A12="","",'Mapa do Dia'!$F12)
A15: =IF('Mapa do Dia'!$A13="","",'Mapa do Dia'!$A13) | L15: =IF('Mapa do Dia'!$A13="","",IF('Mapa do Dia'!$D13="","(falta escalar)",IFERROR(INDEX(Equipe_Curto,MATCH('Mapa do Dia'!$D13,Equipe_Nome,0)),'Mapa do Dia'!$D13))&IF('Mapa do Dia'!$B13<2,"",IF('Mapa do Dia'!$E13="", " · (falta escalar)"," · "&IFERROR(INDEX(Equipe_Curto,MATCH('Mapa do Dia'!$E13,Equipe_Nome,0)),'Mapa do Dia'!$E13)))) | V15: =IF(OR('Mapa do Dia'!$A13="",'Calc'!$B5<>"Sala cirúrgica"),"",IF(SUMPRODUCT((Mapa_Sala='Mapa do Dia'!$N13)*(Mapa_Data=Data_Mapa)*(Mapa_MinOcup>0)*(Mapa_RelIni<10)*(Mapa_RelFim>0))>0,2,IF(SUMPRODUCT((Mapa_Sala='Mapa do Dia'!$N13)*(Mapa_Data=Data_Mapa)*(Mapa_MinOcup>0)*(Mapa_RelFim<10)*(Mapa_RelFim+Limpeza_Min>0))>0,1,0))) | W15: =IF(OR('Mapa do Dia'!$A13="",'Calc'!$B5<>"Sala cirúrgica"),"",IF(SUMPRODUCT((Mapa_Sala='Mapa do Dia'!$N13)*(Mapa_Data=Data_Mapa)*(Mapa_MinOcup>0)*(Mapa_RelIni<20)*(Mapa_RelFim>10))>0,2,IF(SUMPRODUCT((Mapa_Sala='Mapa do Dia'!$N13)*(Mapa_Data=Data_Mapa)*(Mapa_MinOcup>0)*(Mapa_RelFim<20)*(Mapa_RelFim+Limpeza_Min>10))>0,1,0))) | X15: =IF(OR('Mapa do Dia'!$A13="",'Calc'!$B5<>"Sala cirúrgica"),"",IF(SUMPRODUCT((Mapa_Sala='Mapa do Dia'!$N13)*(Mapa_Data=Data_Mapa)*(Mapa_MinOcup>0)*(Mapa_RelIni<30)*(Mapa_RelFim>20))>0,2,IF(SUMPRODUCT((Mapa_Sala='Mapa do Dia'!$N13)*(Mapa_Data=Data_Mapa)*(Mapa_MinOcup>0)*(Mapa_RelFim<30)*(Mapa_RelFim+Limpeza_Min>20))>0,1,0))) | Y15: =IF(OR('Mapa do Dia'!$A13="",'Calc'!$B5<>"Sala cirúrgica"),"",IF(SUMPRODUCT((Mapa_Sala='Mapa do Dia'!$N13)*(Mapa_Data=Data_Mapa)*(Mapa_MinOcup>0)*(Mapa_RelIni<40)*(Mapa_RelFim>30))>0,2,IF(SUMPRODUCT((Mapa_Sala='Mapa do Dia'!$N13)*(Mapa_Data=Data_Mapa)*(Mapa_MinOcup>0)*(Mapa_RelFim<40)*(Mapa_RelFim+Limpeza_Min>30))>0,1,0))) | Z15: =IF(OR('Mapa do Dia'!$A13="",'Calc'!$B5<>"Sala cirúrgica"),"",IF(SUMPRODUCT((Mapa_Sala='Mapa do Dia'!$N13)*(Mapa_Data=Data_Mapa)*(Mapa_MinOcup>0)*(Mapa_RelIni<50)*(Mapa_RelFim>40))>0,2,IF(SUMPRODUCT((Mapa_Sala='Mapa do Dia'!$N13)*(Mapa_Data=Data_Mapa)*(Mapa_MinOcup>0)*(Mapa_RelFim<50)*(Mapa_RelFim+Limpeza_Min>40))>0,1,0))) | AA15: =IF(OR('Mapa do Dia'!$A13="",'Calc'!$B5<>"Sala cirúrgica"),"",IF(SUMPRODUCT((Mapa_Sala='Mapa do Dia'!$N13)*(Mapa_Data=Data_Mapa)*(Mapa_MinOcup>0)*(Mapa_RelIni<60)*(Mapa_RelFim>50))>0,2,IF(SUMPRODUCT((Mapa_Sala='Mapa do Dia'!$N13)*(Mapa_Data=Data_Mapa)*(Mapa_MinOcup>0)*(Mapa_RelFim<60)*(Mapa_RelFim+Limpeza_Min>50))>0,1,0))) | AB15: =IF(OR('Mapa do Dia'!$A13="",'Calc'!$B5<>"Sala cirúrgica"),"",IF(SUMPRODUCT((Mapa_Sala='Mapa do Dia'!$N13)*(Mapa_Data=Data_Mapa)*(Mapa_MinOcup>0)*(Mapa_RelIni<70)*(Mapa_RelFim>60))>0,2,IF(SUMPRODUCT((Mapa_Sala='Mapa do Dia'!$N13)*(Mapa_Data=Data_Mapa)*(Mapa_MinOcup>0)*(Mapa_RelFim<70)*(Mapa_RelFim+Limpeza_Min>60))>0,1,0))) | AC15: =IF(OR('Mapa do Dia'!$A13="",'Calc'!$B5<>"Sala cirúrgica"),"",IF(SUMPRODUCT((Mapa_Sala='Mapa do Dia'!$N13)*(Mapa_Data=Data_Mapa)*(Mapa_MinOcup>0)*(Mapa_RelIni<80)*(Mapa_RelFim>70))>0,2,IF(SUMPRODUCT((Mapa_Sala='Mapa do Dia'!$N13)*(Mapa_Data=Data_Mapa)*(Mapa_MinOcup>0)*(Mapa_RelFim<80)*(Mapa_RelFim+Limpeza_Min>70))>0,1,0))) | AD15: =IF(OR('Mapa do Dia'!$A13="",'Calc'!$B5<>"Sala cirúrgica"),"",IF(SUMPRODUCT((Mapa_Sala='Mapa do Dia'!$N13)*(Mapa_Data=Data_Mapa)*(Mapa_MinOcup>0)*(Mapa_RelIni<90)*(Mapa_RelFim>80))>0,2,IF(SUMPRODUCT((Mapa_Sala='Mapa do Dia'!$N13)*(Mapa_Data=Data_Mapa)*(Mapa_MinOcup>0)*(Mapa_RelFim<90)*(Mapa_RelFim+Limpeza_Min>80))>0,1,0))) | AE15: =IF(OR('Mapa do Dia'!$A13="",'Calc'!$B5<>"Sala cirúrgica"),"",IF(SUMPRODUCT((Mapa_Sala='Mapa do Dia'!$N13)*(Mapa_Data=Data_Mapa)*(Mapa_MinOcup>0)*(Mapa_RelIni<100)*(Mapa_RelFim>90))>0,2,IF(SUMPRODUCT((Mapa_Sala='Mapa do Dia'!$N13)*(Mapa_Data=Data_Mapa)*(Mapa_MinOcup>0)*(Mapa_RelFim<100)*(Mapa_RelFim+Limpeza_Min>90))>0,1,0))) | AF15: =IF(OR('Mapa do Dia'!$A13="",'Calc'!$B5<>"Sala cirúrgica"),"",IF(SUMPRODUCT((Mapa_Sala='Mapa do Dia'!$N13)*(Mapa_Data=Data_Mapa)*(Mapa_MinOcup>0)*(Mapa_RelIni<110)*(Mapa_RelFim>100))>0,2,IF(SUMPRODUCT((Mapa_Sala='Mapa do Dia'!$N13)*(Mapa_Data=Data_Mapa)*(Mapa_MinOcup>0)*(Mapa_RelFim<110)*(Mapa_RelFim+Limpeza_Min>100))>0,1,0))) | AG15: =IF(OR('Mapa do Dia'!$A13="",'Calc'!$B5<>"Sala cirúrgica"),"",IF(SUMPRODUCT((Mapa_Sala='Mapa do Dia'!$N13)*(Mapa_Data=Data_Mapa)*(Mapa_MinOcup>0)*(Mapa_RelIni<120)*(Mapa_RelFim>110))>0,2,IF(SUMPRODUCT((Mapa_Sala='Mapa do Dia'!$N13)*(Mapa_Data=Data_Mapa)*(Mapa_MinOcup>0)*(Mapa_RelFim<120)*(Mapa_RelFim+Limpeza_Min>110))>0,1,0))) | AH15: =IF(OR('Mapa do Dia'!$A13="",'Calc'!$B5<>"Sala cirúrgica"),"",IF(SUMPRODUCT((Mapa_Sala='Mapa do Dia'!$N13)*(Mapa_Data=Data_Mapa)*(Mapa_MinOcup>0)*(Mapa_RelIni<130)*(Mapa_RelFim>120))>0,2,IF(SUMPRODUCT((Mapa_Sala='Mapa do Dia'!$N13)*(Mapa_Data=Data_Mapa)*(Mapa_MinOcup>0)*(Mapa_RelFim<130)*(Mapa_RelFim+Limpeza_Min>120))>0,1,0))) | AI15: =IF(OR('Mapa do Dia'!$A13="",'Calc'!$B5<>"Sala cirúrgica"),"",IF(SUMPRODUCT((Mapa_Sala='Mapa do Dia'!$N13)*(Mapa_Data=Data_Mapa)*(Mapa_MinOcup>0)*(Mapa_RelIni<140)*(Mapa_RelFim>130))>0,2,IF(SUMPRODUCT((Mapa_Sala='Mapa do Dia'!$N13)*(Mapa_Data=Data_Mapa)*(Mapa_MinOcup>0)*(Mapa_RelFim<140)*(Mapa_RelFim+Limpeza_Min>130))>0,1,0))) | AJ15: =IF(OR('Mapa do Dia'!$A13="",'Calc'!$B5<>"Sala cirúrgica"),"",IF(SUMPRODUCT((Mapa_Sala='Mapa do Dia'!$N13)*(Mapa_Data=Data_Mapa)*(Mapa_MinOcup>0)*(Mapa_RelIni<150)*(Mapa_RelFim>140))>0,2,IF(SUMPRODUCT((Mapa_Sala='Mapa do Dia'!$N13)*(Mapa_Data=Data_Mapa)*(Mapa_MinOcup>0)*(Mapa_RelFim<150)*(Mapa_RelFim+Limpeza_Min>140))>0,1,0))) | AK15: =IF(OR('Mapa do Dia'!$A13="",'Calc'!$B5<>"Sala cirúrgica"),"",IF(SUMPRODUCT((Mapa_Sala='Mapa do Dia'!$N13)*(Mapa_Data=Data_Mapa)*(Mapa_MinOcup>0)*(Mapa_RelIni<160)*(Mapa_RelFim>150))>0,2,IF(SUMPRODUCT((Mapa_Sala='Mapa do Dia'!$N13)*(Mapa_Data=Data_Mapa)*(Mapa_MinOcup>0)*(Mapa_RelFim<160)*(Mapa_RelFim+Limpeza_Min>150))>0,1,0))) | AL15: =IF(OR('Mapa do Dia'!$A13="",'Calc'!$B5<>"Sala cirúrgica"),"",IF(SUMPRODUCT((Mapa_Sala='Mapa do Dia'!$N13)*(Mapa_Data=Data_Mapa)*(Mapa_MinOcup>0)*(Mapa_RelIni<170)*(Mapa_RelFim>160))>0,2,IF(SUMPRODUCT((Mapa_Sala='Mapa do Dia'!$N13)*(Mapa_Data=Data_Mapa)*(Mapa_MinOcup>0)*(Mapa_RelFim<170)*(Mapa_RelFim+Limpeza_Min>160))>0,1,0))) | AM15: =IF(OR('Mapa do Dia'!$A13="",'Calc'!$B5<>"Sala cirúrgica"),"",IF(SUMPRODUCT((Mapa_Sala='Mapa do Dia'!$N13)*(Mapa_Data=Data_Mapa)*(Mapa_MinOcup>0)*(Mapa_RelIni<180)*(Mapa_RelFim>170))>0,2,IF(SUMPRODUCT((Mapa_Sala='Mapa do Dia'!$N13)*(Mapa_Data=Data_Mapa)*(Mapa_MinOcup>0)*(Mapa_RelFim<180)*(Mapa_RelFim+Limpeza_Min>170))>0,1,0))) | AN15: =IF(OR('Mapa do Dia'!$A13="",'Calc'!$B5<>"Sala cirúrgica"),"",IF(SUMPRODUCT((Mapa_Sala='Mapa do Dia'!$N13)*(Mapa_Data=Data_Mapa)*(Mapa_MinOcup>0)*(Mapa_RelIni<190)*(Mapa_RelFim>180))>0,2,IF(SUMPRODUCT((Mapa_Sala='Mapa do Dia'!$N13)*(Mapa_Data=Data_Mapa)*(Mapa_MinOcup>0)*(Mapa_RelFim<190)*(Mapa_RelFim+Limpeza_Min>180))>0,1,0))) | AO15: =IF(OR('Mapa do Dia'!$A13="",'Calc'!$B5<>"Sala cirúrgica"),"",IF(SUMPRODUCT((Mapa_Sala='Mapa do Dia'!$N13)*(Mapa_Data=Data_Mapa)*(Mapa_MinOcup>0)*(Mapa_RelIni<200)*(Mapa_RelFim>190))>0,2,IF(SUMPRODUCT((Mapa_Sala='Mapa do Dia'!$N13)*(Mapa_Data=Data_Mapa)*(Mapa_MinOcup>0)*(Mapa_RelFim<200)*(Mapa_RelFim+Limpeza_Min>190))>0,1,0))) | AP15: =IF(OR('Mapa do Dia'!$A13="",'Calc'!$B5<>"Sala cirúrgica"),"",IF(SUMPRODUCT((Mapa_Sala='Mapa do Dia'!$N13)*(Mapa_Data=Data_Mapa)*(Mapa_MinOcup>0)*(Mapa_RelIni<210)*(Mapa_RelFim>200))>0,2,IF(SUMPRODUCT((Mapa_Sala='Mapa do Dia'!$N13)*(Mapa_Data=Data_Mapa)*(Mapa_MinOcup>0)*(Mapa_RelFim<210)*(Mapa_RelFim+Limpeza_Min>200))>0,1,0))) | AQ15: =IF(OR('Mapa do Dia'!$A13="",'Calc'!$B5<>"Sala cirúrgica"),"",IF(SUMPRODUCT((Mapa_Sala='Mapa do Dia'!$N13)*(Mapa_Data=Data_Mapa)*(Mapa_MinOcup>0)*(Mapa_RelIni<220)*(Mapa_RelFim>210))>0,2,IF(SUMPRODUCT((Mapa_Sala='Mapa do Dia'!$N13)*(Mapa_Data=Data_Mapa)*(Mapa_MinOcup>0)*(Mapa_RelFim<220)*(Mapa_RelFim+Limpeza_Min>210))>0,1,0))) | AR15: =IF(OR('Mapa do Dia'!$A13="",'Calc'!$B5<>"Sala cirúrgica"),"",IF(SUMPRODUCT((Mapa_Sala='Mapa do Dia'!$N13)*(Mapa_Data=Data_Mapa)*(Mapa_MinOcup>0)*(Mapa_RelIni<230)*(Mapa_RelFim>220))>0,2,IF(SUMPRODUCT((Mapa_Sala='Mapa do Dia'!$N13)*(Mapa_Data=Data_Mapa)*(Mapa_MinOcup>0)*(Mapa_RelFim<230)*(Mapa_RelFim+Limpeza_Min>220))>0,1,0))) | AS15: =IF(OR('Mapa do Dia'!$A13="",'Calc'!$B5<>"Sala cirúrgica"),"",IF(SUMPRODUCT((Mapa_Sala='Mapa do Dia'!$N13)*(Mapa_Data=Data_Mapa)*(Mapa_MinOcup>0)*(Mapa_RelIni<240)*(Mapa_RelFim>230))>0,2,IF(SUMPRODUCT((Mapa_Sala='Mapa do Dia'!$N13)*(Mapa_Data=Data_Mapa)*(Mapa_MinOcup>0)*(Mapa_RelFim<240)*(Mapa_RelFim+Limpeza_Min>230))>0,1,0))) | AT15: =IF(OR('Mapa do Dia'!$A13="",'Calc'!$B5<>"Sala cirúrgica"),"",IF(SUMPRODUCT((Mapa_Sala='Mapa do Dia'!$N13)*(Mapa_Data=Data_Mapa)*(Mapa_MinOcup>0)*(Mapa_RelIni<250)*(Mapa_RelFim>240))>0,2,IF(SUMPRODUCT((Mapa_Sala='Mapa do Dia'!$N13)*(Mapa_Data=Data_Mapa)*(Mapa_MinOcup>0)*(Mapa_RelFim<250)*(Mapa_RelFim+Limpeza_Min>240))>0,1,0))) | AU15: =IF(OR('Mapa do Dia'!$A13="",'Calc'!$B5<>"Sala cirúrgica"),"",IF(SUMPRODUCT((Mapa_Sala='Mapa do Dia'!$N13)*(Mapa_Data=Data_Mapa)*(Mapa_MinOcup>0)*(Mapa_RelIni<260)*(Mapa_RelFim>250))>0,2,IF(SUMPRODUCT((Mapa_Sala='Mapa do Dia'!$N13)*(Mapa_Data=Data_Mapa)*(Mapa_MinOcup>0)*(Mapa_RelFim<260)*(Mapa_RelFim+Limpeza_Min>250))>0,1,0))) | AV15: =IF(OR('Mapa do Dia'!$A13="",'Calc'!$B5<>"Sala cirúrgica"),"",IF(SUMPRODUCT((Mapa_Sala='Mapa do Dia'!$N13)*(Mapa_Data=Data_Mapa)*(Mapa_MinOcup>0)*(Mapa_RelIni<270)*(Mapa_RelFim>260))>0,2,IF(SUMPRODUCT((Mapa_Sala='Mapa do Dia'!$N13)*(Mapa_Data=Data_Mapa)*(Mapa_MinOcup>0)*(Mapa_RelFim<270)*(Mapa_RelFim+Limpeza_Min>260))>0,1,0))) | AW15: =IF(OR('Mapa do Dia'!$A13="",'Calc'!$B5<>"Sala cirúrgica"),"",IF(SUMPRODUCT((Mapa_Sala='Mapa do Dia'!$N13)*(Mapa_Data=Data_Mapa)*(Mapa_MinOcup>0)*(Mapa_RelIni<280)*(Mapa_RelFim>270))>0,2,IF(SUMPRODUCT((Mapa_Sala='Mapa do Dia'!$N13)*(Mapa_Data=Data_Mapa)*(Mapa_MinOcup>0)*(Mapa_RelFim<280)*(Mapa_RelFim+Limpeza_Min>270))>0,1,0))) | AX15: =IF(OR('Mapa do Dia'!$A13="",'Calc'!$B5<>"Sala cirúrgica"),"",IF(SUMPRODUCT((Mapa_Sala='Mapa do Dia'!$N13)*(Mapa_Data=Data_Mapa)*(Mapa_MinOcup>0)*(Mapa_RelIni<290)*(Mapa_RelFim>280))>0,2,IF(SUMPRODUCT((Mapa_Sala='Mapa do Dia'!$N13)*(Mapa_Data=Data_Mapa)*(Mapa_MinOcup>0)*(Mapa_RelFim<290)*(Mapa_RelFim+Limpeza_Min>280))>0,1,0))) | AY15: =IF(OR('Mapa do Dia'!$A13="",'Calc'!$B5<>"Sala cirúrgica"),"",IF(SUMPRODUCT((Mapa_Sala='Mapa do Dia'!$N13)*(Mapa_Data=Data_Mapa)*(Mapa_MinOcup>0)*(Mapa_RelIni<300)*(Mapa_RelFim>290))>0,2,IF(SUMPRODUCT((Mapa_Sala='Mapa do Dia'!$N13)*(Mapa_Data=Data_Mapa)*(Mapa_MinOcup>0)*(Mapa_RelFim<300)*(Mapa_RelFim+Limpeza_Min>290))>0,1,0))) | AZ15: =IF(OR('Mapa do Dia'!$A13="",'Calc'!$B5<>"Sala cirúrgica"),"",IF(SUMPRODUCT((Mapa_Sala='Mapa do Dia'!$N13)*(Mapa_Data=Data_Mapa)*(Mapa_MinOcup>0)*(Mapa_RelIni<310)*(Mapa_RelFim>300))>0,2,IF(SUMPRODUCT((Mapa_Sala='Mapa do Dia'!$N13)*(Mapa_Data=Data_Mapa)*(Mapa_MinOcup>0)*(Mapa_RelFim<310)*(Mapa_RelFim+Limpeza_Min>300))>0,1,0))) | BA15: =IF(OR('Mapa do Dia'!$A13="",'Calc'!$B5<>"Sala cirúrgica"),"",IF(SUMPRODUCT((Mapa_Sala='Mapa do Dia'!$N13)*(Mapa_Data=Data_Mapa)*(Mapa_MinOcup>0)*(Mapa_RelIni<320)*(Mapa_RelFim>310))>0,2,IF(SUMPRODUCT((Mapa_Sala='Mapa do Dia'!$N13)*(Mapa_Data=Data_Mapa)*(Mapa_MinOcup>0)*(Mapa_RelFim<320)*(Mapa_RelFim+Limpeza_Min>310))>0,1,0))) | BB15: =IF(OR('Mapa do Dia'!$A13="",'Calc'!$B5<>"Sala cirúrgica"),"",IF(SUMPRODUCT((Mapa_Sala='Mapa do Dia'!$N13)*(Mapa_Data=Data_Mapa)*(Mapa_MinOcup>0)*(Mapa_RelIni<330)*(Mapa_RelFim>320))>0,2,IF(SUMPRODUCT((Mapa_Sala='Mapa do Dia'!$N13)*(Mapa_Data=Data_Mapa)*(Mapa_MinOcup>0)*(Mapa_RelFim<330)*(Mapa_RelFim+Limpeza_Min>320))>0,1,0))) | BC15: =IF(OR('Mapa do Dia'!$A13="",'Calc'!$B5<>"Sala cirúrgica"),"",IF(SUMPRODUCT((Mapa_Sala='Mapa do Dia'!$N13)*(Mapa_Data=Data_Mapa)*(Mapa_MinOcup>0)*(Mapa_RelIni<340)*(Mapa_RelFim>330))>0,2,IF(SUMPRODUCT((Mapa_Sala='Mapa do Dia'!$N13)*(Mapa_Data=Data_Mapa)*(Mapa_MinOcup>0)*(Mapa_RelFim<340)*(Mapa_RelFim+Limpeza_Min>330))>0,1,0))) | BD15: =IF(OR('Mapa do Dia'!$A13="",'Calc'!$B5<>"Sala cirúrgica"),"",IF(SUMPRODUCT((Mapa_Sala='Mapa do Dia'!$N13)*(Mapa_Data=Data_Mapa)*(Mapa_MinOcup>0)*(Mapa_RelIni<350)*(Mapa_RelFim>340))>0,2,IF(SUMPRODUCT((Mapa_Sala='Mapa do Dia'!$N13)*(Mapa_Data=Data_Mapa)*(Mapa_MinOcup>0)*(Mapa_RelFim<350)*(Mapa_RelFim+Limpeza_Min>340))>0,1,0))) | BE15: =IF(OR('Mapa do Dia'!$A13="",'Calc'!$B5<>"Sala cirúrgica"),"",IF(SUMPRODUCT((Mapa_Sala='Mapa do Dia'!$N13)*(Mapa_Data=Data_Mapa)*(Mapa_MinOcup>0)*(Mapa_RelIni<360)*(Mapa_RelFim>350))>0,2,IF(SUMPRODUCT((Mapa_Sala='Mapa do Dia'!$N13)*(Mapa_Data=Data_Mapa)*(Mapa_MinOcup>0)*(Mapa_RelFim<360)*(Mapa_RelFim+Limpeza_Min>350))>0,1,0))) | BF15: =IF('Mapa do Dia'!$A13="","",'Mapa do Dia'!$F13)
