Workbook
Name Data_Mapa: 'Parâmetros'!$B$6
Name Peso_Instrumentador: 'Parâmetros'!$B$17
Name Peso_Circulante: 'Parâmetros'!$B$18
Name Afinidade_Meta: 'Parâmetros'!$B$20
Name Afinidade_Min: 'Parâmetros'!$B$21
Name Nivel_Critico: 'Parâmetros'!$B$22
Name Part_Min_Critica: 'Parâmetros'!$B$23
Name Setup_Min: 'Parâmetros'!$B$26
Name Meta_Ocupacao: 'Parâmetros'!$B$27
Name Ocupacao_Max: 'Parâmetros'!$B$28
Name Turnos_Nome: 'Parâmetros'!$A$32:$A$34
Name Turnos_Min: 'Parâmetros'!$D$32:$D$34
Name Lista_Turnos: 'Parâmetros'!$A$32:$A$34
Name Lista_Funcoes: 'Parâmetros'!$F$5:$F$7
Name Lista_StatusEquipe: 'Parâmetros'!$G$5:$G$8
Name Lista_StatusCirurgia: 'Parâmetros'!$H$5:$H$8
Name Lista_Porte: 'Parâmetros'!$I$5:$I$7
Name Lista_Salas: OFFSET('Salas'!$A$2,0,0,MAX(1,COUNTA('Salas'!$A$2:$A$13)),1)
Name Lista_Especialidades: OFFSET('Especialidades'!$B$2,0,0,MAX(1,COUNTA('Especialidades'!$B$2:$B$21)),1)
Name Lista_Tecnicos: OFFSET('Equipe'!$B$2,0,0,MAX(1,COUNTA('Equipe'!$B$2:$B$151)),1)
Name Turnos_Ini: 'Parâmetros'!$B$32:$B$34
Name Turnos_Fim: 'Parâmetros'!$C$32:$C$34
Name Salas_Cod: 'Salas'!$A$2:$A$13
Name Salas_Status: 'Salas'!$C$2:$C$13
Name Esp_Nome: 'Especialidades'!$B$2:$B$21
Name Esp_Dur: 'Especialidades'!$C$2:$C$21
Name Equipe_Nome: 'Equipe'!$B$2:$B$151
Name Equipe_Funcao: 'Equipe'!$C$2:$C$151
Name Equipe_Status: 'Equipe'!$E$2:$E$151
Name Matriz_Nome: 'Matriz_Habilidades'!$B$2:$B$151
Name Matriz_Niveis: 'Matriz_Habilidades'!$D$2:$W$151
Name Matriz_Esp: 'Matriz_Habilidades'!$D$1:$W$1
Name Mix_Esp: 'Calc_Mix'!$D$1:$W$1
Name Mapa_Data: 'Mapa_Cirurgico'!$A$2:$A$301
Name Mapa_Sala: 'Mapa_Cirurgico'!$B$2:$B$301
Name Mapa_Turno: 'Mapa_Cirurgico'!$C$2:$C$301
Name Mapa_Ini: 'Mapa_Cirurgico'!$D$2:$D$301
Name Mapa_Fim: 'Mapa_Cirurgico'!$E$2:$E$301
Name Mapa_Esp: 'Mapa_Cirurgico'!$F$2:$F$301
Name Mapa_Status: 'Mapa_Cirurgico'!$J$2:$J$301
Name Mapa_Dur: 'Mapa_Cirurgico'!$K$2:$K$301
Name Mapa_MinOcup: 'Mapa_Cirurgico'!$L$2:$L$301
Name Mapa_Alerta: 'Mapa_Cirurgico'!$M$2:$M$301
Name Mapa_IniNum: 'Mapa_Cirurgico'!$O$2:$O$301
Name Mapa_FimNum: 'Mapa_Cirurgico'!$P$2:$P$301
Name Esc_Sala: 'Escala_Duplas'!$B$2:$B$37
Name Esc_Turno: 'Escala_Duplas'!$C$2:$C$37
Name Esc_NCir: 'Escala_Duplas'!$D$2:$D$37
Name Esc_MinOcup: 'Escala_Duplas'!$E$2:$E$37
Name Esc_MinTurno: 'Escala_Duplas'!$F$2:$F$37
Name Esc_Circ: 'Escala_Duplas'!$H$2:$H$37
Name Esc_Instr: 'Escala_Duplas'!$J$2:$J$37
Name Esc_Afin: 'Escala_Duplas'!$N$2:$N$37
Name Esc_Class: 'Escala_Duplas'!$O$2:$O$37
Name Esc_AfinNum: 'Escala_Duplas'!$V$2:$V$37
Name Esc_Peso: 'Escala_Duplas'!$W$2:$W$37
Name Esc_Alertas: 'Escala_Duplas'!$T$2:$T$37
Name Equipe_Turno: 'Equipe'!$D$2:$D$151

Sheet Instruções
A1: CENTRO CIRÚRGICO — MAPA CIRÚRGICO E ESCALA DE DUPLAS POR SALA
A2: Ferramenta operacional da coordenação de enfermagem. Modelo de alocação: DUPLA FIXA POR SALA NO TURNO, classificada por AFINIDADE DE HABILIDADE.
B4: 1. COMO A PLANILHA ESTÁ ORGANIZADA
B5: ENTRADAS (o que se digita) | C5: Parâmetros · Especialidades · Salas · Equipe · Matriz_Habilidades · Mapa_Cirurgico · colunas CIRCULANTE/INSTRUMENTADOR da Escala_Duplas
B6: PROCESSAMENTO (não digitar) | C6: Calc_Mix (minutos por especialidade em cada sala × turno) e Calc_Afinidade (afinidade dos técnicos ELEGÍVEIS — ativos, do turno e ainda não escalados — com cada sala × turno). São abas de cálculo, ficam visíveis para auditoria.
B7: SAÍDAS | C7: Escala_Duplas (alocação validada) · Sugestao_Duplas (ranking de quem tem mais afinidade) · Painel (visão executiva) · Base_Historico (acúmulo dia a dia)
B8: 2. A REGRA DE AFINIDADE
B9: Afinidade do técnico com a sala/turno | C9: Média dos níveis de habilidade do técnico nas especialidades daquela sala, PONDERADA PELOS MINUTOS de cada especialidade no turno. Especialidade que ocupa mais tempo pesa mais.
B10: Afinidade da dupla | C10: Peso_Circulante × afinidade do circulante + Peso_Instrumentador × afinidade do instrumentador. Os dois pesos ficam em Parâmetros (padrão 0,40 / 0,60) e podem ser alterados.
B11: Classificação | C11: ADEQUADA quando ≥ Afinidade_Meta (2,50) · ATENÇÃO entre a meta e a mínima · CRÍTICA abaixo de Afinidade_Min (2,00). Os dois limites estão em Parâmetros.
B12: Alerta de inaptidão | C12: Se qualquer especialidade responder por ≥ Part_Min_Critica (20%) do tempo da sala e algum membro da dupla tiver nível ≤ Nivel_Critico (1) nela, a linha é sinalizada mesmo que a média esteja boa.
B13: 3. ROTINA DO DIA
B14: Passo 1 | C14: Em Parâmetros, ajuste a Data do mapa.
B15: Passo 2 | C15: Lance as cirurgias em Mapa_Cirurgico (sala, turno, horários, especialidade, status). A coluna Alerta aponta sobreposição de horário, sala bloqueada, duração inválida e horário fora da janela do turno.
B16: Passo 3 | C16: Em Escala_Duplas, escolha o CIRCULANTE e o INSTRUMENTADOR de cada sala/turno nas listas suspensas (células azuis). A aba Sugestao_Duplas mostra, para cada sala/turno, os técnicos AINDA LIVRES daquele turno em ordem de afinidade — a lista se atualiza a cada nome que você escala.
B17: Passo 4 | C17: Confira a coluna ALERTAS e o Painel. Resolva as linhas CRÍTICA / SEM DUPLA antes de publicar a escala.
B18: Passo 5 (fechamento) | C18: Copie as linhas de Escala_Duplas e cole COMO VALORES em Base_Historico para manter o histórico do dia.
B19: 4. CONVENÇÕES VISUAIS
B20: Azul | C20: Célula de entrada — pode digitar.
B21: Amarelo | C21: Premissa de negócio (Parâmetros). Alterar aqui recalcula toda a planilha.
B22: Preto | C22: Resultado de fórmula — não digitar por cima.
B23: Verde itálico | C23: Valor trazido de outra aba por fórmula.
B24: Vermelho / âmbar / verde | C24: Semáforo de afinidade, ocupação e alertas.
B25: 5. COMO EXPANDIR
B26: Novo técnico | C26: Acrescente a linha em Equipe (até 150). A Matriz_Habilidades, o Calc_Afinidade e as listas suspensas acompanham automaticamente — basta preencher os níveis na Matriz.
B27: Nova especialidade | C27: Acrescente a linha em Especialidades (até 20 posições). As colunas da Matriz_Habilidades e do Calc_Mix pegam o nome automaticamente.
B28: Nova sala | C28: Acrescente a linha em Salas (até 12). As três linhas de turno correspondentes já existem em Calc_Mix, Escala_Duplas e Sugestao_Duplas e passam a funcionar sozinhas.
B29: Mais cirurgias | C29: O Mapa_Cirurgico comporta 300 cirurgias por dia; todas as fórmulas já cobrem esse intervalo.
B30: 6. OBSERVAÇÕES TÉCNICAS
B31: Dados de exemplo | C31: Equipe, matriz de habilidades e mapa cirúrgico vêm preenchidos com um dia de exemplo para demonstração. Substitua pelos dados reais do serviço.
B32: Ocupação da sala | C32: Cada cirurgia consome sua duração + o tempo de setup/limpeza definido em Parâmetros. Cirurgias Canceladas ou Suspensas não entram na ocupação nem no cálculo de afinidade.
B33: Colunas auxiliares ocultas | C33: Mapa_Cirurgico colunas N, O e P e Escala_Duplas colunas U, V e W guardam cálculos intermediários (texto de alerta, horários numéricos e ponderação da afinidade). Não excluir.
B34: Desempate na Sugestao_Duplas | C34: O Calc_Afinidade soma 0,000001 × número da linha para evitar empates no ranking; o efeito é invisível nas duas casas decimais exibidas.
B35: Funções utilizadas | C35: SUMIFS, COUNTIFS, SUMPRODUCT, INDEX, MATCH, LARGE, IF e IFERROR — compatíveis com Excel e LibreOffice. Não há macros, Power Query nem matrizes dinâmicas.

Sheet Parâmetros
A1: PARÂMETROS E PREMISSAS
A2: Células amarelas são premissas de negócio: alterá-las recalcula toda a planilha. Nenhuma premissa está embutida em fórmula.
A3: 1. IDENTIFICAÇÃO | F3: LISTAS AUXILIARES
A4: Unidade / Hospital | B4: Hospital — preencher | F4: Função | G4: Status equipe | H4: Status cirurgia | I4: Porte
A5: Setor | B5: Centro Cirúrgico | F5: Circulante | G5: Ativo | H5: Agendada | I5: P
A6: Data do mapa | B6: 46254 | F6: Instrumentador | G6: Férias | H6: Realizada | I6: M
A7: Coordenação responsável | B7: Coordenação de Enfermagem | F7: Ambos | G7: Afastado | H7: Cancelada | I7: G
G8: Folga | H8: Suspensa
A9: 2. ESCALA DE HABILIDADE (usada na Matriz_Habilidades)
A10: Nível | B10: Descrição | C10: Pontos | D10: Critério operacional
A11: 0 | B11: Não apto | C11: 0 | D11: Não pode assumir a especialidade
A12: 1 | B12: Em treinamento | C12: 1 | D12: Só atua acompanhado de técnico apto
A13: 2 | B13: Apto | C13: 2 | D13: Atua com autonomia na especialidade
A14: 3 | B14: Referência | C14: 3 | D14: Atua em alta complexidade e treina a equipe
A16: 3. PARÂMETROS DE AFINIDADE DA DUPLA
A17: Peso do INSTRUMENTADOR na afinidade da dupla | B17: 0.6 | D17: Peso_Instrumentador
A18: Peso do CIRCULANTE na afinidade da dupla | B18: 0.4 | D18: Peso_Circulante
A19: Soma dos pesos (precisa ser 1,00) | B19: =B17+B18
A20: Afinidade META — dupla ADEQUADA quando ≥ | B20: 2.5 | D20: Afinidade_Meta
A21: Afinidade MÍNIMA aceitável — abaixo disto é CRÍTICA | B21: 2 | D21: Afinidade_Min
A22: Nível considerado INAPTO (≤) | B22: 1 | D22: Nivel_Critico
A23: Participação mínima da especialidade para alerta crítico | B23: 0.2 | D23: Part_Min_Critica
A25: 4. PARÂMETROS OPERACIONAIS
A26: Tempo de setup / limpeza por cirurgia (min) | B26: 30 | D26: Setup_Min
A27: Meta de ocupação de sala | B27: 0.85 | D27: Meta_Ocupacao
A28: Ocupação máxima admitida | B28: 1 | D28: Ocupacao_Max
A30: 5. TURNOS
A31: Turno | B31: Início | C31: Fim | D31: Minutos disponíveis
A32: Manhã | B32: 0.29166667 | C32: 0.54166667 | D32: =MOD(C32-B32,1)*1440
A33: Tarde | B33: 0.54166667 | C33: 0.79166667 | D33: =MOD(C33-B33,1)*1440
A34: Noite | B34: 0.79166667 | C34: 0.29166667 | D34: =MOD(C34-B34,1)*1440

Sheet Especialidades
A1: Código | B1: Especialidade | C1: Duração média (min) | D1: Ativa | E1: Observação
A2: ORT | B2: Ortopedia | C2: 120 | D2: Sim
A3: CGE | B3: Cirurgia Geral | C3: 90 | D3: Sim
A4: NEU | B4: Neurocirurgia | C4: 240 | D4: Sim
A5: CCV | B5: Cirurgia Cardiovascular | C5: 300 | D5: Sim
A6: URO | B6: Urologia | C6: 90 | D6: Sim
A7: GIN | B7: Ginecologia | C7: 90 | D7: Sim
A8: OBS | B8: Obstetrícia | C8: 60 | D8: Sim
A9: OFT | B9: Oftalmologia | C9: 45 | D9: Sim
A10: OTO | B10: Otorrinolaringologia | C10: 75 | D10: Sim
A11: PLA | B11: Cirurgia Plástica | C11: 120 | D11: Sim
A12: VAS | B12: Cirurgia Vascular | C12: 150 | D12: Sim
A13: BAR | B13: Cirurgia Bariátrica | C13: 150 | D13: Sim
... A15: BMF | B15: Buco-Maxilo-Facial | C15: 120 | D15: Sim

Sheet Salas
A1: Sala | B1: Descrição | C1: Status | D1: Especialidades do perfil | E1: Observação
A2: SO-01 | B2: Sala 1 — Ortopedia | C2: Ativa | D2: Ortopedia
A3: SO-02 | B3: Sala 2 — Geral/Bariátrica | C3: Ativa | D3: Cirurgia Geral, Cirurgia Bariátrica
A4: SO-03 | B4: Sala 3 — Neurocirurgia | C4: Ativa | D4: Neurocirurgia
A5: SO-04 | B5: Sala 4 — Cardiovascular | C5: Ativa | D5: Cirurgia Cardiovascular, Cirurgia Vascular
A6: SO-05 | B6: Sala 5 — Uro/Gineco | C6: Ativa | D6: Urologia, Ginecologia
A7: SO-06 | B7: Sala 6 — Oftalmo/Otorrino | C7: Ativa | D7: Oftalmologia, Otorrinolaringologia
A8: SO-07 | B8: Sala 7 — Plástica/BMF | C8: Ativa | D8: Cirurgia Plástica, Buco-Maxilo-Facial
A9: SO-08 | B9: Sala 8 — Pediátrica/Obst. | C9: Ativa | D9: Cirurgia Pediátrica, Obstetrícia

Sheet Equipe
A1: Matrícula | B1: Nome do técnico | C1: Função | D1: Turno preferencial | E1: Status | F1: Observação
A2: TEC-001 | B2: Ana Paula Ribeiro | C2: Circulante | D2: Manhã | E2: Ativo
A3: TEC-002 | B3: Bruno Tavares | C3: Instrumentador | D3: Manhã | E3: Ativo
A4: TEC-003 | B4: Carla Menezes | C4: Circulante | D4: Tarde | E4: Ativo
A5: TEC-004 | B5: Daniel Prado | C5: Instrumentador | D5: Tarde | E5: Ativo
A6: TEC-005 | B6: Elisa Fontes | C6: Circulante | D6: Noite | E6: Ativo
A7: TEC-006 | B7: Fábio Cardoso | C7: Instrumentador | D7: Noite | E7: Ativo
A8: TEC-007 | B8: Gabriela Nunes | C8: Circulante | D8: Manhã | E8: Ativo
A9: TEC-008 | B9: Henrique Sales | C9: Instrumentador | D9: Manhã | E9: Ativo
A10: TEC-009 | B10: Isabel Moraes | C10: Circulante | D10: Tarde | E10: Ativo
A11: TEC-010 | B11: João Vitor Lima | C11: Instrumentador | D11: Tarde | E11: Ativo
A12: TEC-011 | B12: Karina Duarte | C12: Circulante | D12: Noite | E12: Ativo
A13: TEC-012 | B13: Leandro Peixoto | C13: Instrumentador | D13: Noite | E13: Ativo
... A61: TEC-060 | B61: Lucas Vilarinho | C61: Ambos | D61: Noite | E61: Afastado

Sheet Matriz_Habilidades
A1: Matrícula | B1: Nome do técnico | C1: Função | D1: =IF('Especialidades'!$B$2="","",'Especialidades'!$B$2) | E1: =IF('Especialidades'!$B$3="","",'Especialidades'!$B$3) | F1: =IF('Especialidades'!$B$4="","",'Especialidades'!$B$4) | G1: =IF('Especialidades'!$B$5="","",'Especialidades'!$B$5) | H1: =IF('Especialidades'!$B$6="","",'Especialidades'!$B$6) | I1: =IF('Especialidades'!$B$7="","",'Especialidades'!$B$7) | J1: =IF('Especialidades'!$B$8="","",'Especialidades'!$B$8) | K1: =IF('Especialidades'!$B$9="","",'Especialidades'!$B$9) | L1: =IF('Especialidades'!$B$10="","",'Especialidades'!$B$10) | M1: =IF('Especialidades'!$B$11="","",'Especialidades'!$B$11) | N1: =IF('Especialidades'!$B$12="","",'Especialidades'!$B$12) | O1: =IF('Especialidades'!$B$13="","",'Especialidades'!$B$13) | P1: =IF('Especialidades'!$B$14="","",'Especialidades'!$B$14) | Q1: =IF('Especialidades'!$B$15="","",'Especialidades'!$B$15) | R1: =IF('Especialidades'!$B$16="","",'Especialidades'!$B$16) | S1: =IF('Especialidades'!$B$17="","",'Especialidades'!$B$17) | T1: =IF('Especialidades'!$B$18="","",'Especialidades'!$B$18) | U1: =IF('Especialidades'!$B$19="","",'Especialidades'!$B$19) | V1: =IF('Especialidades'!$B$20="","",'Especialidades'!$B$20) | W1: =IF('Especialidades'!$B$21="","",'Especialidades'!$B$21) | X1: Nível médio (geral) | Y1: Nº especialidades aptas (≥2)
A2: =IF('Equipe'!A2="","",'Equipe'!A2) | B2: =IF('Equipe'!B2="","",'Equipe'!B2) | C2: =IF('Equipe'!C2="","",'Equipe'!C2) | D2: 3 | E2: 2 | F2: 0 | G2: 0 | H2: 0 | I2: 1 | J2: 2 | K2: 1 | L2: 0 | M2: 0 | N2: 1 | O2: 2 | P2: 1 | Q2: 0 | X2: =IF($B2="","",IFERROR(SUMPRODUCT((Matriz_Esp<>"")*D2:W2)/SUMPRODUCT(--(Matriz_Esp<>"")),"")) | Y2: =IF($B2="","",SUMPRODUCT((Matriz_Esp<>"")*(D2:W2>=2)))
A3: =IF('Equipe'!A3="","",'Equipe'!A3) | B3: =IF('Equipe'!B3="","",'Equipe'!B3) | C3: =IF('Equipe'!C3="","",'Equipe'!C3) | D3: 3 | E3: 2 | F3: 0 | G3: 1 | H3: 1 | I3: 0 | J3: 2 | K3: 0 | L3: 0 | M3: 1 | N3: 0 | O3: 1 | P3: 1 | Q3: 0 | X3: =IF($B3="","",IFERROR(SUMPRODUCT((Matriz_Esp<>"")*D3:W3)/SUMPRODUCT(--(Matriz_Esp<>"")),"")) | Y3: =IF($B3="","",SUMPRODUCT((Matriz_Esp<>"")*(D3:W3>=2)))
A4: =IF('Equipe'!A4="","",'Equipe'!A4) | B4: =IF('Equipe'!B4="","",'Equipe'!B4) | C4: =IF('Equipe'!C4="","",'Equipe'!C4) | D4: 3 | E4: 2 | F4: 0 | G4: 0 | H4: 0 | I4: 0 | J4: 2 | K4: 0 | L4: 1 | M4: 1 | N4: 1 | O4: 2 | P4: 1 | Q4: 0 | X4: =IF($B4="","",IFERROR(SUMPRODUCT((Matriz_Esp<>"")*D4:W4)/SUMPRODUCT(--(Matriz_Esp<>"")),"")) | Y4: =IF($B4="","",SUMPRODUCT((Matriz_Esp<>"")*(D4:W4>=2)))
A5: =IF('Equipe'!A5="","",'Equipe'!A5) | B5: =IF('Equipe'!B5="","",'Equipe'!B5) | C5: =IF('Equipe'!C5="","",'Equipe'!C5) | D5: 3 | E5: 1 | F5: 0 | G5: 0 | H5: 0 | I5: 0 | J5: 1 | K5: 0 | L5: 1 | M5: 0 | N5: 0 | O5: 1 | P5: 1 | Q5: 0 | X5: =IF($B5="","",IFERROR(SUMPRODUCT((Matriz_Esp<>"")*D5:W5)/SUMPRODUCT(--(Matriz_Esp<>"")),"")) | Y5: =IF($B5="","",SUMPRODUCT((Matriz_Esp<>"")*(D5:W5>=2)))
A6: =IF('Equipe'!A6="","",'Equipe'!A6) | B6: =IF('Equipe'!B6="","",'Equipe'!B6) | C6: =IF('Equipe'!C6="","",'Equipe'!C6) | D6: 3 | E6: 2 | F6: 1 | G6: 0 | H6: 1 | I6: 1 | J6: 2 | K6: 0 | L6: 0 | M6: 1 | N6: 1 | O6: 1 | P6: 2 | Q6: 1 | X6: =IF($B6="","",IFERROR(SUMPRODUCT((Matriz_Esp<>"")*D6:W6)/SUMPRODUCT(--(Matriz_Esp<>"")),"")) | Y6: =IF($B6="","",SUMPRODUCT((Matriz_Esp<>"")*(D6:W6>=2)))
A7: =IF('Equipe'!A7="","",'Equipe'!A7) | B7: =IF('Equipe'!B7="","",'Equipe'!B7) | C7: =IF('Equipe'!C7="","",'Equipe'!C7) | D7: 3 | E7: 1 | F7: 1 | G7: 0 | H7: 0 | I7: 0 | J7: 2 | K7: 1 | L7: 1 | M7: 1 | N7: 1 | O7: 2 | P7: 2 | Q7: 1 | X7: =IF($B7="","",IFERROR(SUMPRODUCT((Matriz_Esp<>"")*D7:W7)/SUMPRODUCT(--(Matriz_Esp<>"")),"")) | Y7: =IF($B7="","",SUMPRODUCT((Matriz_Esp<>"")*(D7:W7>=2)))
A8: =IF('Equipe'!A8="","",'Equipe'!A8) | B8: =IF('Equipe'!B8="","",'Equipe'!B8) | C8: =IF('Equipe'!C8="","",'Equipe'!C8) | D8: 2 | E8: 3 | F8: 1 | G8: 0 | H8: 0 | I8: 0 | J8: 0 | K8: 0 | L8: 0 | M8: 1 | N8: 0 | O8: 3 | P8: 0 | Q8: 0 | X8: =IF($B8="","",IFERROR(SUMPRODUCT((Matriz_Esp<>"")*D8:W8)/SUMPRODUCT(--(Matriz_Esp<>"")),"")) | Y8: =IF($B8="","",SUMPRODUCT((Matriz_Esp<>"")*(D8:W8>=2)))
A9: =IF('Equipe'!A9="","",'Equipe'!A9) | B9: =IF('Equipe'!B9="","",'Equipe'!B9) | C9: =IF('Equipe'!C9="","",'Equipe'!C9) | D9: 2 | E9: 3 | F9: 2 | G9: 0 | H9: 0 | I9: 0 | J9: 0 | K9: 0 | L9: 0 | M9: 0 | N9: 0 | O9: 3 | P9: 0 | Q9: 1 | X9: =IF($B9="","",IFERROR(SUMPRODUCT((Matriz_Esp<>"")*D9:W9)/SUMPRODUCT(--(Matriz_Esp<>"")),"")) | Y9: =IF($B9="","",SUMPRODUCT((Matriz_Esp<>"")*(D9:W9>=2)))
A10: =IF('Equipe'!A10="","",'Equipe'!A10) | B10: =IF('Equipe'!B10="","",'Equipe'!B10) | C10: =IF('Equipe'!C10="","",'Equipe'!C10) | D10: 2 | E10: 3 | F10: 1 | G10: 0 | H10: 0 | I10: 0 | J10: 1 | K10: 1 | L10: 1 | M10: 0 | N10: 0 | O10: 3 | P10: 0 | Q10: 1 | X10: =IF($B10="","",IFERROR(SUMPRODUCT((Matriz_Esp<>"")*D10:W10)/SUMPRODUCT(--(Matriz_Esp<>"")),"")) | Y10: =IF($B10="","",SUMPRODUCT((Matriz_Esp<>"")*(D10:W10>=2)))
A11: =IF('Equipe'!A11="","",'Equipe'!A11) | B11: =IF('Equipe'!B11="","",'Equipe'!B11) | C11: =IF('Equipe'!C11="","",'Equipe'!C11) | D11: 2 | E11: 3 | F11: 2 | G11: 1 | H11: 1 | I11: 0 | J11: 0 | K11: 1 | L11: 0 | M11: 0 | N11: 1 | O11: 3 | P11: 0 | Q11: 0 | X11: =IF($B11="","",IFERROR(SUMPRODUCT((Matriz_Esp<>"")*D11:W11)/SUMPRODUCT(--(Matriz_Esp<>"")),"")) | Y11: =IF($B11="","",SUMPRODUCT((Matriz_Esp<>"")*(D11:W11>=2)))
A12: =IF('Equipe'!A12="","",'Equipe'!A12) | B12: =IF('Equipe'!B12="","",'Equipe'!B12) | C12: =IF('Equipe'!C12="","",'Equipe'!C12) | D12: 2 | E12: 3 | F12: 2 | G12: 0 | H12: 1 | I12: 1 | J12: 1 | K12: 0 | L12: 0 | M12: 1 | N12: 0 | O12: 3 | P12: 0 | Q12: 1 | X12: =IF($B12="","",IFERROR(SUMPRODUCT((Matriz_Esp<>"")*D12:W12)/SUMPRODUCT(--(Matriz_Esp<>"")),"")) | Y12: =IF($B12="","",SUMPRODUCT((Matriz_Esp<>"")*(D12:W12>=2)))
A13: =IF('Equipe'!A13="","",'Equipe'!A13) | B13: =IF('Equipe'!B13="","",'Equipe'!B13) | C13: =IF('Equipe'!C13="","",'Equipe'!C13) | D13: 1 | E13: 3 | F13: 1 | G13: 1 | H13: 0 | I13: 0 | J13: 0 | K13: 0 | L13: 1 | M13: 0 | N13: 1 | O13: 3 | P13: 0 | Q13: 0 | X13: =IF($B13="","",IFERROR(SUMPRODUCT((Matriz_Esp<>"")*D13:W13)/SUMPRODUCT(--(Matriz_Esp<>"")),"")) | Y13: =IF($B13="","",SUMPRODUCT((Matriz_Esp<>"")*(D13:W13>=2)))
... A61: =IF('Equipe'!A61="","",'Equipe'!A61) | B61: =IF('Equipe'!B61="","",'Equipe'!B61) | C61: =IF('Equipe'!C61="","",'Equipe'!C61) | D61: 1 | E61: 1 | F61: 2 | G61: 2 | H61: 1 | I61: 1 | J61: 2 | K61: 1 | L61: 1 | M61: 1 | N61: 1 | O61: 2 | P61: 1 | Q61: 2 | X61: =IF($B61="","",IFERROR(SUMPRODUCT((Matriz_Esp<>"")*D61:W61)/SUMPRODUCT(--(Matriz_Esp<>"")),"")) | Y61: =IF($B61="","",SUMPRODUCT((Matriz_Esp<>"")*(D61:W61>=2)))
A62: =IF('Equipe'!A62="","",'Equipe'!A62) | B62: =IF('Equipe'!B62="","",'Equipe'!B62) | C62: =IF('Equipe'!C62="","",'Equipe'!C62) | X62: =IF($B62="","",IFERROR(SUMPRODUCT((Matriz_Esp<>"")*D62:W62)/SUMPRODUCT(--(Matriz_Esp<>"")),"")) | Y62: =IF($B62="","",SUMPRODUCT((Matriz_Esp<>"")*(D62:W62>=2)))
A63: =IF('Equipe'!A63="","",'Equipe'!A63) | B63: =IF('Equipe'!B63="","",'Equipe'!B63) | C63: =IF('Equipe'!C63="","",'Equipe'!C63) | X63: =IF($B63="","",IFERROR(SUMPRODUCT((Matriz_Esp<>"")*D63:W63)/SUMPRODUCT(--(Matriz_Esp<>"")),"")) | Y63: =IF($B63="","",SUMPRODUCT((Matriz_Esp<>"")*(D63:W63>=2)))
A64: =IF('Equipe'!A64="","",'Equipe'!A64) | B64: =IF('Equipe'!B64="","",'Equipe'!B64) | C64: =IF('Equipe'!C64="","",'Equipe'!C64) | X64: =IF($B64="","",IFERROR(SUMPRODUCT((Matriz_Esp<>"")*D64:W64)/SUMPRODUCT(--(Matriz_Esp<>"")),"")) | Y64: =IF($B64="","",SUMPRODUCT((Matriz_Esp<>"")*(D64:W64>=2)))
A65: =IF('Equipe'!A65="","",'Equipe'!A65) | B65: =IF('Equipe'!B65="","",'Equipe'!B65) | C65: =IF('Equipe'!C65="","",'Equipe'!C65) | X65: =IF($B65="","",IFERROR(SUMPRODUCT((Matriz_Esp<>"")*D65:W65)/SUMPRODUCT(--(Matriz_Esp<>"")),"")) | Y65: =IF($B65="","",SUMPRODUCT((Matriz_Esp<>"")*(D65:W65>=2)))
A66: =IF('Equipe'!A66="","",'Equipe'!A66) | B66: =IF('Equipe'!B66="","",'Equipe'!B66) | C66: =IF('Equipe'!C66="","",'Equipe'!C66) | X66: =IF($B66="","",IFERROR(SUMPRODUCT((Matriz_Esp<>"")*D66:W66)/SUMPRODUCT(--(Matriz_Esp<>"")),"")) | Y66: =IF($B66="","",SUMPRODUCT((Matriz_Esp<>"")*(D66:W66>=2)))
A67: =IF('Equipe'!A67="","",'Equipe'!A67) | B67: =IF('Equipe'!B67="","",'Equipe'!B67) | C67: =IF('Equipe'!C67="","",'Equipe'!C67) | X67: =IF($B67="","",IFERROR(SUMPRODUCT((Matriz_Esp<>"")*D67:W67)/SUMPRODUCT(--(Matriz_Esp<>"")),"")) | Y67: =IF($B67="","",SUMPRODUCT((Matriz_Esp<>"")*(D67:W67>=2)))
A68: =IF('Equipe'!A68="","",'Equipe'!A68) | B68: =IF('Equipe'!B68="","",'Equipe'!B68) | C68: =IF('Equipe'!C68="","",'Equipe'!C68) | X68: =IF($B68="","",IFERROR(SUMPRODUCT((Matriz_Esp<>"")*D68:W68)/SUMPRODUCT(--(Matriz_Esp<>"")),"")) | Y68: =IF($B68="","",SUMPRODUCT((Matriz_Esp<>"")*(D68:W68>=2)))
A69: =IF('Equipe'!A69="","",'Equipe'!A69) | B69: =IF('Equipe'!B69="","",'Equipe'!B69) | C69: =IF('Equipe'!C69="","",'Equipe'!C69) | X69: =IF($B69="","",IFERROR(SUMPRODUCT((Matriz_Esp<>"")*D69:W69)/SUMPRODUCT(--(Matriz_Esp<>"")),"")) | Y69: =IF($B69="","",SUMPRODUCT((Matriz_Esp<>"")*(D69:W69>=2)))
A70: =IF('Equipe'!A70="","",'Equipe'!A70) | B70: =IF('Equipe'!B70="","",'Equipe'!B70) | C70: =IF('Equipe'!C70="","",'Equipe'!C70) | X70: =IF($B70="","",IFERROR(SUMPRODUCT((Matriz_Esp<>"")*D70:W70)/SUMPRODUCT(--(Matriz_Esp<>"")),"")) | Y70: =IF($B70="","",SUMPRODUCT((Matriz_Esp<>"")*(D70:W70>=2)))
A71: =IF('Equipe'!A71="","",'Equipe'!A71) | B71: =IF('Equipe'!B71="","",'Equipe'!B71) | C71: =IF('Equipe'!C71="","",'Equipe'!C71) | X71: =IF($B71="","",IFERROR(SUMPRODUCT((Matriz_Esp<>"")*D71:W71)/SUMPRODUCT(--(Matriz_Esp<>"")),"")) | Y71: =IF($B71="","",SUMPRODUCT((Matriz_Esp<>"")*(D71:W71>=2)))
A72: =IF('Equipe'!A72="","",'Equipe'!A72) | B72: =IF('Equipe'!B72="","",'Equipe'!B72) | C72: =IF('Equipe'!C72="","",'Equipe'!C72) | X72: =IF($B72="","",IFERROR(SUMPRODUCT((Matriz_Esp<>"")*D72:W72)/SUMPRODUCT(--(Matriz_Esp<>"")),"")) | Y72: =IF($B72="","",SUMPRODUCT((Matriz_Esp<>"")*(D72:W72>=2)))
A73: =IF('Equipe'!A73="","",'Equipe'!A73) | B73: =IF('Equipe'!B73="","",'Equipe'!B73) | C73: =IF('Equipe'!C73="","",'Equipe'!C73) | X73: =IF($B73="","",IFERROR(SUMPRODUCT((Matriz_Esp<>"")*D73:W73)/SUMPRODUCT(--(Matriz_Esp<>"")),"")) | Y73: =IF($B73="","",SUMPRODUCT((Matriz_Esp<>"")*(D73:W73>=2)))
... A151: =IF('Equipe'!A151="","",'Equipe'!A151) | B151: =IF('Equipe'!B151="","",'Equipe'!B151) | C151: =IF('Equipe'!C151="","",'Equipe'!C151) | X151: =IF($B151="","",IFERROR(SUMPRODUCT((Matriz_Esp<>"")*D151:W151)/SUMPRODUCT(--(Matriz_Esp<>"")),"")) | Y151: =IF($B151="","",SUMPRODUCT((Matriz_Esp<>"")*(D151:W151>=2)))

Sheet Mapa_Cirurgico
A1: Data | B1: Sala | C1: Turno | D1: Hora início | E1: Hora fim | F1: Especialidade | G1: Procedimento | H1: Cirurgião | I1: Porte | J1: Status | K1: Duração (min) | L1: Min. ocupação (dur+setup) | M1: Alerta | N1: aux_concat | O1: aux_ini | P1: aux_fim
A2: 46254 | B2: SO-01 | C2: Manhã | D2: 0.29166667 | E2: 0.39236111 | F2: Ortopedia | G2: Artroplastia total de joelho | H2: Dr. Almeida | I2: M | J2: Agendada | K2: =IF(OR($B2="",NOT(ISNUMBER($D2)),NOT(ISNUMBER($E2))),"",ROUND(MOD($E2-$D2,1)*1440,0)) | L2: =IF(NOT(ISNUMBER($K2)),0,IF(OR($K2<=0,$J2="Cancelada",$J2="Suspensa"),0,$K2+Setup_Min)) | M2: =IF($B2="","",IF($N2="","OK",LEFT($N2,LEN($N2)-3))) | N2: =IF($B2="","",IF(COUNTIF(Salas_Cod,$B2)=0,"Sala não cadastrada | ","")&IF(AND(COUNTIF(Salas_Cod,$B2)>0,IFERROR(INDEX(Salas_Status,MATCH($B2,Salas_Cod,0)),"")<>"Ativa"),"Sala bloqueada | ","")&IF(COUNTIF(Turnos_Nome,$C2)=0,"Turno inválido | ","")&IF(COUNTIF(Esp_Nome,$F2)=0,"Especialidade não cadastrada | ","")&IF(COUNTIF(Lista_StatusCirurgia,$J2)=0,"Status inválido | ","")&IF(OR(NOT(ISNUMBER($D2)),NOT(ISNUMBER($E2))),"Horário inválido | ","")&IFERROR(IF(AND(ISNUMBER($D2),ISNUMBER($E2),MOD($E2-$D2,1)*1440<=0),"Duração nula ou negativa | ",""),"")&IFERROR(IF(AND(ISNUMBER($D2),COUNTIF(Turnos_Nome,$C2)>0,MOD($D2-INDEX(Turnos_Ini,MATCH($C2,Turnos_Nome,0)),1)*1440>=INDEX(Turnos_Min,MATCH($C2,Turnos_Nome,0))),"Início fora da janela do turno | ",""),"")&IFERROR(IF(AND($L2>0,SUMPRODUCT((Mapa_Sala=$B2)*(Mapa_Data=$A2)*(Mapa_MinOcup>0)*(((MOD(Mapa_IniNum-$O2,1)<MOD($P2-$O2,1))+(MOD($O2-Mapa_IniNum,1)<MOD(Mapa_FimNum-Mapa_IniNum,1)))>0))>1),"Sobreposição de horário na sala | ",""),"")&IFERROR(IF(AND(ISNUMBER($K2),$K2>0,COUNTIF(Esp_Nome,$F2)>0,$K2>3*INDEX(Esp_Dur,MATCH($F2,Esp_Nome,0))),"Duração atípica (>3x a média) | ",""),"")) | O2: =IF(ISNUMBER($D2),$D2,0) | P2: =IF(ISNUMBER($E2),$E2,0)
A3: 46254 | B3: SO-01 | C3: Manhã | D3: 0.41319444 | E3: 0.49305556 | F3: Ortopedia | G3: Osteossíntese de fêmur | H3: Dra. Bernardes | I3: M | J3: Agendada | K3: =IF(OR($B3="",NOT(ISNUMBER($D3)),NOT(ISNUMBER($E3))),"",ROUND(MOD($E3-$D3,1)*1440,0)) | L3: =IF(NOT(ISNUMBER($K3)),0,IF(OR($K3<=0,$J3="Cancelada",$J3="Suspensa"),0,$K3+Setup_Min)) | M3: =IF($B3="","",IF($N3="","OK",LEFT($N3,LEN($N3)-3))) | N3: =IF($B3="","",IF(COUNTIF(Salas_Cod,$B3)=0,"Sala não cadastrada | ","")&IF(AND(COUNTIF(Salas_Cod,$B3)>0,IFERROR(INDEX(Salas_Status,MATCH($B3,Salas_Cod,0)),"")<>"Ativa"),"Sala bloqueada | ","")&IF(COUNTIF(Turnos_Nome,$C3)=0,"Turno inválido | ","")&IF(COUNTIF(Esp_Nome,$F3)=0,"Especialidade não cadastrada | ","")&IF(COUNTIF(Lista_StatusCirurgia,$J3)=0,"Status inválido | ","")&IF(OR(NOT(ISNUMBER($D3)),NOT(ISNUMBER($E3))),"Horário inválido | ","")&IFERROR(IF(AND(ISNUMBER($D3),ISNUMBER($E3),MOD($E3-$D3,1)*1440<=0),"Duração nula ou negativa | ",""),"")&IFERROR(IF(AND(ISNUMBER($D3),COUNTIF(Turnos_Nome,$C3)>0,MOD($D3-INDEX(Turnos_Ini,MATCH($C3,Turnos_Nome,0)),1)*1440>=INDEX(Turnos_Min,MATCH($C3,Turnos_Nome,0))),"Início fora da janela do turno | ",""),"")&IFERROR(IF(AND($L3>0,SUMPRODUCT((Mapa_Sala=$B3)*(Mapa_Data=$A3)*(Mapa_MinOcup>0)*(((MOD(Mapa_IniNum-$O3,1)<MOD($P3-$O3,1))+(MOD($O3-Mapa_IniNum,1)<MOD(Mapa_FimNum-Mapa_IniNum,1)))>0))>1),"Sobreposição de horário na sala | ",""),"")&IFERROR(IF(AND(ISNUMBER($K3),$K3>0,COUNTIF(Esp_Nome,$F3)>0,$K3>3*INDEX(Esp_Dur,MATCH($F3,Esp_Nome,0))),"Duração atípica (>3x a média) | ",""),"")) | O3: =IF(ISNUMBER($D3),$D3,0) | P3: =IF(ISNUMBER($E3),$E3,0)
A4: 46254 | B4: SO-01 | C4: Tarde | D4: 0.54166667 | E4: 0.63194444 | F4: Ortopedia | G4: Artroplastia total de joelho | H4: Dr. Almeida | I4: M | J4: Agendada | K4: =IF(OR($B4="",NOT(ISNUMBER($D4)),NOT(ISNUMBER($E4))),"",ROUND(MOD($E4-$D4,1)*1440,0)) | L4: =IF(NOT(ISNUMBER($K4)),0,IF(OR($K4<=0,$J4="Cancelada",$J4="Suspensa"),0,$K4+Setup_Min)) | M4: =IF($B4="","",IF($N4="","OK",LEFT($N4,LEN($N4)-3))) | N4: =IF($B4="","",IF(COUNTIF(Salas_Cod,$B4)=0,"Sala não cadastrada | ","")&IF(AND(COUNTIF(Salas_Cod,$B4)>0,IFERROR(INDEX(Salas_Status,MATCH($B4,Salas_Cod,0)),"")<>"Ativa"),"Sala bloqueada | ","")&IF(COUNTIF(Turnos_Nome,$C4)=0,"Turno inválido | ","")&IF(COUNTIF(Esp_Nome,$F4)=0,"Especialidade não cadastrada | ","")&IF(COUNTIF(Lista_StatusCirurgia,$J4)=0,"Status inválido | ","")&IF(OR(NOT(ISNUMBER($D4)),NOT(ISNUMBER($E4))),"Horário inválido | ","")&IFERROR(IF(AND(ISNUMBER($D4),ISNUMBER($E4),MOD($E4-$D4,1)*1440<=0),"Duração nula ou negativa | ",""),"")&IFERROR(IF(AND(ISNUMBER($D4),COUNTIF(Turnos_Nome,$C4)>0,MOD($D4-INDEX(Turnos_Ini,MATCH($C4,Turnos_Nome,0)),1)*1440>=INDEX(Turnos_Min,MATCH($C4,Turnos_Nome,0))),"Início fora da janela do turno | ",""),"")&IFERROR(IF(AND($L4>0,SUMPRODUCT((Mapa_Sala=$B4)*(Mapa_Data=$A4)*(Mapa_MinOcup>0)*(((MOD(Mapa_IniNum-$O4,1)<MOD($P4-$O4,1))+(MOD($O4-Mapa_IniNum,1)<MOD(Mapa_FimNum-Mapa_IniNum,1)))>0))>1),"Sobreposição de horário na sala | ",""),"")&IFERROR(IF(AND(ISNUMBER($K4),$K4>0,COUNTIF(Esp_Nome,$F4)>0,$K4>3*INDEX(Esp_Dur,MATCH($F4,Esp_Nome,0))),"Duração atípica (>3x a média) | ",""),"")) | O4: =IF(ISNUMBER($D4),$D4,0) | P4: =IF(ISNUMBER($E4),$E4,0)
A5: 46254 | B5: SO-01 | C5: Tarde | D5: 0.65277778 | E5: 0.75347222 | F5: Ortopedia | G5: Osteossíntese de fêmur | H5: Dra. Bernardes | I5: M | J5: Agendada | K5: =IF(OR($B5="",NOT(ISNUMBER($D5)),NOT(ISNUMBER($E5))),"",ROUND(MOD($E5-$D5,1)*1440,0)) | L5: =IF(NOT(ISNUMBER($K5)),0,IF(OR($K5<=0,$J5="Cancelada",$J5="Suspensa"),0,$K5+Setup_Min)) | M5: =IF($B5="","",IF($N5="","OK",LEFT($N5,LEN($N5)-3))) | N5: =IF($B5="","",IF(COUNTIF(Salas_Cod,$B5)=0,"Sala não cadastrada | ","")&IF(AND(COUNTIF(Salas_Cod,$B5)>0,IFERROR(INDEX(Salas_Status,MATCH($B5,Salas_Cod,0)),"")<>"Ativa"),"Sala bloqueada | ","")&IF(COUNTIF(Turnos_Nome,$C5)=0,"Turno inválido | ","")&IF(COUNTIF(Esp_Nome,$F5)=0,"Especialidade não cadastrada | ","")&IF(COUNTIF(Lista_StatusCirurgia,$J5)=0,"Status inválido | ","")&IF(OR(NOT(ISNUMBER($D5)),NOT(ISNUMBER($E5))),"Horário inválido | ","")&IFERROR(IF(AND(ISNUMBER($D5),ISNUMBER($E5),MOD($E5-$D5,1)*1440<=0),"Duração nula ou negativa | ",""),"")&IFERROR(IF(AND(ISNUMBER($D5),COUNTIF(Turnos_Nome,$C5)>0,MOD($D5-INDEX(Turnos_Ini,MATCH($C5,Turnos_Nome,0)),1)*1440>=INDEX(Turnos_Min,MATCH($C5,Turnos_Nome,0))),"Início fora da janela do turno | ",""),"")&IFERROR(IF(AND($L5>0,SUMPRODUCT((Mapa_Sala=$B5)*(Mapa_Data=$A5)*(Mapa_MinOcup>0)*(((MOD(Mapa_IniNum-$O5,1)<MOD($P5-$O5,1))+(MOD($O5-Mapa_IniNum,1)<MOD(Mapa_FimNum-Mapa_IniNum,1)))>0))>1),"Sobreposição de horário na sala | ",""),"")&IFERROR(IF(AND(ISNUMBER($K5),$K5>0,COUNTIF(Esp_Nome,$F5)>0,$K5>3*INDEX(Esp_Dur,MATCH($F5,Esp_Nome,0))),"Duração atípica (>3x a média) | ",""),"")) | O5: =IF(ISNUMBER($D5),$D5,0) | P5: =IF(ISNUMBER($E5),$E5,0)
A6: 46254 | B6: SO-01 | C6: Noite | D6: 0.79166667 | E6: 0.86805556 | F6: Ortopedia | G6: Artroplastia total de joelho | H6: Dr. Almeida | I6: M | J6: Agendada | K6: =IF(OR($B6="",NOT(ISNUMBER($D6)),NOT(ISNUMBER($E6))),"",ROUND(MOD($E6-$D6,1)*1440,0)) | L6: =IF(NOT(ISNUMBER($K6)),0,IF(OR($K6<=0,$J6="Cancelada",$J6="Suspensa"),0,$K6+Setup_Min)) | M6: =IF($B6="","",IF($N6="","OK",LEFT($N6,LEN($N6)-3))) | N6: =IF($B6="","",IF(COUNTIF(Salas_Cod,$B6)=0,"Sala não cadastrada | ","")&IF(AND(COUNTIF(Salas_Cod,$B6)>0,IFERROR(INDEX(Salas_Status,MATCH($B6,Salas_Cod,0)),"")<>"Ativa"),"Sala bloqueada | ","")&IF(COUNTIF(Turnos_Nome,$C6)=0,"Turno inválido | ","")&IF(COUNTIF(Esp_Nome,$F6)=0,"Especialidade não cadastrada | ","")&IF(COUNTIF(Lista_StatusCirurgia,$J6)=0,"Status inválido | ","")&IF(OR(NOT(ISNUMBER($D6)),NOT(ISNUMBER($E6))),"Horário inválido | ","")&IFERROR(IF(AND(ISNUMBER($D6),ISNUMBER($E6),MOD($E6-$D6,1)*1440<=0),"Duração nula ou negativa | ",""),"")&IFERROR(IF(AND(ISNUMBER($D6),COUNTIF(Turnos_Nome,$C6)>0,MOD($D6-INDEX(Turnos_Ini,MATCH($C6,Turnos_Nome,0)),1)*1440>=INDEX(Turnos_Min,MATCH($C6,Turnos_Nome,0))),"Início fora da janela do turno | ",""),"")&IFERROR(IF(AND($L6>0,SUMPRODUCT((Mapa_Sala=$B6)*(Mapa_Data=$A6)*(Mapa_MinOcup>0)*(((MOD(Mapa_IniNum-$O6,1)<MOD($P6-$O6,1))+(MOD($O6-Mapa_IniNum,1)<MOD(Mapa_FimNum-Mapa_IniNum,1)))>0))>1),"Sobreposição de horário na sala | ",""),"")&IFERROR(IF(AND(ISNUMBER($K6),$K6>0,COUNTIF(Esp_Nome,$F6)>0,$K6>3*INDEX(Esp_Dur,MATCH($F6,Esp_Nome,0))),"Duração atípica (>3x a média) | ",""),"")) | O6: =IF(ISNUMBER($D6),$D6,0) | P6: =IF(ISNUMBER($E6),$E6,0)
A7: 46254 | B7: SO-01 | C7: Noite | D7: 0.88888889 | E7: 0.96180556 | F7: Ortopedia | G7: Osteossíntese de fêmur | H7: Dra. Bernardes | I7: M | J7: Agendada | K7: =IF(OR($B7="",NOT(ISNUMBER($D7)),NOT(ISNUMBER($E7))),"",ROUND(MOD($E7-$D7,1)*1440,0)) | L7: =IF(NOT(ISNUMBER($K7)),0,IF(OR($K7<=0,$J7="Cancelada",$J7="Suspensa"),0,$K7+Setup_Min)) | M7: =IF($B7="","",IF($N7="","OK",LEFT($N7,LEN($N7)-3))) | N7: =IF($B7="","",IF(COUNTIF(Salas_Cod,$B7)=0,"Sala não cadastrada | ","")&IF(AND(COUNTIF(Salas_Cod,$B7)>0,IFERROR(INDEX(Salas_Status,MATCH($B7,Salas_Cod,0)),"")<>"Ativa"),"Sala bloqueada | ","")&IF(COUNTIF(Turnos_Nome,$C7)=0,"Turno inválido | ","")&IF(COUNTIF(Esp_Nome,$F7)=0,"Especialidade não cadastrada | ","")&IF(COUNTIF(Lista_StatusCirurgia,$J7)=0,"Status inválido | ","")&IF(OR(NOT(ISNUMBER($D7)),NOT(ISNUMBER($E7))),"Horário inválido | ","")&IFERROR(IF(AND(ISNUMBER($D7),ISNUMBER($E7),MOD($E7-$D7,1)*1440<=0),"Duração nula ou negativa | ",""),"")&IFERROR(IF(AND(ISNUMBER($D7),COUNTIF(Turnos_Nome,$C7)>0,MOD($D7-INDEX(Turnos_Ini,MATCH($C7,Turnos_Nome,0)),1)*1440>=INDEX(Turnos_Min,MATCH($C7,Turnos_Nome,0))),"Início fora da janela do turno | ",""),"")&IFERROR(IF(AND($L7>0,SUMPRODUCT((Mapa_Sala=$B7)*(Mapa_Data=$A7)*(Mapa_MinOcup>0)*(((MOD(Mapa_IniNum-$O7,1)<MOD($P7-$O7,1))+(MOD($O7-Mapa_IniNum,1)<MOD(Mapa_FimNum-Mapa_IniNum,1)))>0))>1),"Sobreposição de horário na sala | ",""),"")&IFERROR(IF(AND(ISNUMBER($K7),$K7>0,COUNTIF(Esp_Nome,$F7)>0,$K7>3*INDEX(Esp_Dur,MATCH($F7,Esp_Nome,0))),"Duração atípica (>3x a média) | ",""),"")) | O7: =IF(ISNUMBER($D7),$D7,0) | P7: =IF(ISNUMBER($E7),$E7,0)
A8: 46254 | B8: SO-01 | C8: Noite | D8: 0.98263889 | E8: 0.059027778 | F8: Ortopedia | G8: Artroscopia de ombro | H8: Dr. Coelho | I8: M | J8: Agendada | K8: =IF(OR($B8="",NOT(ISNUMBER($D8)),NOT(ISNUMBER($E8))),"",ROUND(MOD($E8-$D8,1)*1440,0)) | L8: =IF(NOT(ISNUMBER($K8)),0,IF(OR($K8<=0,$J8="Cancelada",$J8="Suspensa"),0,$K8+Setup_Min)) | M8: =IF($B8="","",IF($N8="","OK",LEFT($N8,LEN($N8)-3))) | N8: =IF($B8="","",IF(COUNTIF(Salas_Cod,$B8)=0,"Sala não cadastrada | ","")&IF(AND(COUNTIF(Salas_Cod,$B8)>0,IFERROR(INDEX(Salas_Status,MATCH($B8,Salas_Cod,0)),"")<>"Ativa"),"Sala bloqueada | ","")&IF(COUNTIF(Turnos_Nome,$C8)=0,"Turno inválido | ","")&IF(COUNTIF(Esp_Nome,$F8)=0,"Especialidade não cadastrada | ","")&IF(COUNTIF(Lista_StatusCirurgia,$J8)=0,"Status inválido | ","")&IF(OR(NOT(ISNUMBER($D8)),NOT(ISNUMBER($E8))),"Horário inválido | ","")&IFERROR(IF(AND(ISNUMBER($D8),ISNUMBER($E8),MOD($E8-$D8,1)*1440<=0),"Duração nula ou negativa | ",""),"")&IFERROR(IF(AND(ISNUMBER($D8),COUNTIF(Turnos_Nome,$C8)>0,MOD($D8-INDEX(Turnos_Ini,MATCH($C8,Turnos_Nome,0)),1)*1440>=INDEX(Turnos_Min,MATCH($C8,Turnos_Nome,0))),"Início fora da janela do turno | ",""),"")&IFERROR(IF(AND($L8>0,SUMPRODUCT((Mapa_Sala=$B8)*(Mapa_Data=$A8)*(Mapa_MinOcup>0)*(((MOD(Mapa_IniNum-$O8,1)<MOD($P8-$O8,1))+(MOD($O8-Mapa_IniNum,1)<MOD(Mapa_FimNum-Mapa_IniNum,1)))>0))>1),"Sobreposição de horário na sala | ",""),"")&IFERROR(IF(AND(ISNUMBER($K8),$K8>0,COUNTIF(Esp_Nome,$F8)>0,$K8>3*INDEX(Esp_Dur,MATCH($F8,Esp_Nome,0))),"Duração atípica (>3x a média) | ",""),"")) | O8: =IF(ISNUMBER($D8),$D8,0) | P8: =IF(ISNUMBER($E8),$E8,0)
A9: 46254 | B9: SO-01 | C9: Noite | D9: 0.079861111 | E9: 0.17361111 | F9: Ortopedia | G9: Artroplastia total de joelho | H9: Dra. Delgado | I9: M | J9: Agendada | K9: =IF(OR($B9="",NOT(ISNUMBER($D9)),NOT(ISNUMBER($E9))),"",ROUND(MOD($E9-$D9,1)*1440,0)) | L9: =IF(NOT(ISNUMBER($K9)),0,IF(OR($K9<=0,$J9="Cancelada",$J9="Suspensa"),0,$K9+Setup_Min)) | M9: =IF($B9="","",IF($N9="","OK",LEFT($N9,LEN($N9)-3))) | N9: =IF($B9="","",IF(COUNTIF(Salas_Cod,$B9)=0,"Sala não cadastrada | ","")&IF(AND(COUNTIF(Salas_Cod,$B9)>0,IFERROR(INDEX(Salas_Status,MATCH($B9,Salas_Cod,0)),"")<>"Ativa"),"Sala bloqueada | ","")&IF(COUNTIF(Turnos_Nome,$C9)=0,"Turno inválido | ","")&IF(COUNTIF(Esp_Nome,$F9)=0,"Especialidade não cadastrada | ","")&IF(COUNTIF(Lista_StatusCirurgia,$J9)=0,"Status inválido | ","")&IF(OR(NOT(ISNUMBER($D9)),NOT(ISNUMBER($E9))),"Horário inválido | ","")&IFERROR(IF(AND(ISNUMBER($D9),ISNUMBER($E9),MOD($E9-$D9,1)*1440<=0),"Duração nula ou negativa | ",""),"")&IFERROR(IF(AND(ISNUMBER($D9),COUNTIF(Turnos_Nome,$C9)>0,MOD($D9-INDEX(Turnos_Ini,MATCH($C9,Turnos_Nome,0)),1)*1440>=INDEX(Turnos_Min,MATCH($C9,Turnos_Nome,0))),"Início fora da janela do turno | ",""),"")&IFERROR(IF(AND($L9>0,SUMPRODUCT((Mapa_Sala=$B9)*(Mapa_Data=$A9)*(Mapa_MinOcup>0)*(((MOD(Mapa_IniNum-$O9,1)<MOD($P9-$O9,1))+(MOD($O9-Mapa_IniNum,1)<MOD(Mapa_FimNum-Mapa_IniNum,1)))>0))>1),"Sobreposição de horário na sala | ",""),"")&IFERROR(IF(AND(ISNUMBER($K9),$K9>0,COUNTIF(Esp_Nome,$F9)>0,$K9>3*INDEX(Esp_Dur,MATCH($F9,Esp_Nome,0))),"Duração atípica (>3x a média) | ",""),"")) | O9: =IF(ISNUMBER($D9),$D9,0) | P9: =IF(ISNUMBER($E9),$E9,0)
A10: 46254 | B10: SO-01 | C10: Noite | D10: 0.19444444 | E10: 0.26388889 | F10: Ortopedia | G10: Osteossíntese de fêmur | H10: Dr. Esteves | I10: M | J10: Agendada | K10: =IF(OR($B10="",NOT(ISNUMBER($D10)),NOT(ISNUMBER($E10))),"",ROUND(MOD($E10-$D10,1)*1440,0)) | L10: =IF(NOT(ISNUMBER($K10)),0,IF(OR($K10<=0,$J10="Cancelada",$J10="Suspensa"),0,$K10+Setup_Min)) | M10: =IF($B10="","",IF($N10="","OK",LEFT($N10,LEN($N10)-3))) | N10: =IF($B10="","",IF(COUNTIF(Salas_Cod,$B10)=0,"Sala não cadastrada | ","")&IF(AND(COUNTIF(Salas_Cod,$B10)>0,IFERROR(INDEX(Salas_Status,MATCH($B10,Salas_Cod,0)),"")<>"Ativa"),"Sala bloqueada | ","")&IF(COUNTIF(Turnos_Nome,$C10)=0,"Turno inválido | ","")&IF(COUNTIF(Esp_Nome,$F10)=0,"Especialidade não cadastrada | ","")&IF(COUNTIF(Lista_StatusCirurgia,$J10)=0,"Status inválido | ","")&IF(OR(NOT(ISNUMBER($D10)),NOT(ISNUMBER($E10))),"Horário inválido | ","")&IFERROR(IF(AND(ISNUMBER($D10),ISNUMBER($E10),MOD($E10-$D10,1)*1440<=0),"Duração nula ou negativa | ",""),"")&IFERROR(IF(AND(ISNUMBER($D10),COUNTIF(Turnos_Nome,$C10)>0,MOD($D10-INDEX(Turnos_Ini,MATCH($C10,Turnos_Nome,0)),1)*1440>=INDEX(Turnos_Min,MATCH($C10,Turnos_Nome,0))),"Início fora da janela do turno | ",""),"")&IFERROR(IF(AND($L10>0,SUMPRODUCT((Mapa_Sala=$B10)*(Mapa_Data=$A10)*(Mapa_MinOcup>0)*(((MOD(Mapa_IniNum-$O10,1)<MOD($P10-$O10,1))+(MOD($O10-Mapa_IniNum,1)<MOD(Mapa_FimNum-Mapa_IniNum,1)))>0))>1),"Sobreposição de horário na sala | ",""),"")&IFERROR(IF(AND(ISNUMBER($K10),$K10>0,COUNTIF(Esp_Nome,$F10)>0,$K10>3*INDEX(Esp_Dur,MATCH($F10,Esp_Nome,0))),"Duração atípica (>3x a média) | ",""),"")) | O10: =IF(ISNUMBER($D10),$D10,0) | P10: =IF(ISNUMBER($E10),$E10,0)
A11: 46254 | B11: SO-02 | C11: Manhã | D11: 0.29166667 | E11: 0.34722222 | F11: Cirurgia Geral | G11: Colecistectomia videolaparoscópica | H11: Dra. Delgado | I11: P | J11: Agendada | K11: =IF(OR($B11="",NOT(ISNUMBER($D11)),NOT(ISNUMBER($E11))),"",ROUND(MOD($E11-$D11,1)*1440,0)) | L11: =IF(NOT(ISNUMBER($K11)),0,IF(OR($K11<=0,$J11="Cancelada",$J11="Suspensa"),0,$K11+Setup_Min)) | M11: =IF($B11="","",IF($N11="","OK",LEFT($N11,LEN($N11)-3))) | N11: =IF($B11="","",IF(COUNTIF(Salas_Cod,$B11)=0,"Sala não cadastrada | ","")&IF(AND(COUNTIF(Salas_Cod,$B11)>0,IFERROR(INDEX(Salas_Status,MATCH($B11,Salas_Cod,0)),"")<>"Ativa"),"Sala bloqueada | ","")&IF(COUNTIF(Turnos_Nome,$C11)=0,"Turno inválido | ","")&IF(COUNTIF(Esp_Nome,$F11)=0,"Especialidade não cadastrada | ","")&IF(COUNTIF(Lista_StatusCirurgia,$J11)=0,"Status inválido | ","")&IF(OR(NOT(ISNUMBER($D11)),NOT(ISNUMBER($E11))),"Horário inválido | ","")&IFERROR(IF(AND(ISNUMBER($D11),ISNUMBER($E11),MOD($E11-$D11,1)*1440<=0),"Duração nula ou negativa | ",""),"")&IFERROR(IF(AND(ISNUMBER($D11),COUNTIF(Turnos_Nome,$C11)>0,MOD($D11-INDEX(Turnos_Ini,MATCH($C11,Turnos_Nome,0)),1)*1440>=INDEX(Turnos_Min,MATCH($C11,Turnos_Nome,0))),"Início fora da janela do turno | ",""),"")&IFERROR(IF(AND($L11>0,SUMPRODUCT((Mapa_Sala=$B11)*(Mapa_Data=$A11)*(Mapa_MinOcup>0)*(((MOD(Mapa_IniNum-$O11,1)<MOD($P11-$O11,1))+(MOD($O11-Mapa_IniNum,1)<MOD(Mapa_FimNum-Mapa_IniNum,1)))>0))>1),"Sobreposição de horário na sala | ",""),"")&IFERROR(IF(AND(ISNUMBER($K11),$K11>0,COUNTIF(Esp_Nome,$F11)>0,$K11>3*INDEX(Esp_Dur,MATCH($F11,Esp_Nome,0))),"Duração atípica (>3x a média) | ",""),"")) | O11: =IF(ISNUMBER($D11),$D11,0) | P11: =IF(ISNUMBER($E11),$E11,0)
A12: 46254 | B12: SO-02 | C12: Manhã | D12: 0.36805556 | E12: 0.46875 | F12: Cirurgia Bariátrica | G12: Gastrectomia vertical | H12: Dr. Esteves | I12: M | J12: Agendada | K12: =IF(OR($B12="",NOT(ISNUMBER($D12)),NOT(ISNUMBER($E12))),"",ROUND(MOD($E12-$D12,1)*1440,0)) | L12: =IF(NOT(ISNUMBER($K12)),0,IF(OR($K12<=0,$J12="Cancelada",$J12="Suspensa"),0,$K12+Setup_Min)) | M12: =IF($B12="","",IF($N12="","OK",LEFT($N12,LEN($N12)-3))) | N12: =IF($B12="","",IF(COUNTIF(Salas_Cod,$B12)=0,"Sala não cadastrada | ","")&IF(AND(COUNTIF(Salas_Cod,$B12)>0,IFERROR(INDEX(Salas_Status,MATCH($B12,Salas_Cod,0)),"")<>"Ativa"),"Sala bloqueada | ","")&IF(COUNTIF(Turnos_Nome,$C12)=0,"Turno inválido | ","")&IF(COUNTIF(Esp_Nome,$F12)=0,"Especialidade não cadastrada | ","")&IF(COUNTIF(Lista_StatusCirurgia,$J12)=0,"Status inválido | ","")&IF(OR(NOT(ISNUMBER($D12)),NOT(ISNUMBER($E12))),"Horário inválido | ","")&IFERROR(IF(AND(ISNUMBER($D12),ISNUMBER($E12),MOD($E12-$D12,1)*1440<=0),"Duração nula ou negativa | ",""),"")&IFERROR(IF(AND(ISNUMBER($D12),COUNTIF(Turnos_Nome,$C12)>0,MOD($D12-INDEX(Turnos_Ini,MATCH($C12,Turnos_Nome,0)),1)*1440>=INDEX(Turnos_Min,MATCH($C12,Turnos_Nome,0))),"Início fora da janela do turno | ",""),"")&IFERROR(IF(AND($L12>0,SUMPRODUCT((Mapa_Sala=$B12)*(Mapa_Data=$A12)*(Mapa_MinOcup>0)*(((MOD(Mapa_IniNum-$O12,1)<MOD($P12-$O12,1))+(MOD($O12-Mapa_IniNum,1)<MOD(Mapa_FimNum-Mapa_IniNum,1)))>0))>1),"Sobreposição de horário na sala | ",""),"")&IFERROR(IF(AND(ISNUMBER($K12),$K12>0,COUNTIF(Esp_Nome,$F12)>0,$K12>3*INDEX(Esp_Dur,MATCH($F12,Esp_Nome,0))),"Duração atípica (>3x a média) | ",""),"")) | O12: =IF(ISNUMBER($D12),$D12,0) | P12: =IF(ISNUMBER($E12),$E12,0)
A13: 46254 | B13: SO-02 | C13: Tarde | D13: 0.54166667 | E13: 0.59375 | F13: Cirurgia Geral | G13: Colecistectomia videolaparoscópica | H13: Dra. Delgado | I13: P | J13: Agendada | K13: =IF(OR($B13="",NOT(ISNUMBER($D13)),NOT(ISNUMBER($E13))),"",ROUND(MOD($E13-$D13,1)*1440,0)) | L13: =IF(NOT(ISNUMBER($K13)),0,IF(OR($K13<=0,$J13="Cancelada",$J13="Suspensa"),0,$K13+Setup_Min)) | M13: =IF($B13="","",IF($N13="","OK",LEFT($N13,LEN($N13)-3))) | N13: =IF($B13="","",IF(COUNTIF(Salas_Cod,$B13)=0,"Sala não cadastrada | ","")&IF(AND(COUNTIF(Salas_Cod,$B13)>0,IFERROR(INDEX(Salas_Status,MATCH($B13,Salas_Cod,0)),"")<>"Ativa"),"Sala bloqueada | ","")&IF(COUNTIF(Turnos_Nome,$C13)=0,"Turno inválido | ","")&IF(COUNTIF(Esp_Nome,$F13)=0,"Especialidade não cadastrada | ","")&IF(COUNTIF(Lista_StatusCirurgia,$J13)=0,"Status inválido | ","")&IF(OR(NOT(ISNUMBER($D13)),NOT(ISNUMBER($E13))),"Horário inválido | ","")&IFERROR(IF(AND(ISNUMBER($D13),ISNUMBER($E13),MOD($E13-$D13,1)*1440<=0),"Duração nula ou negativa | ",""),"")&IFERROR(IF(AND(ISNUMBER($D13),COUNTIF(Turnos_Nome,$C13)>0,MOD($D13-INDEX(Turnos_Ini,MATCH($C13,Turnos_Nome,0)),1)*1440>=INDEX(Turnos_Min,MATCH($C13,Turnos_Nome,0))),"Início fora da janela do turno | ",""),"")&IFERROR(IF(AND($L13>0,SUMPRODUCT((Mapa_Sala=$B13)*(Mapa_Data=$A13)*(Mapa_MinOcup>0)*(((MOD(Mapa_IniNum-$O13,1)<MOD($P13-$O13,1))+(MOD($O13-Mapa_IniNum,1)<MOD(Mapa_FimNum-Mapa_IniNum,1)))>0))>1),"Sobreposição de horário na sala | ",""),"")&IFERROR(IF(AND(ISNUMBER($K13),$K13>0,COUNTIF(Esp_Nome,$F13)>0,$K13>3*INDEX(Esp_Dur,MATCH($F13,Esp_Nome,0))),"Duração atípica (>3x a média) | ",""),"")) | O13: =IF(ISNUMBER($D13),$D13,0) | P13: =IF(ISNUMBER($E13),$E13,0)
... A69: 46254 | B69: SO-08 | C69: Noite | D69: 0.076388889 | E69: 0.14583333 | F69: Cirurgia Pediátrica | G69: Postectomia | H69: Dra. Fialho | I69: M | J69: Agendada | K69: =IF(OR($B69="",NOT(ISNUMBER($D69)),NOT(ISNUMBER($E69))),"",ROUND(MOD($E69-$D69,1)*1440,0)) | L69: =IF(NOT(ISNUMBER($K69)),0,IF(OR($K69<=0,$J69="Cancelada",$J69="Suspensa"),0,$K69+Setup_Min)) | M69: =IF($B69="","",IF($N69="","OK",LEFT($N69,LEN($N69)-3))) | N69: =IF($B69="","",IF(COUNTIF(Salas_Cod,$B69)=0,"Sala não cadastrada | ","")&IF(AND(COUNTIF(Salas_Cod,$B69)>0,IFERROR(INDEX(Salas_Status,MATCH($B69,Salas_Cod,0)),"")<>"Ativa"),"Sala bloqueada | ","")&IF(COUNTIF(Turnos_Nome,$C69)=0,"Turno inválido | ","")&IF(COUNTIF(Esp_Nome,$F69)=0,"Especialidade não cadastrada | ","")&IF(COUNTIF(Lista_StatusCirurgia,$J69)=0,"Status inválido | ","")&IF(OR(NOT(ISNUMBER($D69)),NOT(ISNUMBER($E69))),"Horário inválido | ","")&IFERROR(IF(AND(ISNUMBER($D69),ISNUMBER($E69),MOD($E69-$D69,1)*1440<=0),"Duração nula ou negativa | ",""),"")&IFERROR(IF(AND(ISNUMBER($D69),COUNTIF(Turnos_Nome,$C69)>0,MOD($D69-INDEX(Turnos_Ini,MATCH($C69,Turnos_Nome,0)),1)*1440>=INDEX(Turnos_Min,MATCH($C69,Turnos_Nome,0))),"Início fora da janela do turno | ",""),"")&IFERROR(IF(AND($L69>0,SUMPRODUCT((Mapa_Sala=$B69)*(Mapa_Data=$A69)*(Mapa_MinOcup>0)*(((MOD(Mapa_IniNum-$O69,1)<MOD($P69-$O69,1))+(MOD($O69-Mapa_IniNum,1)<MOD(Mapa_FimNum-Mapa_IniNum,1)))>0))>1),"Sobreposição de horário na sala | ",""),"")&IFERROR(IF(AND(ISNUMBER($K69),$K69>0,COUNTIF(Esp_Nome,$F69)>0,$K69>3*INDEX(Esp_Dur,MATCH($F69,Esp_Nome,0))),"Duração atípica (>3x a média) | ",""),"")) | O69: =IF(ISNUMBER($D69),$D69,0) | P69: =IF(ISNUMBER($E69),$E69,0)
K70: =IF(OR($B70="",NOT(ISNUMBER($D70)),NOT(ISNUMBER($E70))),"",ROUND(MOD($E70-$D70,1)*1440,0)) | L70: =IF(NOT(ISNUMBER($K70)),0,IF(OR($K70<=0,$J70="Cancelada",$J70="Suspensa"),0,$K70+Setup_Min)) | M70: =IF($B70="","",IF($N70="","OK",LEFT($N70,LEN($N70)-3))) | N70: =IF($B70="","",IF(COUNTIF(Salas_Cod,$B70)=0,"Sala não cadastrada | ","")&IF(AND(COUNTIF(Salas_Cod,$B70)>0,IFERROR(INDEX(Salas_Status,MATCH($B70,Salas_Cod,0)),"")<>"Ativa"),"Sala bloqueada | ","")&IF(COUNTIF(Turnos_Nome,$C70)=0,"Turno inválido | ","")&IF(COUNTIF(Esp_Nome,$F70)=0,"Especialidade não cadastrada | ","")&IF(COUNTIF(Lista_StatusCirurgia,$J70)=0,"Status inválido | ","")&IF(OR(NOT(ISNUMBER($D70)),NOT(ISNUMBER($E70))),"Horário inválido | ","")&IFERROR(IF(AND(ISNUMBER($D70),ISNUMBER($E70),MOD($E70-$D70,1)*1440<=0),"Duração nula ou negativa | ",""),"")&IFERROR(IF(AND(ISNUMBER($D70),COUNTIF(Turnos_Nome,$C70)>0,MOD($D70-INDEX(Turnos_Ini,MATCH($C70,Turnos_Nome,0)),1)*1440>=INDEX(Turnos_Min,MATCH($C70,Turnos_Nome,0))),"Início fora da janela do turno | ",""),"")&IFERROR(IF(AND($L70>0,SUMPRODUCT((Mapa_Sala=$B70)*(Mapa_Data=$A70)*(Mapa_MinOcup>0)*(((MOD(Mapa_IniNum-$O70,1)<MOD($P70-$O70,1))+(MOD($O70-Mapa_IniNum,1)<MOD(Mapa_FimNum-Mapa_IniNum,1)))>0))>1),"Sobreposição de horário na sala | ",""),"")&IFERROR(IF(AND(ISNUMBER($K70),$K70>0,COUNTIF(Esp_Nome,$F70)>0,$K70>3*INDEX(Esp_Dur,MATCH($F70,Esp_Nome,0))),"Duração atípica (>3x a média) | ",""),"")) | O70: =IF(ISNUMBER($D70),$D70,0) | P70: =IF(ISNUMBER($E70),$E70,0)
K71: =IF(OR($B71="",NOT(ISNUMBER($D71)),NOT(ISNUMBER($E71))),"",ROUND(MOD($E71-$D71,1)*1440,0)) | L71: =IF(NOT(ISNUMBER($K71)),0,IF(OR($K71<=0,$J71="Cancelada",$J71="Suspensa"),0,$K71+Setup_Min)) | M71: =IF($B71="","",IF($N71="","OK",LEFT($N71,LEN($N71)-3))) | N71: =IF($B71="","",IF(COUNTIF(Salas_Cod,$B71)=0,"Sala não cadastrada | ","")&IF(AND(COUNTIF(Salas_Cod,$B71)>0,IFERROR(INDEX(Salas_Status,MATCH($B71,Salas_Cod,0)),"")<>"Ativa"),"Sala bloqueada | ","")&IF(COUNTIF(Turnos_Nome,$C71)=0,"Turno inválido | ","")&IF(COUNTIF(Esp_Nome,$F71)=0,"Especialidade não cadastrada | ","")&IF(COUNTIF(Lista_StatusCirurgia,$J71)=0,"Status inválido | ","")&IF(OR(NOT(ISNUMBER($D71)),NOT(ISNUMBER($E71))),"Horário inválido | ","")&IFERROR(IF(AND(ISNUMBER($D71),ISNUMBER($E71),MOD($E71-$D71,1)*1440<=0),"Duração nula ou negativa | ",""),"")&IFERROR(IF(AND(ISNUMBER($D71),COUNTIF(Turnos_Nome,$C71)>0,MOD($D71-INDEX(Turnos_Ini,MATCH($C71,Turnos_Nome,0)),1)*1440>=INDEX(Turnos_Min,MATCH($C71,Turnos_Nome,0))),"Início fora da janela do turno | ",""),"")&IFERROR(IF(AND($L71>0,SUMPRODUCT((Mapa_Sala=$B71)*(Mapa_Data=$A71)*(Mapa_MinOcup>0)*(((MOD(Mapa_IniNum-$O71,1)<MOD($P71-$O71,1))+(MOD($O71-Mapa_IniNum,1)<MOD(Mapa_FimNum-Mapa_IniNum,1)))>0))>1),"Sobreposição de horário na sala | ",""),"")&IFERROR(IF(AND(ISNUMBER($K71),$K71>0,COUNTIF(Esp_Nome,$F71)>0,$K71>3*INDEX(Esp_Dur,MATCH($F71,Esp_Nome,0))),"Duração atípica (>3x a média) | ",""),"")) | O71: =IF(ISNUMBER($D71),$D71,0) | P71: =IF(ISNUMBER($E71),$E71,0)
K72: =IF(OR($B72="",NOT(ISNUMBER($D72)),NOT(ISNUMBER($E72))),"",ROUND(MOD($E72-$D72,1)*1440,0)) | L72: =IF(NOT(ISNUMBER($K72)),0,IF(OR($K72<=0,$J72="Cancelada",$J72="Suspensa"),0,$K72+Setup_Min)) | M72: =IF($B72="","",IF($N72="","OK",LEFT($N72,LEN($N72)-3))) | N72: =IF($B72="","",IF(COUNTIF(Salas_Cod,$B72)=0,"Sala não cadastrada | ","")&IF(AND(COUNTIF(Salas_Cod,$B72)>0,IFERROR(INDEX(Salas_Status,MATCH($B72,Salas_Cod,0)),"")<>"Ativa"),"Sala bloqueada | ","")&IF(COUNTIF(Turnos_Nome,$C72)=0,"Turno inválido | ","")&IF(COUNTIF(Esp_Nome,$F72)=0,"Especialidade não cadastrada | ","")&IF(COUNTIF(Lista_StatusCirurgia,$J72)=0,"Status inválido | ","")&IF(OR(NOT(ISNUMBER($D72)),NOT(ISNUMBER($E72))),"Horário inválido | ","")&IFERROR(IF(AND(ISNUMBER($D72),ISNUMBER($E72),MOD($E72-$D72,1)*1440<=0),"Duração nula ou negativa | ",""),"")&IFERROR(IF(AND(ISNUMBER($D72),COUNTIF(Turnos_Nome,$C72)>0,MOD($D72-INDEX(Turnos_Ini,MATCH($C72,Turnos_Nome,0)),1)*1440>=INDEX(Turnos_Min,MATCH($C72,Turnos_Nome,0))),"Início fora da janela do turno | ",""),"")&IFERROR(IF(AND($L72>0,SUMPRODUCT((Mapa_Sala=$B72)*(Mapa_Data=$A72)*(Mapa_MinOcup>0)*(((MOD(Mapa_IniNum-$O72,1)<MOD($P72-$O72,1))+(MOD($O72-Mapa_IniNum,1)<MOD(Mapa_FimNum-Mapa_IniNum,1)))>0))>1),"Sobreposição de horário na sala | ",""),"")&IFERROR(IF(AND(ISNUMBER($K72),$K72>0,COUNTIF(Esp_Nome,$F72)>0,$K72>3*INDEX(Esp_Dur,MATCH($F72,Esp_Nome,0))),"Duração atípica (>3x a média) | ",""),"")) | O72: =IF(ISNUMBER($D72),$D72,0) | P72: =IF(ISNUMBER($E72),$E72,0)
K73: =IF(OR($B73="",NOT(ISNUMBER($D73)),NOT(ISNUMBER($E73))),"",ROUND(MOD($E73-$D73,1)*1440,0)) | L73: =IF(NOT(ISNUMBER($K73)),0,IF(OR($K73<=0,$J73="Cancelada",$J73="Suspensa"),0,$K73+Setup_Min)) | M73: =IF($B73="","",IF($N73="","OK",LEFT($N73,LEN($N73)-3))) | N73: =IF($B73="","",IF(COUNTIF(Salas_Cod,$B73)=0,"Sala não cadastrada | ","")&IF(AND(COUNTIF(Salas_Cod,$B73)>0,IFERROR(INDEX(Salas_Status,MATCH($B73,Salas_Cod,0)),"")<>"Ativa"),"Sala bloqueada | ","")&IF(COUNTIF(Turnos_Nome,$C73)=0,"Turno inválido | ","")&IF(COUNTIF(Esp_Nome,$F73)=0,"Especialidade não cadastrada | ","")&IF(COUNTIF(Lista_StatusCirurgia,$J73)=0,"Status inválido | ","")&IF(OR(NOT(ISNUMBER($D73)),NOT(ISNUMBER($E73))),"Horário inválido | ","")&IFERROR(IF(AND(ISNUMBER($D73),ISNUMBER($E73),MOD($E73-$D73,1)*1440<=0),"Duração nula ou negativa | ",""),"")&IFERROR(IF(AND(ISNUMBER($D73),COUNTIF(Turnos_Nome,$C73)>0,MOD($D73-INDEX(Turnos_Ini,MATCH($C73,Turnos_Nome,0)),1)*1440>=INDEX(Turnos_Min,MATCH($C73,Turnos_Nome,0))),"Início fora da janela do turno | ",""),"")&IFERROR(IF(AND($L73>0,SUMPRODUCT((Mapa_Sala=$B73)*(Mapa_Data=$A73)*(Mapa_MinOcup>0)*(((MOD(Mapa_IniNum-$O73,1)<MOD($P73-$O73,1))+(MOD($O73-Mapa_IniNum,1)<MOD(Mapa_FimNum-Mapa_IniNum,1)))>0))>1),"Sobreposição de horário na sala | ",""),"")&IFERROR(IF(AND(ISNUMBER($K73),$K73>0,COUNTIF(Esp_Nome,$F73)>0,$K73>3*INDEX(Esp_Dur,MATCH($F73,Esp_Nome,0))),"Duração atípica (>3x a média) | ",""),"")) | O73: =IF(ISNUMBER($D73),$D73,0) | P73: =IF(ISNUMBER($E73),$E73,0)
K74: =IF(OR($B74="",NOT(ISNUMBER($D74)),NOT(ISNUMBER($E74))),"",ROUND(MOD($E74-$D74,1)*1440,0)) | L74: =IF(NOT(ISNUMBER($K74)),0,IF(OR($K74<=0,$J74="Cancelada",$J74="Suspensa"),0,$K74+Setup_Min)) | M74: =IF($B74="","",IF($N74="","OK",LEFT($N74,LEN($N74)-3))) | N74: =IF($B74="","",IF(COUNTIF(Salas_Cod,$B74)=0,"Sala não cadastrada | ","")&IF(AND(COUNTIF(Salas_Cod,$B74)>0,IFERROR(INDEX(Salas_Status,MATCH($B74,Salas_Cod,0)),"")<>"Ativa"),"Sala bloqueada | ","")&IF(COUNTIF(Turnos_Nome,$C74)=0,"Turno inválido | ","")&IF(COUNTIF(Esp_Nome,$F74)=0,"Especialidade não cadastrada | ","")&IF(COUNTIF(Lista_StatusCirurgia,$J74)=0,"Status inválido | ","")&IF(OR(NOT(ISNUMBER($D74)),NOT(ISNUMBER($E74))),"Horário inválido | ","")&IFERROR(IF(AND(ISNUMBER($D74),ISNUMBER($E74),MOD($E74-$D74,1)*1440<=0),"Duração nula ou negativa | ",""),"")&IFERROR(IF(AND(ISNUMBER($D74),COUNTIF(Turnos_Nome,$C74)>0,MOD($D74-INDEX(Turnos_Ini,MATCH($C74,Turnos_Nome,0)),1)*1440>=INDEX(Turnos_Min,MATCH($C74,Turnos_Nome,0))),"Início fora da janela do turno | ",""),"")&IFERROR(IF(AND($L74>0,SUMPRODUCT((Mapa_Sala=$B74)*(Mapa_Data=$A74)*(Mapa_MinOcup>0)*(((MOD(Mapa_IniNum-$O74,1)<MOD($P74-$O74,1))+(MOD($O74-Mapa_IniNum,1)<MOD(Mapa_FimNum-Mapa_IniNum,1)))>0))>1),"Sobreposição de horário na sala | ",""),"")&IFERROR(IF(AND(ISNUMBER($K74),$K74>0,COUNTIF(Esp_Nome,$F74)>0,$K74>3*INDEX(Esp_Dur,MATCH($F74,Esp_Nome,0))),"Duração atípica (>3x a média) | ",""),"")) | O74: =IF(ISNUMBER($D74),$D74,0) | P74: =IF(ISNUMBER($E74),$E74,0)
K75: =IF(OR($B75="",NOT(ISNUMBER($D75)),NOT(ISNUMBER($E75))),"",ROUND(MOD($E75-$D75,1)*1440,0)) | L75: =IF(NOT(ISNUMBER($K75)),0,IF(OR($K75<=0,$J75="Cancelada",$J75="Suspensa"),0,$K75+Setup_Min)) | M75: =IF($B75="","",IF($N75="","OK",LEFT($N75,LEN($N75)-3))) | N75: =IF($B75="","",IF(COUNTIF(Salas_Cod,$B75)=0,"Sala não cadastrada | ","")&IF(AND(COUNTIF(Salas_Cod,$B75)>0,IFERROR(INDEX(Salas_Status,MATCH($B75,Salas_Cod,0)),"")<>"Ativa"),"Sala bloqueada | ","")&IF(COUNTIF(Turnos_Nome,$C75)=0,"Turno inválido | ","")&IF(COUNTIF(Esp_Nome,$F75)=0,"Especialidade não cadastrada | ","")&IF(COUNTIF(Lista_StatusCirurgia,$J75)=0,"Status inválido | ","")&IF(OR(NOT(ISNUMBER($D75)),NOT(ISNUMBER($E75))),"Horário inválido | ","")&IFERROR(IF(AND(ISNUMBER($D75),ISNUMBER($E75),MOD($E75-$D75,1)*1440<=0),"Duração nula ou negativa | ",""),"")&IFERROR(IF(AND(ISNUMBER($D75),COUNTIF(Turnos_Nome,$C75)>0,MOD($D75-INDEX(Turnos_Ini,MATCH($C75,Turnos_Nome,0)),1)*1440>=INDEX(Turnos_Min,MATCH($C75,Turnos_Nome,0))),"Início fora da janela do turno | ",""),"")&IFERROR(IF(AND($L75>0,SUMPRODUCT((Mapa_Sala=$B75)*(Mapa_Data=$A75)*(Mapa_MinOcup>0)*(((MOD(Mapa_IniNum-$O75,1)<MOD($P75-$O75,1))+(MOD($O75-Mapa_IniNum,1)<MOD(Mapa_FimNum-Mapa_IniNum,1)))>0))>1),"Sobreposição de horário na sala | ",""),"")&IFERROR(IF(AND(ISNUMBER($K75),$K75>0,COUNTIF(Esp_Nome,$F75)>0,$K75>3*INDEX(Esp_Dur,MATCH($F75,Esp_Nome,0))),"Duração atípica (>3x a média) | ",""),"")) | O75: =IF(ISNUMBER($D75),$D75,0) | P75: =IF(ISNUMBER($E75),$E75,0)
K76: =IF(OR($B76="",NOT(ISNUMBER($D76)),NOT(ISNUMBER($E76))),"",ROUND(MOD($E76-$D76,1)*1440,0)) | L76: =IF(NOT(ISNUMBER($K76)),0,IF(OR($K76<=0,$J76="Cancelada",$J76="Suspensa"),0,$K76+Setup_Min)) | M76: =IF($B76="","",IF($N76="","OK",LEFT($N76,LEN($N76)-3))) | N76: =IF($B76="","",IF(COUNTIF(Salas_Cod,$B76)=0,"Sala não cadastrada | ","")&IF(AND(COUNTIF(Salas_Cod,$B76)>0,IFERROR(INDEX(Salas_Status,MATCH($B76,Salas_Cod,0)),"")<>"Ativa"),"Sala bloqueada | ","")&IF(COUNTIF(Turnos_Nome,$C76)=0,"Turno inválido | ","")&IF(COUNTIF(Esp_Nome,$F76)=0,"Especialidade não cadastrada | ","")&IF(COUNTIF(Lista_StatusCirurgia,$J76)=0,"Status inválido | ","")&IF(OR(NOT(ISNUMBER($D76)),NOT(ISNUMBER($E76))),"Horário inválido | ","")&IFERROR(IF(AND(ISNUMBER($D76),ISNUMBER($E76),MOD($E76-$D76,1)*1440<=0),"Duração nula ou negativa | ",""),"")&IFERROR(IF(AND(ISNUMBER($D76),COUNTIF(Turnos_Nome,$C76)>0,MOD($D76-INDEX(Turnos_Ini,MATCH($C76,Turnos_Nome,0)),1)*1440>=INDEX(Turnos_Min,MATCH($C76,Turnos_Nome,0))),"Início fora da janela do turno | ",""),"")&IFERROR(IF(AND($L76>0,SUMPRODUCT((Mapa_Sala=$B76)*(Mapa_Data=$A76)*(Mapa_MinOcup>0)*(((MOD(Mapa_IniNum-$O76,1)<MOD($P76-$O76,1))+(MOD($O76-Mapa_IniNum,1)<MOD(Mapa_FimNum-Mapa_IniNum,1)))>0))>1),"Sobreposição de horário na sala | ",""),"")&IFERROR(IF(AND(ISNUMBER($K76),$K76>0,COUNTIF(Esp_Nome,$F76)>0,$K76>3*INDEX(Esp_Dur,MATCH($F76,Esp_Nome,0))),"Duração atípica (>3x a média) | ",""),"")) | O76: =IF(ISNUMBER($D76),$D76,0) | P76: =IF(ISNUMBER($E76),$E76,0)
K77: =IF(OR($B77="",NOT(ISNUMBER($D77)),NOT(ISNUMBER($E77))),"",ROUND(MOD($E77-$D77,1)*1440,0)) | L77: =IF(NOT(ISNUMBER($K77)),0,IF(OR($K77<=0,$J77="Cancelada",$J77="Suspensa"),0,$K77+Setup_Min)) | M77: =IF($B77="","",IF($N77="","OK",LEFT($N77,LEN($N77)-3))) | N77: =IF($B77="","",IF(COUNTIF(Salas_Cod,$B77)=0,"Sala não cadastrada | ","")&IF(AND(COUNTIF(Salas_Cod,$B77)>0,IFERROR(INDEX(Salas_Status,MATCH($B77,Salas_Cod,0)),"")<>"Ativa"),"Sala bloqueada | ","")&IF(COUNTIF(Turnos_Nome,$C77)=0,"Turno inválido | ","")&IF(COUNTIF(Esp_Nome,$F77)=0,"Especialidade não cadastrada | ","")&IF(COUNTIF(Lista_StatusCirurgia,$J77)=0,"Status inválido | ","")&IF(OR(NOT(ISNUMBER($D77)),NOT(ISNUMBER($E77))),"Horário inválido | ","")&IFERROR(IF(AND(ISNUMBER($D77),ISNUMBER($E77),MOD($E77-$D77,1)*1440<=0),"Duração nula ou negativa | ",""),"")&IFERROR(IF(AND(ISNUMBER($D77),COUNTIF(Turnos_Nome,$C77)>0,MOD($D77-INDEX(Turnos_Ini,MATCH($C77,Turnos_Nome,0)),1)*1440>=INDEX(Turnos_Min,MATCH($C77,Turnos_Nome,0))),"Início fora da janela do turno | ",""),"")&IFERROR(IF(AND($L77>0,SUMPRODUCT((Mapa_Sala=$B77)*(Mapa_Data=$A77)*(Mapa_MinOcup>0)*(((MOD(Mapa_IniNum-$O77,1)<MOD($P77-$O77,1))+(MOD($O77-Mapa_IniNum,1)<MOD(Mapa_FimNum-Mapa_IniNum,1)))>0))>1),"Sobreposição de horário na sala | ",""),"")&IFERROR(IF(AND(ISNUMBER($K77),$K77>0,COUNTIF(Esp_Nome,$F77)>0,$K77>3*INDEX(Esp_Dur,MATCH($F77,Esp_Nome,0))),"Duração atípica (>3x a média) | ",""),"")) | O77: =IF(ISNUMBER($D77),$D77,0) | P77: =IF(ISNUMBER($E77),$E77,0)
K78: =IF(OR($B78="",NOT(ISNUMBER($D78)),NOT(ISNUMBER($E78))),"",ROUND(MOD($E78-$D78,1)*1440,0)) | L78: =IF(NOT(ISNUMBER($K78)),0,IF(OR($K78<=0,$J78="Cancelada",$J78="Suspensa"),0,$K78+Setup_Min)) | M78: =IF($B78="","",IF($N78="","OK",LEFT($N78,LEN($N78)-3))) | N78: =IF($B78="","",IF(COUNTIF(Salas_Cod,$B78)=0,"Sala não cadastrada | ","")&IF(AND(COUNTIF(Salas_Cod,$B78)>0,IFERROR(INDEX(Salas_Status,MATCH($B78,Salas_Cod,0)),"")<>"Ativa"),"Sala bloqueada | ","")&IF(COUNTIF(Turnos_Nome,$C78)=0,"Turno inválido | ","")&IF(COUNTIF(Esp_Nome,$F78)=0,"Especialidade não cadastrada | ","")&IF(COUNTIF(Lista_StatusCirurgia,$J78)=0,"Status inválido | ","")&IF(OR(NOT(ISNUMBER($D78)),NOT(ISNUMBER($E78))),"Horário inválido | ","")&IFERROR(IF(AND(ISNUMBER($D78),ISNUMBER($E78),MOD($E78-$D78,1)*1440<=0),"Duração nula ou negativa | ",""),"")&IFERROR(IF(AND(ISNUMBER($D78),COUNTIF(Turnos_Nome,$C78)>0,MOD($D78-INDEX(Turnos_Ini,MATCH($C78,Turnos_Nome,0)),1)*1440>=INDEX(Turnos_Min,MATCH($C78,Turnos_Nome,0))),"Início fora da janela do turno | ",""),"")&IFERROR(IF(AND($L78>0,SUMPRODUCT((Mapa_Sala=$B78)*(Mapa_Data=$A78)*(Mapa_MinOcup>0)*(((MOD(Mapa_IniNum-$O78,1)<MOD($P78-$O78,1))+(MOD($O78-Mapa_IniNum,1)<MOD(Mapa_FimNum-Mapa_IniNum,1)))>0))>1),"Sobreposição de horário na sala | ",""),"")&IFERROR(IF(AND(ISNUMBER($K78),$K78>0,COUNTIF(Esp_Nome,$F78)>0,$K78>3*INDEX(Esp_Dur,MATCH($F78,Esp_Nome,0))),"Duração atípica (>3x a média) | ",""),"")) | O78: =IF(ISNUMBER($D78),$D78,0) | P78: =IF(ISNUMBER($E78),$E78,0)
K79: =IF(OR($B79="",NOT(ISNUMBER($D79)),NOT(ISNUMBER($E79))),"",ROUND(MOD($E79-$D79,1)*1440,0)) | L79: =IF(NOT(ISNUMBER($K79)),0,IF(OR($K79<=0,$J79="Cancelada",$J79="Suspensa"),0,$K79+Setup_Min)) | M79: =IF($B79="","",IF($N79="","OK",LEFT($N79,LEN($N79)-3))) | N79: =IF($B79="","",IF(COUNTIF(Salas_Cod,$B79)=0,"Sala não cadastrada | ","")&IF(AND(COUNTIF(Salas_Cod,$B79)>0,IFERROR(INDEX(Salas_Status,MATCH($B79,Salas_Cod,0)),"")<>"Ativa"),"Sala bloqueada | ","")&IF(COUNTIF(Turnos_Nome,$C79)=0,"Turno inválido | ","")&IF(COUNTIF(Esp_Nome,$F79)=0,"Especialidade não cadastrada | ","")&IF(COUNTIF(Lista_StatusCirurgia,$J79)=0,"Status inválido | ","")&IF(OR(NOT(ISNUMBER($D79)),NOT(ISNUMBER($E79))),"Horário inválido | ","")&IFERROR(IF(AND(ISNUMBER($D79),ISNUMBER($E79),MOD($E79-$D79,1)*1440<=0),"Duração nula ou negativa | ",""),"")&IFERROR(IF(AND(ISNUMBER($D79),COUNTIF(Turnos_Nome,$C79)>0,MOD($D79-INDEX(Turnos_Ini,MATCH($C79,Turnos_Nome,0)),1)*1440>=INDEX(Turnos_Min,MATCH($C79,Turnos_Nome,0))),"Início fora da janela do turno | ",""),"")&IFERROR(IF(AND($L79>0,SUMPRODUCT((Mapa_Sala=$B79)*(Mapa_Data=$A79)*(Mapa_MinOcup>0)*(((MOD(Mapa_IniNum-$O79,1)<MOD($P79-$O79,1))+(MOD($O79-Mapa_IniNum,1)<MOD(Mapa_FimNum-Mapa_IniNum,1)))>0))>1),"Sobreposição de horário na sala | ",""),"")&IFERROR(IF(AND(ISNUMBER($K79),$K79>0,COUNTIF(Esp_Nome,$F79)>0,$K79>3*INDEX(Esp_Dur,MATCH($F79,Esp_Nome,0))),"Duração atípica (>3x a média) | ",""),"")) | O79: =IF(ISNUMBER($D79),$D79,0) | P79: =IF(ISNUMBER($E79),$E79,0)
